2022-06-15 00:01:45,847 | apscheduler.scheduler | INFO | start:171 | Scheduler started
2022-06-15 00:01:45,862 | telegram.ext._application | INFO | start:492 | Application started
2022-06-15 00:01:56,656 | telegram.ext._application | ERROR | process_error:1484 | No error handlers are registered, logging exception.
Traceback (most recent call last):
  File "/home/bori/.local/lib/python3.7/site-packages/telegram/ext/_application.py", line 970, in process_update
    await coroutine
  File "/home/bori/.local/lib/python3.7/site-packages/telegram/ext/_handler.py", line 137, in handle_update
    return await self.callback(update, context)
  File "/home/bori/dev/py/beud/beubot/start.py", line 48, in context_hlr
    text=f"{    context.bot_data}\n\n{    context.chat_data}\n\n{    context.user_data}")
  File "/home/bori/.local/lib/python3.7/site-packages/telegram/_bot.py", line 236, in decorator
    result = await func(*args, **kwargs)
  File "/home/bori/.local/lib/python3.7/site-packages/telegram/_bot.py", line 653, in send_message
    api_kwargs=api_kwargs,
  File "/home/bori/.local/lib/python3.7/site-packages/telegram/ext/_extbot.py", line 266, in _send_message
    api_kwargs=api_kwargs,
  File "/home/bori/.local/lib/python3.7/site-packages/telegram/_bot.py", line 353, in _send_message
    api_kwargs=api_kwargs,
  File "/home/bori/.local/lib/python3.7/site-packages/telegram/_bot.py", line 315, in _post
    pool_timeout=pool_timeout,
  File "/home/bori/.local/lib/python3.7/site-packages/telegram/request/_baserequest.py", line 169, in post
    pool_timeout=pool_timeout,
  File "/home/bori/.local/lib/python3.7/site-packages/telegram/request/_baserequest.py", line 325, in _request_wrapper
    raise BadRequest(message)
telegram.error.BadRequest: Can't parse entities: unsupported start tag "telegram._message.message" at byte offset 182
2022-06-15 00:02:12,354 | telegram.ext._application | ERROR | process_error:1484 | No error handlers are registered, logging exception.
Traceback (most recent call last):
  File "/home/bori/.local/lib/python3.7/site-packages/telegram/ext/_application.py", line 970, in process_update
    await coroutine
  File "/home/bori/.local/lib/python3.7/site-packages/telegram/ext/_handler.py", line 137, in handle_update
    return await self.callback(update, context)
  File "/home/bori/dev/py/beud/beubot/start.py", line 48, in context_hlr
    text=f"{    context.bot_data}\n\n{    context.chat_data}\n\n{    context.user_data}")
  File "/home/bori/.local/lib/python3.7/site-packages/telegram/_bot.py", line 236, in decorator
    result = await func(*args, **kwargs)
  File "/home/bori/.local/lib/python3.7/site-packages/telegram/_bot.py", line 653, in send_message
    api_kwargs=api_kwargs,
  File "/home/bori/.local/lib/python3.7/site-packages/telegram/ext/_extbot.py", line 266, in _send_message
    api_kwargs=api_kwargs,
  File "/home/bori/.local/lib/python3.7/site-packages/telegram/_bot.py", line 353, in _send_message
    api_kwargs=api_kwargs,
  File "/home/bori/.local/lib/python3.7/site-packages/telegram/_bot.py", line 315, in _post
    pool_timeout=pool_timeout,
  File "/home/bori/.local/lib/python3.7/site-packages/telegram/request/_baserequest.py", line 169, in post
    pool_timeout=pool_timeout,
  File "/home/bori/.local/lib/python3.7/site-packages/telegram/request/_baserequest.py", line 325, in _request_wrapper
    raise BadRequest(message)
telegram.error.BadRequest: Can't parse entities: unsupported start tag "telegram._message.message" at byte offset 182
2022-06-15 00:04:04,232 | apscheduler.scheduler | INFO | start:171 | Scheduler started
2022-06-15 00:04:04,233 | telegram.ext._application | INFO | start:492 | Application started
2022-06-15 00:04:07,846 | telegram.ext._application | ERROR | process_error:1484 | No error handlers are registered, logging exception.
Traceback (most recent call last):
  File "/home/bori/.local/lib/python3.7/site-packages/telegram/ext/_application.py", line 970, in process_update
    await coroutine
  File "/home/bori/.local/lib/python3.7/site-packages/telegram/ext/_handler.py", line 137, in handle_update
    return await self.callback(update, context)
  File "/home/bori/dev/py/beud/beubot/start.py", line 49, in context_hlr
    text=f"{str(context.bot_data)}")
  File "/home/bori/.local/lib/python3.7/site-packages/telegram/_bot.py", line 236, in decorator
    result = await func(*args, **kwargs)
  File "/home/bori/.local/lib/python3.7/site-packages/telegram/_bot.py", line 653, in send_message
    api_kwargs=api_kwargs,
  File "/home/bori/.local/lib/python3.7/site-packages/telegram/ext/_extbot.py", line 266, in _send_message
    api_kwargs=api_kwargs,
  File "/home/bori/.local/lib/python3.7/site-packages/telegram/_bot.py", line 353, in _send_message
    api_kwargs=api_kwargs,
  File "/home/bori/.local/lib/python3.7/site-packages/telegram/_bot.py", line 315, in _post
    pool_timeout=pool_timeout,
  File "/home/bori/.local/lib/python3.7/site-packages/telegram/request/_baserequest.py", line 169, in post
    pool_timeout=pool_timeout,
  File "/home/bori/.local/lib/python3.7/site-packages/telegram/request/_baserequest.py", line 325, in _request_wrapper
    raise BadRequest(message)
telegram.error.BadRequest: Can't parse entities: unsupported start tag "telegram._message.message" at byte offset 182
2022-06-15 00:04:58,592 | apscheduler.scheduler | INFO | start:171 | Scheduler started
2022-06-15 00:04:58,593 | telegram.ext._application | INFO | start:492 | Application started
2022-06-15 00:05:00,849 | telegram.ext._application | ERROR | process_error:1484 | No error handlers are registered, logging exception.
Traceback (most recent call last):
  File "/home/bori/.local/lib/python3.7/site-packages/telegram/ext/_application.py", line 970, in process_update
    await coroutine
  File "/home/bori/.local/lib/python3.7/site-packages/telegram/ext/_handler.py", line 137, in handle_update
    return await self.callback(update, context)
  File "/home/bori/dev/py/beud/beubot/start.py", line 55, in context_hlr
    text=f"{str(context.user_data)}")
  File "/home/bori/.local/lib/python3.7/site-packages/telegram/_bot.py", line 236, in decorator
    result = await func(*args, **kwargs)
  File "/home/bori/.local/lib/python3.7/site-packages/telegram/_bot.py", line 653, in send_message
    api_kwargs=api_kwargs,
  File "/home/bori/.local/lib/python3.7/site-packages/telegram/ext/_extbot.py", line 266, in _send_message
    api_kwargs=api_kwargs,
  File "/home/bori/.local/lib/python3.7/site-packages/telegram/_bot.py", line 353, in _send_message
    api_kwargs=api_kwargs,
  File "/home/bori/.local/lib/python3.7/site-packages/telegram/_bot.py", line 315, in _post
    pool_timeout=pool_timeout,
  File "/home/bori/.local/lib/python3.7/site-packages/telegram/request/_baserequest.py", line 169, in post
    pool_timeout=pool_timeout,
  File "/home/bori/.local/lib/python3.7/site-packages/telegram/request/_baserequest.py", line 325, in _request_wrapper
    raise BadRequest(message)
telegram.error.BadRequest: Can't parse entities: unsupported start tag "telegram._message.message" at byte offset 170
2022-06-15 00:05:31,398 | apscheduler.scheduler | INFO | start:171 | Scheduler started
2022-06-15 00:05:31,399 | telegram.ext._application | INFO | start:492 | Application started
2022-06-15 00:06:25,330 | apscheduler.scheduler | INFO | start:171 | Scheduler started
2022-06-15 00:06:25,330 | telegram.ext._application | INFO | start:492 | Application started
2022-06-15 00:08:29,336 | apscheduler.scheduler | INFO | start:171 | Scheduler started
2022-06-15 00:08:29,336 | telegram.ext._application | INFO | start:492 | Application started
2022-06-15 00:08:48,823 | apscheduler.scheduler | INFO | start:171 | Scheduler started
2022-06-15 00:08:48,824 | telegram.ext._application | INFO | start:492 | Application started
2022-06-15 00:10:01,348 | apscheduler.scheduler | INFO | start:171 | Scheduler started
2022-06-15 00:10:01,348 | telegram.ext._application | INFO | start:492 | Application started
2022-06-15 00:11:57,331 | apscheduler.scheduler | INFO | start:171 | Scheduler started
2022-06-15 00:11:57,331 | telegram.ext._application | INFO | start:492 | Application started
2022-06-15 00:12:46,515 | apscheduler.scheduler | INFO | start:171 | Scheduler started
2022-06-15 00:12:46,516 | telegram.ext._application | INFO | start:492 | Application started
2022-06-15 00:13:10,194 | telegram.ext._application | ERROR | process_error:1484 | No error handlers are registered, logging exception.
Traceback (most recent call last):
  File "/home/bori/.local/lib/python3.7/site-packages/telegram/ext/_application.py", line 970, in process_update
    await coroutine
  File "/home/bori/.local/lib/python3.7/site-packages/telegram/ext/_handler.py", line 137, in handle_update
    return await self.callback(update, context)
  File "/home/bori/dev/py/beud/beubot/start.py", line 49, in context_hlr
    text=f"{str(context.bot_data)}")
  File "/home/bori/.local/lib/python3.7/site-packages/telegram/_bot.py", line 236, in decorator
    result = await func(*args, **kwargs)
  File "/home/bori/.local/lib/python3.7/site-packages/telegram/_bot.py", line 653, in send_message
    api_kwargs=api_kwargs,
  File "/home/bori/.local/lib/python3.7/site-packages/telegram/ext/_extbot.py", line 266, in _send_message
    api_kwargs=api_kwargs,
  File "/home/bori/.local/lib/python3.7/site-packages/telegram/_bot.py", line 353, in _send_message
    api_kwargs=api_kwargs,
  File "/home/bori/.local/lib/python3.7/site-packages/telegram/_bot.py", line 315, in _post
    pool_timeout=pool_timeout,
  File "/home/bori/.local/lib/python3.7/site-packages/telegram/request/_baserequest.py", line 169, in post
    pool_timeout=pool_timeout,
  File "/home/bori/.local/lib/python3.7/site-packages/telegram/request/_baserequest.py", line 325, in _request_wrapper
    raise BadRequest(message)
telegram.error.BadRequest: Can't parse entities: unsupported start tag "telegram._message.message" at byte offset 182
2022-06-15 00:14:04,564 | apscheduler.scheduler | INFO | start:171 | Scheduler started
2022-06-15 00:14:04,565 | telegram.ext._application | INFO | start:492 | Application started
2022-06-15 00:16:41,447 | apscheduler.scheduler | INFO | start:171 | Scheduler started
2022-06-15 00:16:41,447 | telegram.ext._application | INFO | start:492 | Application started
2022-06-15 00:17:04,204 | apscheduler.scheduler | INFO | start:171 | Scheduler started
2022-06-15 00:17:04,204 | telegram.ext._application | INFO | start:492 | Application started
2022-06-15 00:17:13,497 | telegram.ext._application | ERROR | process_error:1484 | No error handlers are registered, logging exception.
Traceback (most recent call last):
  File "/home/bori/.local/lib/python3.7/site-packages/telegram/ext/_application.py", line 970, in process_update
    await coroutine
  File "/home/bori/.local/lib/python3.7/site-packages/telegram/ext/_handler.py", line 137, in handle_update
    return await self.callback(update, context)
  File "/home/bori/dev/py/beud/misc/access_control.py", line 15, in wrapped
    return await func(update, context, *args, **kwargs)
  File "/home/bori/dev/py/beud/beubot/flows/prompt_handlers/nominal_phlr.py", line 101, in food_inline_hlr
    {'food': food_selected, 'status': 'pending' , 'from_id': update.callback_query.from_user.id})
TypeError: object NoneType can't be used in 'await' expression
2022-06-15 00:18:50,710 | apscheduler.scheduler | INFO | start:171 | Scheduler started
2022-06-15 00:18:50,710 | telegram.ext._application | INFO | start:492 | Application started
2022-06-15 00:22:48,831 | apscheduler.scheduler | INFO | start:171 | Scheduler started
2022-06-15 00:22:48,831 | telegram.ext._application | INFO | start:492 | Application started
2022-06-15 00:23:47,607 | apscheduler.scheduler | INFO | start:171 | Scheduler started
2022-06-15 00:23:47,607 | telegram.ext._application | INFO | start:492 | Application started
2022-06-15 00:23:48,318 | telegram.ext._application | ERROR | process_error:1484 | No error handlers are registered, logging exception.
Traceback (most recent call last):
  File "/home/bori/.local/lib/python3.7/site-packages/telegram/ext/_application.py", line 970, in process_update
    await coroutine
  File "/home/bori/.local/lib/python3.7/site-packages/telegram/ext/_handler.py", line 137, in handle_update
    return await self.callback(update, context)
  File "/home/bori/dev/py/beud/misc/access_control.py", line 15, in wrapped
    return await func(update, context, *args, **kwargs)
  File "/home/bori/dev/py/beud/beubot/flows/prompt_handlers/nominal_phlr.py", line 125, in view_pending_orders_hlr
    reply_makup = InlineKeyboardMarkup(keyboard))
  File "/home/bori/.local/lib/python3.7/site-packages/telegram/_inline/inlinekeyboardmarkup.py", line 55, in __init__
    "The parameter `inline_keyboard` should be a list of "
ValueError: The parameter `inline_keyboard` should be a list of list of InlineKeyboardButtons
2022-06-15 00:24:03,657 | apscheduler.scheduler | INFO | start:171 | Scheduler started
2022-06-15 00:24:03,662 | telegram.ext._application | INFO | start:492 | Application started
2022-06-15 00:24:06,957 | telegram.ext._application | ERROR | process_error:1484 | No error handlers are registered, logging exception.
Traceback (most recent call last):
  File "/home/bori/.local/lib/python3.7/site-packages/telegram/ext/_application.py", line 970, in process_update
    await coroutine
  File "/home/bori/.local/lib/python3.7/site-packages/telegram/ext/_handler.py", line 137, in handle_update
    return await self.callback(update, context)
  File "/home/bori/dev/py/beud/misc/access_control.py", line 15, in wrapped
    return await func(update, context, *args, **kwargs)
  File "/home/bori/dev/py/beud/beubot/flows/prompt_handlers/nominal_phlr.py", line 125, in view_pending_orders_hlr
    reply_makup = InlineKeyboardMarkup(keyboard))
  File "/home/bori/.local/lib/python3.7/site-packages/telegram/_bot.py", line 236, in decorator
    result = await func(*args, **kwargs)
TypeError: send_message() got an unexpected keyword argument 'reply_makup'
2022-06-15 00:24:14,061 | apscheduler.scheduler | INFO | start:171 | Scheduler started
2022-06-15 00:24:14,061 | telegram.ext._application | INFO | start:492 | Application started
2022-06-15 00:24:54,438 | apscheduler.scheduler | INFO | start:171 | Scheduler started
2022-06-15 00:24:54,439 | telegram.ext._application | INFO | start:492 | Application started
2022-06-15 00:25:15,811 | apscheduler.scheduler | INFO | start:171 | Scheduler started
2022-06-15 00:25:15,811 | telegram.ext._application | INFO | start:492 | Application started
2022-06-15 00:25:18,639 | telegram.ext._application | ERROR | process_error:1484 | No error handlers are registered, logging exception.
Traceback (most recent call last):
  File "/home/bori/.local/lib/python3.7/site-packages/telegram/ext/_application.py", line 970, in process_update
    await coroutine
  File "/home/bori/.local/lib/python3.7/site-packages/telegram/ext/_handler.py", line 137, in handle_update
    return await self.callback(update, context)
  File "/home/bori/dev/py/beud/misc/access_control.py", line 15, in wrapped
    return await func(update, context, *args, **kwargs)
  File "/home/bori/dev/py/beud/beubot/flows/prompt_handlers/nominal_phlr.py", line 124, in view_pending_orders_hlr
    text = 'An order for ' + order['food'] + 'from'+ order['from_id'] +  ' is pending',
TypeError: can only concatenate str (not "int") to str
2022-06-15 00:25:33,384 | apscheduler.scheduler | INFO | start:171 | Scheduler started
2022-06-15 00:25:33,384 | telegram.ext._application | INFO | start:492 | Application started
2022-06-15 00:25:42,151 | apscheduler.scheduler | INFO | start:171 | Scheduler started
2022-06-15 00:25:42,152 | telegram.ext._application | INFO | start:492 | Application started
2022-06-15 00:25:50,385 | apscheduler.scheduler | INFO | start:171 | Scheduler started
2022-06-15 00:25:50,389 | telegram.ext._application | INFO | start:492 | Application started
2022-06-15 00:26:04,611 | apscheduler.scheduler | INFO | start:171 | Scheduler started
2022-06-15 00:26:04,612 | telegram.ext._application | INFO | start:492 | Application started
2022-06-15 00:34:45,730 | apscheduler.scheduler | INFO | start:171 | Scheduler started
2022-06-15 00:34:45,731 | telegram.ext._application | INFO | start:492 | Application started
2022-06-15 00:35:28,011 | apscheduler.scheduler | INFO | start:171 | Scheduler started
2022-06-15 00:35:28,011 | telegram.ext._application | INFO | start:492 | Application started
2022-06-15 00:37:15,989 | apscheduler.scheduler | INFO | start:171 | Scheduler started
2022-06-15 00:37:15,990 | telegram.ext._application | INFO | start:492 | Application started
2022-06-15 00:37:52,886 | apscheduler.scheduler | INFO | start:171 | Scheduler started
2022-06-15 00:37:52,886 | telegram.ext._application | INFO | start:492 | Application started
2022-06-15 00:41:28,099 | apscheduler.scheduler | INFO | start:171 | Scheduler started
2022-06-15 00:41:28,100 | telegram.ext._application | INFO | start:492 | Application started
2022-06-15 00:41:34,417 | telegram.ext._application | ERROR | process_error:1484 | No error handlers are registered, logging exception.
Traceback (most recent call last):
  File "/home/bori/.local/lib/python3.7/site-packages/telegram/ext/_application.py", line 970, in process_update
    await coroutine
  File "/home/bori/.local/lib/python3.7/site-packages/telegram/ext/_handler.py", line 137, in handle_update
    return await self.callback(update, context)
  File "/home/bori/dev/py/beud/misc/access_control.py", line 15, in wrapped
    return await func(update, context, *args, **kwargs)
  File "/home/bori/dev/py/beud/beubot/flows/prompt_handlers/nominal_phlr.py", line 143, in view_pending_orders_hlr
    'Accept', callback_data="accept_" + order['food']+order['from_id']),
TypeError: can only concatenate str (not "int") to str
2022-06-15 00:41:56,105 | apscheduler.scheduler | INFO | start:171 | Scheduler started
2022-06-15 00:41:56,105 | telegram.ext._application | INFO | start:492 | Application started
2022-06-15 00:42:07,736 | telegram.ext._application | ERROR | process_error:1484 | No error handlers are registered, logging exception.
Traceback (most recent call last):
  File "/home/bori/.local/lib/python3.7/site-packages/telegram/ext/_application.py", line 970, in process_update
    await coroutine
  File "/home/bori/.local/lib/python3.7/site-packages/telegram/ext/_handler.py", line 137, in handle_update
    return await self.callback(update, context)
  File "/home/bori/dev/py/beud/misc/access_control.py", line 15, in wrapped
    return await func(update, context, *args, **kwargs)
  File "/home/bori/dev/py/beud/beubot/flows/prompt_handlers/nominal_phlr.py", line 128, in reject_hlr
    orders = context.bot_data[int(update.effective_user.id)]['orders'].remove()
TypeError: remove() takes exactly one argument (0 given)
2022-06-15 00:42:32,827 | apscheduler.scheduler | INFO | start:171 | Scheduler started
2022-06-15 00:42:32,828 | telegram.ext._application | INFO | start:492 | Application started
2022-06-15 00:42:45,246 | apscheduler.scheduler | INFO | start:171 | Scheduler started
2022-06-15 00:42:45,246 | telegram.ext._application | INFO | start:492 | Application started
2022-06-15 00:42:45,603 | telegram.ext._application | ERROR | process_error:1484 | No error handlers are registered, logging exception.
Traceback (most recent call last):
  File "/home/bori/.local/lib/python3.7/site-packages/telegram/ext/_application.py", line 970, in process_update
    await coroutine
  File "/home/bori/.local/lib/python3.7/site-packages/telegram/ext/_handler.py", line 137, in handle_update
    return await self.callback(update, context)
  File "/home/bori/dev/py/beud/misc/access_control.py", line 15, in wrapped
    return await func(update, context, *args, **kwargs)
  File "/home/bori/dev/py/beud/beubot/flows/prompt_handlers/nominal_phlr.py", line 149, in view_pending_orders_hlr
    text = 'An order for ' + order['food'] + ' from '+ str(order['from_name']) +  ' is pending',
KeyError: 'from_name'
2022-06-15 00:43:07,201 | telegram.ext._application | INFO | stop:523 | Application is stopping. This might take a moment.
2022-06-15 00:43:07,202 | apscheduler.scheduler | INFO | shutdown:202 | Scheduler has been shut down
2022-06-15 00:43:07,212 | telegram.ext._application | INFO | stop:548 | Application.stop() complete
2022-06-15 00:43:12,708 | apscheduler.scheduler | INFO | start:171 | Scheduler started
2022-06-15 00:43:12,712 | telegram.ext._application | INFO | start:492 | Application started
2022-06-15 00:44:44,947 | telegram.ext._application | ERROR | process_error:1484 | No error handlers are registered, logging exception.
Traceback (most recent call last):
  File "/home/bori/.local/lib/python3.7/site-packages/telegram/ext/_application.py", line 970, in process_update
    await coroutine
  File "/home/bori/.local/lib/python3.7/site-packages/telegram/ext/_handler.py", line 137, in handle_update
    return await self.callback(update, context)
  File "/home/bori/dev/py/beud/misc/access_control.py", line 15, in wrapped
    return await func(update, context, *args, **kwargs)
  File "/home/bori/dev/py/beud/beubot/flows/prompt_handlers/nominal_phlr.py", line 98, in food_inline_hlr
    'from_name': update.callback_query.from_user.first_name
TypeError: object NoneType can't be used in 'await' expression
2022-06-15 00:45:07,100 | apscheduler.scheduler | INFO | start:171 | Scheduler started
2022-06-15 00:45:07,101 | telegram.ext._application | INFO | start:492 | Application started
2022-06-15 00:45:27,989 | apscheduler.scheduler | INFO | start:171 | Scheduler started
2022-06-15 00:45:27,991 | telegram.ext._application | INFO | start:492 | Application started
2022-06-15 00:45:40,546 | telegram.ext._application | INFO | stop:523 | Application is stopping. This might take a moment.
2022-06-15 00:45:40,547 | apscheduler.scheduler | INFO | shutdown:202 | Scheduler has been shut down
2022-06-15 00:45:40,558 | telegram.ext._application | INFO | stop:548 | Application.stop() complete
2022-06-15 00:45:43,443 | apscheduler.scheduler | INFO | start:171 | Scheduler started
2022-06-15 00:45:43,444 | telegram.ext._application | INFO | start:492 | Application started
2022-06-15 00:45:53,683 | telegram.ext._application | ERROR | process_error:1484 | No error handlers are registered, logging exception.
Traceback (most recent call last):
  File "/home/bori/.local/lib/python3.7/site-packages/telegram/ext/_application.py", line 970, in process_update
    await coroutine
  File "/home/bori/.local/lib/python3.7/site-packages/telegram/ext/_handler.py", line 137, in handle_update
    return await self.callback(update, context)
  File "/home/bori/dev/py/beud/misc/access_control.py", line 15, in wrapped
    return await func(update, context, *args, **kwargs)
  File "/home/bori/dev/py/beud/beubot/flows/prompt_handlers/nominal_phlr.py", line 98, in food_inline_hlr
    'from_name': update.callback_query.from_user.full_name,
TypeError: object NoneType can't be used in 'await' expression
2022-06-15 00:46:05,487 | apscheduler.scheduler | INFO | start:171 | Scheduler started
2022-06-15 00:46:05,488 | telegram.ext._application | INFO | start:492 | Application started
2022-06-15 00:46:11,963 | telegram.ext._application | ERROR | process_error:1484 | No error handlers are registered, logging exception.
Traceback (most recent call last):
  File "/home/bori/.local/lib/python3.7/site-packages/telegram/ext/_application.py", line 970, in process_update
    await coroutine
  File "/home/bori/.local/lib/python3.7/site-packages/telegram/ext/_handler.py", line 137, in handle_update
    return await self.callback(update, context)
  File "/home/bori/dev/py/beud/misc/access_control.py", line 15, in wrapped
    return await func(update, context, *args, **kwargs)
  File "/home/bori/dev/py/beud/beubot/flows/prompt_handlers/nominal_phlr.py", line 89, in food_inline_hlr
    for_rest = context.user_data['selected_restaurant']
KeyError: 'selected_restaurant'
2022-06-15 00:47:04,570 | apscheduler.scheduler | INFO | start:171 | Scheduler started
2022-06-15 00:47:04,570 | telegram.ext._application | INFO | start:492 | Application started
2022-06-15 00:47:34,591 | telegram.ext._application | ERROR | process_error:1484 | No error handlers are registered, logging exception.
Traceback (most recent call last):
  File "/home/bori/.local/lib/python3.7/site-packages/telegram/ext/_application.py", line 970, in process_update
    await coroutine
  File "/home/bori/.local/lib/python3.7/site-packages/telegram/ext/_handler.py", line 137, in handle_update
    return await self.callback(update, context)
  File "/home/bori/dev/py/beud/misc/access_control.py", line 15, in wrapped
    return await func(update, context, *args, **kwargs)
  File "/home/bori/dev/py/beud/beubot/flows/prompt_handlers/nominal_phlr.py", line 97, in food_inline_hlr
    'from_name': update.callback_query.from_user,
TypeError: object NoneType can't be used in 'await' expression
2022-06-15 00:47:54,101 | apscheduler.scheduler | INFO | start:171 | Scheduler started
2022-06-15 00:47:54,101 | telegram.ext._application | INFO | start:492 | Application started
2022-06-15 00:48:02,885 | telegram.ext._application | ERROR | process_error:1484 | No error handlers are registered, logging exception.
Traceback (most recent call last):
  File "/home/bori/.local/lib/python3.7/site-packages/telegram/ext/_application.py", line 970, in process_update
    await coroutine
  File "/home/bori/.local/lib/python3.7/site-packages/telegram/ext/_handler.py", line 137, in handle_update
    return await self.callback(update, context)
  File "/home/bori/dev/py/beud/misc/access_control.py", line 15, in wrapped
    return await func(update, context, *args, **kwargs)
  File "/home/bori/dev/py/beud/beubot/flows/prompt_handlers/nominal_phlr.py", line 96, in food_inline_hlr
    'from_id': update.callback_query.from_user.id,
TypeError: object NoneType can't be used in 'await' expression
2022-06-15 00:48:15,383 | telegram.ext._application | INFO | stop:523 | Application is stopping. This might take a moment.
2022-06-15 00:48:15,384 | apscheduler.scheduler | INFO | shutdown:202 | Scheduler has been shut down
2022-06-15 00:48:15,395 | telegram.ext._application | INFO | stop:548 | Application.stop() complete
2022-06-15 00:48:20,126 | apscheduler.scheduler | INFO | start:171 | Scheduler started
2022-06-15 00:48:20,126 | telegram.ext._application | INFO | start:492 | Application started
2022-06-15 00:48:21,583 | telegram.ext._application | ERROR | process_error:1484 | No error handlers are registered, logging exception.
Traceback (most recent call last):
  File "/home/bori/.local/lib/python3.7/site-packages/telegram/ext/_application.py", line 970, in process_update
    await coroutine
  File "/home/bori/.local/lib/python3.7/site-packages/telegram/ext/_handler.py", line 137, in handle_update
    return await self.callback(update, context)
  File "/home/bori/dev/py/beud/misc/access_control.py", line 15, in wrapped
    return await func(update, context, *args, **kwargs)
  File "/home/bori/dev/py/beud/beubot/flows/prompt_handlers/nominal_phlr.py", line 96, in food_inline_hlr
    'from_id': update.callback_query.from_user.id,
TypeError: object NoneType can't be used in 'await' expression
2022-06-15 00:48:40,003 | telegram.ext._application | ERROR | process_error:1484 | No error handlers are registered, logging exception.
Traceback (most recent call last):
  File "/home/bori/.local/lib/python3.7/site-packages/telegram/ext/_application.py", line 970, in process_update
    await coroutine
  File "/home/bori/.local/lib/python3.7/site-packages/telegram/ext/_handler.py", line 137, in handle_update
    return await self.callback(update, context)
  File "/home/bori/dev/py/beud/misc/access_control.py", line 15, in wrapped
    return await func(update, context, *args, **kwargs)
  File "/home/bori/dev/py/beud/beubot/flows/prompt_handlers/nominal_phlr.py", line 148, in view_pending_orders_hlr
    text = 'An order for ' + order['food'] + ' from '+ str(order['from_name']) +  ' is pending',
KeyError: 'from_name'
2022-06-15 00:50:15,968 | apscheduler.scheduler | INFO | start:171 | Scheduler started
2022-06-15 00:50:15,970 | telegram.ext._application | INFO | start:492 | Application started
2022-06-15 00:50:20,713 | apscheduler.scheduler | INFO | start:171 | Scheduler started
2022-06-15 00:50:20,719 | telegram.ext._application | INFO | start:492 | Application started
2022-06-15 00:50:28,773 | telegram.ext._application | ERROR | process_error:1484 | No error handlers are registered, logging exception.
Traceback (most recent call last):
  File "/home/bori/.local/lib/python3.7/site-packages/telegram/ext/_application.py", line 970, in process_update
    await coroutine
  File "/home/bori/.local/lib/python3.7/site-packages/telegram/ext/_handler.py", line 137, in handle_update
    return await self.callback(update, context)
  File "/home/bori/dev/py/beud/misc/access_control.py", line 15, in wrapped
    return await func(update, context, *args, **kwargs)
  File "/home/bori/dev/py/beud/beubot/flows/prompt_handlers/nominal_phlr.py", line 127, in reject_hlr
    orders = context.bot_data[int(update.effective_user.id)]['orders'].remove()
TypeError: remove() takes exactly one argument (0 given)
2022-06-15 00:51:01,998 | apscheduler.scheduler | INFO | start:171 | Scheduler started
2022-06-15 00:51:01,998 | telegram.ext._application | INFO | start:492 | Application started
2022-06-15 00:51:49,714 | telegram.ext._application | ERROR | process_error:1484 | No error handlers are registered, logging exception.
Traceback (most recent call last):
  File "/home/bori/.local/lib/python3.7/site-packages/telegram/ext/_application.py", line 970, in process_update
    await coroutine
  File "/home/bori/.local/lib/python3.7/site-packages/telegram/ext/_handler.py", line 137, in handle_update
    return await self.callback(update, context)
  File "/home/bori/dev/py/beud/misc/access_control.py", line 15, in wrapped
    return await func(update, context, *args, **kwargs)
  File "/home/bori/dev/py/beud/beubot/flows/prompt_handlers/nominal_phlr.py", line 127, in reject_hlr
    orders = context.bot_data[int(update.effective_user.id)]['orders']['pending']
TypeError: list indices must be integers or slices, not str
2022-06-15 00:53:52,655 | apscheduler.scheduler | INFO | start:171 | Scheduler started
2022-06-15 00:53:52,657 | telegram.ext._application | INFO | start:492 | Application started
2022-06-15 00:54:55,839 | apscheduler.scheduler | INFO | start:171 | Scheduler started
2022-06-15 00:54:55,839 | telegram.ext._application | INFO | start:492 | Application started
2022-06-15 00:55:09,901 | apscheduler.scheduler | INFO | start:171 | Scheduler started
2022-06-15 00:55:09,902 | telegram.ext._application | INFO | start:492 | Application started
2022-06-15 00:55:38,813 | apscheduler.scheduler | INFO | start:171 | Scheduler started
2022-06-15 00:55:38,818 | telegram.ext._application | INFO | start:492 | Application started
2022-06-15 00:56:22,345 | apscheduler.scheduler | INFO | start:171 | Scheduler started
2022-06-15 00:56:22,345 | telegram.ext._application | INFO | start:492 | Application started
2022-06-15 00:56:39,058 | apscheduler.scheduler | INFO | start:171 | Scheduler started
2022-06-15 00:56:39,058 | telegram.ext._application | INFO | start:492 | Application started
2022-06-15 00:56:52,545 | apscheduler.scheduler | INFO | start:171 | Scheduler started
2022-06-15 00:56:52,546 | telegram.ext._application | INFO | start:492 | Application started
2022-06-15 01:07:48,449 | telegram.ext._application | ERROR | process_error:1484 | No error handlers are registered, logging exception.
Traceback (most recent call last):
  File "/home/bori/.local/lib/python3.7/site-packages/telegram/ext/_application.py", line 970, in process_update
    await coroutine
  File "/home/bori/.local/lib/python3.7/site-packages/telegram/ext/_handler.py", line 137, in handle_update
    return await self.callback(update, context)
  File "/home/bori/dev/py/beud/misc/access_control.py", line 15, in wrapped
    return await func(update, context, *args, **kwargs)
  File "/home/bori/dev/py/beud/beubot/flows/prompt_handlers/nominal_phlr.py", line 96, in food_inline_hlr
    'from_id': update.callback_query.from_user.id,
TypeError: object NoneType can't be used in 'await' expression
2022-06-15 01:08:07,890 | apscheduler.scheduler | INFO | start:171 | Scheduler started
2022-06-15 01:08:07,893 | telegram.ext._application | INFO | start:492 | Application started
2022-06-15 01:08:33,987 | apscheduler.scheduler | INFO | start:171 | Scheduler started
2022-06-15 01:08:33,987 | telegram.ext._application | INFO | start:492 | Application started
2022-06-15 01:10:01,401 | apscheduler.scheduler | INFO | start:171 | Scheduler started
2022-06-15 01:10:01,402 | telegram.ext._application | INFO | start:492 | Application started
2022-06-15 01:10:33,867 | apscheduler.scheduler | INFO | start:171 | Scheduler started
2022-06-15 01:10:33,867 | telegram.ext._application | INFO | start:492 | Application started
2022-06-15 01:13:03,547 | apscheduler.scheduler | INFO | start:171 | Scheduler started
2022-06-15 01:13:03,554 | telegram.ext._application | INFO | start:492 | Application started
2022-06-15 01:13:33,464 | apscheduler.scheduler | INFO | start:171 | Scheduler started
2022-06-15 01:13:33,465 | telegram.ext._application | INFO | start:492 | Application started
2022-06-15 01:14:27,558 | apscheduler.scheduler | INFO | start:171 | Scheduler started
2022-06-15 01:14:27,558 | telegram.ext._application | INFO | start:492 | Application started
2022-06-15 01:14:41,996 | telegram.ext._updater | ERROR | _network_loop_retry:569 | Error while getting Updates: httpx HTTPError: [Errno -2] Name or service not known
2022-06-15 01:14:41,998 | telegram.ext._application | ERROR | process_error:1484 | No error handlers are registered, logging exception.
Traceback (most recent call last):
  File "/home/bori/.local/lib/python3.7/site-packages/httpcore/_exceptions.py", line 8, in map_exceptions
    yield
  File "/home/bori/.local/lib/python3.7/site-packages/httpcore/backends/asyncio.py", line 112, in connect_tcp
    local_host=local_address,
  File "/home/bori/.local/lib/python3.7/site-packages/anyio/_core/_sockets.py", line 190, in connect_tcp
    target_host, remote_port, family=family, type=socket.SOCK_STREAM
  File "/home/bori/.local/lib/python3.7/site-packages/anyio/_core/_sockets.py", line 497, in getaddrinfo
    encoded_host, port, family=family, type=type, proto=proto, flags=flags
  File "/home/bori/.local/lib/python3.7/site-packages/anyio/_backends/_asyncio.py", line 1755, in getaddrinfo
    host, port, family=family, type=type, proto=proto, flags=flags
  File "/usr/lib/python3.7/asyncio/base_events.py", line 792, in getaddrinfo
    None, getaddr_func, host, port, family, type, proto, flags)
  File "/usr/lib/python3.7/concurrent/futures/thread.py", line 57, in run
    result = self.fn(*self.args, **self.kwargs)
  File "/usr/lib/python3.7/socket.py", line 752, in getaddrinfo
    for res in _socket.getaddrinfo(host, port, family, type, proto, flags):
socket.gaierror: [Errno -2] Name or service not known

During handling of the above exception, another exception occurred:

Traceback (most recent call last):
  File "/home/bori/.local/lib/python3.7/site-packages/httpx/_transports/default.py", line 60, in map_httpcore_exceptions
    yield
  File "/home/bori/.local/lib/python3.7/site-packages/httpx/_transports/default.py", line 353, in handle_async_request
    resp = await self._pool.handle_async_request(req)
  File "/home/bori/.local/lib/python3.7/site-packages/httpcore/_async/connection_pool.py", line 253, in handle_async_request
    raise exc
  File "/home/bori/.local/lib/python3.7/site-packages/httpcore/_async/connection_pool.py", line 237, in handle_async_request
    response = await connection.handle_async_request(request)
  File "/home/bori/.local/lib/python3.7/site-packages/httpcore/_async/connection.py", line 86, in handle_async_request
    raise exc
  File "/home/bori/.local/lib/python3.7/site-packages/httpcore/_async/connection.py", line 63, in handle_async_request
    stream = await self._connect(request)
  File "/home/bori/.local/lib/python3.7/site-packages/httpcore/_async/connection.py", line 111, in _connect
    stream = await self._network_backend.connect_tcp(**kwargs)
  File "/home/bori/.local/lib/python3.7/site-packages/httpcore/backends/auto.py", line 30, in connect_tcp
    host, port, timeout=timeout, local_address=local_address
  File "/home/bori/.local/lib/python3.7/site-packages/httpcore/backends/asyncio.py", line 112, in connect_tcp
    local_host=local_address,
  File "/usr/lib/python3.7/contextlib.py", line 130, in __exit__
    self.gen.throw(type, value, traceback)
  File "/home/bori/.local/lib/python3.7/site-packages/httpcore/_exceptions.py", line 12, in map_exceptions
    raise to_exc(exc)
httpcore.ConnectError: [Errno -2] Name or service not known

The above exception was the direct cause of the following exception:

Traceback (most recent call last):
  File "/home/bori/.local/lib/python3.7/site-packages/telegram/request/_httpxrequest.py", line 180, in do_request
    data=data,
  File "/home/bori/.local/lib/python3.7/site-packages/httpx/_client.py", line 1527, in request
    return await self.send(request, auth=auth, follow_redirects=follow_redirects)
  File "/home/bori/.local/lib/python3.7/site-packages/httpx/_client.py", line 1618, in send
    history=[],
  File "/home/bori/.local/lib/python3.7/site-packages/httpx/_client.py", line 1645, in _send_handling_auth
    history=history,
  File "/home/bori/.local/lib/python3.7/site-packages/httpx/_client.py", line 1679, in _send_handling_redirects
    response = await self._send_single_request(request)
  File "/home/bori/.local/lib/python3.7/site-packages/httpx/_client.py", line 1716, in _send_single_request
    response = await transport.handle_async_request(request)
  File "/home/bori/.local/lib/python3.7/site-packages/httpx/_transports/default.py", line 353, in handle_async_request
    resp = await self._pool.handle_async_request(req)
  File "/usr/lib/python3.7/contextlib.py", line 130, in __exit__
    self.gen.throw(type, value, traceback)
  File "/home/bori/.local/lib/python3.7/site-packages/httpx/_transports/default.py", line 77, in map_httpcore_exceptions
    raise mapped_exc(message) from exc
httpx.ConnectError: [Errno -2] Name or service not known

The above exception was the direct cause of the following exception:

Traceback (most recent call last):
  File "/home/bori/.local/lib/python3.7/site-packages/telegram/ext/_updater.py", line 556, in _network_loop_retry
    if not await action_cb():
  File "/home/bori/.local/lib/python3.7/site-packages/telegram/ext/_updater.py", line 318, in polling_action_cb
    raise exc
  File "/home/bori/.local/lib/python3.7/site-packages/telegram/ext/_updater.py", line 310, in polling_action_cb
    allowed_updates=allowed_updates,
  File "/home/bori/.local/lib/python3.7/site-packages/telegram/ext/_extbot.py", line 294, in get_updates
    api_kwargs=api_kwargs,
  File "/home/bori/.local/lib/python3.7/site-packages/telegram/_bot.py", line 236, in decorator
    result = await func(*args, **kwargs)
  File "/home/bori/.local/lib/python3.7/site-packages/telegram/_bot.py", line 3778, in get_updates
    api_kwargs=api_kwargs,
  File "/home/bori/.local/lib/python3.7/site-packages/telegram/_bot.py", line 315, in _post
    pool_timeout=pool_timeout,
  File "/home/bori/.local/lib/python3.7/site-packages/telegram/request/_baserequest.py", line 169, in post
    pool_timeout=pool_timeout,
  File "/home/bori/.local/lib/python3.7/site-packages/telegram/request/_baserequest.py", line 285, in _request_wrapper
    raise exc
  File "/home/bori/.local/lib/python3.7/site-packages/telegram/request/_baserequest.py", line 278, in _request_wrapper
    pool_timeout=pool_timeout,
  File "/home/bori/.local/lib/python3.7/site-packages/telegram/request/_httpxrequest.py", line 195, in do_request
    raise NetworkError(f"httpx HTTPError: {err}") from err
telegram.error.NetworkError: httpx HTTPError: [Errno -2] Name or service not known
2022-06-15 01:14:43,004 | telegram.ext._updater | ERROR | _network_loop_retry:569 | Error while getting Updates: httpx HTTPError: [Errno -2] Name or service not known
2022-06-15 01:14:43,005 | telegram.ext._application | ERROR | process_error:1484 | No error handlers are registered, logging exception.
Traceback (most recent call last):
  File "/home/bori/.local/lib/python3.7/site-packages/httpcore/_exceptions.py", line 8, in map_exceptions
    yield
  File "/home/bori/.local/lib/python3.7/site-packages/httpcore/backends/asyncio.py", line 112, in connect_tcp
    local_host=local_address,
  File "/home/bori/.local/lib/python3.7/site-packages/anyio/_core/_sockets.py", line 190, in connect_tcp
    target_host, remote_port, family=family, type=socket.SOCK_STREAM
  File "/home/bori/.local/lib/python3.7/site-packages/anyio/_core/_sockets.py", line 497, in getaddrinfo
    encoded_host, port, family=family, type=type, proto=proto, flags=flags
  File "/home/bori/.local/lib/python3.7/site-packages/anyio/_backends/_asyncio.py", line 1755, in getaddrinfo
    host, port, family=family, type=type, proto=proto, flags=flags
  File "/usr/lib/python3.7/asyncio/base_events.py", line 792, in getaddrinfo
    None, getaddr_func, host, port, family, type, proto, flags)
  File "/usr/lib/python3.7/concurrent/futures/thread.py", line 57, in run
    result = self.fn(*self.args, **self.kwargs)
  File "/usr/lib/python3.7/socket.py", line 752, in getaddrinfo
    for res in _socket.getaddrinfo(host, port, family, type, proto, flags):
socket.gaierror: [Errno -2] Name or service not known

During handling of the above exception, another exception occurred:

Traceback (most recent call last):
  File "/home/bori/.local/lib/python3.7/site-packages/httpx/_transports/default.py", line 60, in map_httpcore_exceptions
    yield
  File "/home/bori/.local/lib/python3.7/site-packages/httpx/_transports/default.py", line 353, in handle_async_request
    resp = await self._pool.handle_async_request(req)
  File "/home/bori/.local/lib/python3.7/site-packages/httpcore/_async/connection_pool.py", line 253, in handle_async_request
    raise exc
  File "/home/bori/.local/lib/python3.7/site-packages/httpcore/_async/connection_pool.py", line 237, in handle_async_request
    response = await connection.handle_async_request(request)
  File "/home/bori/.local/lib/python3.7/site-packages/httpcore/_async/connection.py", line 86, in handle_async_request
    raise exc
  File "/home/bori/.local/lib/python3.7/site-packages/httpcore/_async/connection.py", line 63, in handle_async_request
    stream = await self._connect(request)
  File "/home/bori/.local/lib/python3.7/site-packages/httpcore/_async/connection.py", line 111, in _connect
    stream = await self._network_backend.connect_tcp(**kwargs)
  File "/home/bori/.local/lib/python3.7/site-packages/httpcore/backends/auto.py", line 30, in connect_tcp
    host, port, timeout=timeout, local_address=local_address
  File "/home/bori/.local/lib/python3.7/site-packages/httpcore/backends/asyncio.py", line 112, in connect_tcp
    local_host=local_address,
  File "/usr/lib/python3.7/contextlib.py", line 130, in __exit__
    self.gen.throw(type, value, traceback)
  File "/home/bori/.local/lib/python3.7/site-packages/httpcore/_exceptions.py", line 12, in map_exceptions
    raise to_exc(exc)
httpcore.ConnectError: [Errno -2] Name or service not known

The above exception was the direct cause of the following exception:

Traceback (most recent call last):
  File "/home/bori/.local/lib/python3.7/site-packages/telegram/request/_httpxrequest.py", line 180, in do_request
    data=data,
  File "/home/bori/.local/lib/python3.7/site-packages/httpx/_client.py", line 1527, in request
    return await self.send(request, auth=auth, follow_redirects=follow_redirects)
  File "/home/bori/.local/lib/python3.7/site-packages/httpx/_client.py", line 1618, in send
    history=[],
  File "/home/bori/.local/lib/python3.7/site-packages/httpx/_client.py", line 1645, in _send_handling_auth
    history=history,
  File "/home/bori/.local/lib/python3.7/site-packages/httpx/_client.py", line 1679, in _send_handling_redirects
    response = await self._send_single_request(request)
  File "/home/bori/.local/lib/python3.7/site-packages/httpx/_client.py", line 1716, in _send_single_request
    response = await transport.handle_async_request(request)
  File "/home/bori/.local/lib/python3.7/site-packages/httpx/_transports/default.py", line 353, in handle_async_request
    resp = await self._pool.handle_async_request(req)
  File "/usr/lib/python3.7/contextlib.py", line 130, in __exit__
    self.gen.throw(type, value, traceback)
  File "/home/bori/.local/lib/python3.7/site-packages/httpx/_transports/default.py", line 77, in map_httpcore_exceptions
    raise mapped_exc(message) from exc
httpx.ConnectError: [Errno -2] Name or service not known

The above exception was the direct cause of the following exception:

Traceback (most recent call last):
  File "/home/bori/.local/lib/python3.7/site-packages/telegram/ext/_updater.py", line 556, in _network_loop_retry
    if not await action_cb():
  File "/home/bori/.local/lib/python3.7/site-packages/telegram/ext/_updater.py", line 318, in polling_action_cb
    raise exc
  File "/home/bori/.local/lib/python3.7/site-packages/telegram/ext/_updater.py", line 310, in polling_action_cb
    allowed_updates=allowed_updates,
  File "/home/bori/.local/lib/python3.7/site-packages/telegram/ext/_extbot.py", line 294, in get_updates
    api_kwargs=api_kwargs,
  File "/home/bori/.local/lib/python3.7/site-packages/telegram/_bot.py", line 236, in decorator
    result = await func(*args, **kwargs)
  File "/home/bori/.local/lib/python3.7/site-packages/telegram/_bot.py", line 3778, in get_updates
    api_kwargs=api_kwargs,
  File "/home/bori/.local/lib/python3.7/site-packages/telegram/_bot.py", line 315, in _post
    pool_timeout=pool_timeout,
  File "/home/bori/.local/lib/python3.7/site-packages/telegram/request/_baserequest.py", line 169, in post
    pool_timeout=pool_timeout,
  File "/home/bori/.local/lib/python3.7/site-packages/telegram/request/_baserequest.py", line 285, in _request_wrapper
    raise exc
  File "/home/bori/.local/lib/python3.7/site-packages/telegram/request/_baserequest.py", line 278, in _request_wrapper
    pool_timeout=pool_timeout,
  File "/home/bori/.local/lib/python3.7/site-packages/telegram/request/_httpxrequest.py", line 195, in do_request
    raise NetworkError(f"httpx HTTPError: {err}") from err
telegram.error.NetworkError: httpx HTTPError: [Errno -2] Name or service not known
2022-06-15 01:14:57,968 | apscheduler.scheduler | INFO | start:171 | Scheduler started
2022-06-15 01:14:57,968 | telegram.ext._application | INFO | start:492 | Application started
2022-06-15 01:16:14,871 | apscheduler.scheduler | INFO | start:171 | Scheduler started
2022-06-15 01:16:14,875 | telegram.ext._application | INFO | start:492 | Application started
2022-06-15 01:16:44,194 | apscheduler.scheduler | INFO | start:171 | Scheduler started
2022-06-15 01:16:44,195 | telegram.ext._application | INFO | start:492 | Application started
2022-06-15 01:17:23,554 | telegram.ext._application | ERROR | process_error:1484 | No error handlers are registered, logging exception.
Traceback (most recent call last):
  File "/home/bori/.local/lib/python3.7/site-packages/telegram/ext/_application.py", line 970, in process_update
    await coroutine
  File "/home/bori/.local/lib/python3.7/site-packages/telegram/ext/_handler.py", line 137, in handle_update
    return await self.callback(update, context)
  File "/home/bori/dev/py/beud/misc/access_control.py", line 15, in wrapped
    return await func(update, context, *args, **kwargs)
  File "/home/bori/dev/py/beud/beubot/flows/prompt_handlers/nominal_phlr.py", line 194, in view_accepted_orders_hlr
    reply_markup=InlineKeyboardMarkup(keyboard))
UnboundLocalError: local variable 'keyboard' referenced before assignment
2022-06-15 01:17:40,422 | apscheduler.scheduler | INFO | start:171 | Scheduler started
2022-06-15 01:17:40,422 | telegram.ext._application | INFO | start:492 | Application started
2022-06-15 01:17:59,101 | apscheduler.scheduler | INFO | start:171 | Scheduler started
2022-06-15 01:17:59,103 | telegram.ext._application | INFO | start:492 | Application started
2022-06-15 01:19:20,260 | apscheduler.scheduler | INFO | start:171 | Scheduler started
2022-06-15 01:19:20,260 | telegram.ext._application | INFO | start:492 | Application started
2022-06-15 01:20:54,373 | apscheduler.scheduler | INFO | start:171 | Scheduler started
2022-06-15 01:20:54,373 | telegram.ext._application | INFO | start:492 | Application started
2022-06-15 01:21:20,905 | apscheduler.scheduler | INFO | start:171 | Scheduler started
2022-06-15 01:21:20,906 | telegram.ext._application | INFO | start:492 | Application started
2022-06-15 01:22:59,367 | apscheduler.scheduler | INFO | start:171 | Scheduler started
2022-06-15 01:22:59,369 | telegram.ext._application | INFO | start:492 | Application started
2022-06-15 01:23:13,976 | apscheduler.scheduler | INFO | start:171 | Scheduler started
2022-06-15 01:23:13,977 | telegram.ext._application | INFO | start:492 | Application started
2022-06-15 01:23:17,709 | telegram.ext._application | ERROR | process_error:1484 | No error handlers are registered, logging exception.
Traceback (most recent call last):
  File "/home/bori/.local/lib/python3.7/site-packages/telegram/ext/_application.py", line 970, in process_update
    await coroutine
  File "/home/bori/.local/lib/python3.7/site-packages/telegram/ext/_handler.py", line 137, in handle_update
    return await self.callback(update, context)
  File "/home/bori/dev/py/beud/misc/access_control.py", line 15, in wrapped
    return await func(update, context, *args, **kwargs)
  File "/home/bori/dev/py/beud/beubot/flows/prompt_handlers/nominal_phlr.py", line 134, in accept_hlr
    order['state'] == 'accepted'
KeyError: 'state'
2022-06-15 01:23:39,953 | apscheduler.scheduler | INFO | start:171 | Scheduler started
2022-06-15 01:23:39,955 | telegram.ext._application | INFO | start:492 | Application started
2022-06-15 01:24:49,585 | apscheduler.scheduler | INFO | start:171 | Scheduler started
2022-06-15 01:24:49,585 | telegram.ext._application | INFO | start:492 | Application started
2022-06-15 01:27:22,545 | telegram.ext._application | INFO | stop:523 | Application is stopping. This might take a moment.
2022-06-15 01:27:22,545 | apscheduler.scheduler | INFO | shutdown:202 | Scheduler has been shut down
2022-06-15 01:27:22,556 | telegram.ext._application | INFO | stop:548 | Application.stop() complete
2022-06-15 01:28:01,764 | apscheduler.scheduler | INFO | start:171 | Scheduler started
2022-06-15 01:28:01,766 | telegram.ext._application | INFO | start:492 | Application started
2022-06-15 01:28:34,754 | apscheduler.scheduler | INFO | start:171 | Scheduler started
2022-06-15 01:28:34,757 | telegram.ext._application | INFO | start:492 | Application started
2022-06-15 01:29:03,438 | apscheduler.scheduler | INFO | start:171 | Scheduler started
2022-06-15 01:29:03,438 | telegram.ext._application | INFO | start:492 | Application started
2022-06-15 01:29:17,043 | telegram.ext._application | ERROR | process_error:1484 | No error handlers are registered, logging exception.
Traceback (most recent call last):
  File "/home/bori/.local/lib/python3.7/site-packages/telegram/ext/_application.py", line 970, in process_update
    await coroutine
  File "/home/bori/.local/lib/python3.7/site-packages/telegram/ext/_handler.py", line 137, in handle_update
    return await self.callback(update, context)
  File "/home/bori/dev/py/beud/misc/access_control.py", line 15, in wrapped
    return await func(update, context, *args, **kwargs)
  File "/home/bori/dev/py/beud/beubot/flows/prompt_handlers/nominal_phlr.py", line 154, in reject_hlr
    await order['message'].delete()
  File "/home/bori/.local/lib/python3.7/site-packages/telegram/_message.py", line 2531, in delete
    api_kwargs=api_kwargs,
  File "/home/bori/.local/lib/python3.7/site-packages/telegram/_bot.py", line 236, in decorator
    result = await func(*args, **kwargs)
  File "/home/bori/.local/lib/python3.7/site-packages/telegram/_bot.py", line 719, in delete_message
    api_kwargs=api_kwargs,
  File "/home/bori/.local/lib/python3.7/site-packages/telegram/_bot.py", line 315, in _post
    pool_timeout=pool_timeout,
  File "/home/bori/.local/lib/python3.7/site-packages/telegram/request/_baserequest.py", line 169, in post
    pool_timeout=pool_timeout,
  File "/home/bori/.local/lib/python3.7/site-packages/telegram/request/_baserequest.py", line 325, in _request_wrapper
    raise BadRequest(message)
telegram.error.BadRequest: Message to delete not found
2022-06-15 01:29:35,950 | apscheduler.scheduler | INFO | start:171 | Scheduler started
2022-06-15 01:29:35,954 | telegram.ext._application | INFO | start:492 | Application started
2022-06-15 01:31:43,156 | apscheduler.scheduler | INFO | start:171 | Scheduler started
2022-06-15 01:31:43,156 | telegram.ext._application | INFO | start:492 | Application started
2022-06-15 01:32:15,820 | apscheduler.scheduler | INFO | start:171 | Scheduler started
2022-06-15 01:32:15,821 | telegram.ext._application | INFO | start:492 | Application started
2022-06-15 01:33:16,840 | apscheduler.scheduler | INFO | start:171 | Scheduler started
2022-06-15 01:33:16,843 | telegram.ext._application | INFO | start:492 | Application started
2022-06-15 01:34:41,213 | apscheduler.scheduler | INFO | start:171 | Scheduler started
2022-06-15 01:34:41,214 | telegram.ext._application | INFO | start:492 | Application started
2022-06-15 01:34:52,782 | apscheduler.scheduler | INFO | start:171 | Scheduler started
2022-06-15 01:34:52,783 | telegram.ext._application | INFO | start:492 | Application started
2022-06-15 01:34:59,979 | telegram.ext._application | ERROR | process_error:1484 | No error handlers are registered, logging exception.
Traceback (most recent call last):
  File "/home/bori/.local/lib/python3.7/site-packages/telegram/ext/_application.py", line 970, in process_update
    await coroutine
  File "/home/bori/.local/lib/python3.7/site-packages/telegram/ext/_handler.py", line 137, in handle_update
    return await self.callback(update, context)
  File "/home/bori/dev/py/beud/misc/access_control.py", line 15, in wrapped
    return await func(update, context, *args, **kwargs)
  File "/home/bori/dev/py/beud/beubot/flows/prompt_handlers/nominal_phlr.py", line 154, in prepare_hlr
    await order['message'].delete()
  File "/home/bori/.local/lib/python3.7/site-packages/telegram/_message.py", line 2531, in delete
    api_kwargs=api_kwargs,
  File "/home/bori/.local/lib/python3.7/site-packages/telegram/_bot.py", line 236, in decorator
    result = await func(*args, **kwargs)
  File "/home/bori/.local/lib/python3.7/site-packages/telegram/_bot.py", line 719, in delete_message
    api_kwargs=api_kwargs,
  File "/home/bori/.local/lib/python3.7/site-packages/telegram/_bot.py", line 315, in _post
    pool_timeout=pool_timeout,
  File "/home/bori/.local/lib/python3.7/site-packages/telegram/request/_baserequest.py", line 169, in post
    pool_timeout=pool_timeout,
  File "/home/bori/.local/lib/python3.7/site-packages/telegram/request/_baserequest.py", line 325, in _request_wrapper
    raise BadRequest(message)
telegram.error.BadRequest: Message to delete not found
2022-06-15 01:35:11,992 | apscheduler.scheduler | INFO | start:171 | Scheduler started
2022-06-15 01:35:11,993 | telegram.ext._application | INFO | start:492 | Application started
2022-06-15 01:35:49,903 | apscheduler.scheduler | INFO | start:171 | Scheduler started
2022-06-15 01:35:49,903 | telegram.ext._application | INFO | start:492 | Application started
2022-06-15 01:35:58,874 | apscheduler.scheduler | INFO | start:171 | Scheduler started
2022-06-15 01:35:58,875 | telegram.ext._application | INFO | start:492 | Application started
2022-06-15 01:36:23,082 | apscheduler.scheduler | INFO | start:171 | Scheduler started
2022-06-15 01:36:23,083 | telegram.ext._application | INFO | start:492 | Application started
2022-06-15 01:40:01,079 | apscheduler.scheduler | INFO | start:171 | Scheduler started
2022-06-15 01:40:01,080 | telegram.ext._application | INFO | start:492 | Application started
2022-06-15 01:49:23,808 | telegram.ext._application | INFO | stop:523 | Application is stopping. This might take a moment.
2022-06-15 01:49:23,809 | apscheduler.scheduler | INFO | shutdown:202 | Scheduler has been shut down
2022-06-15 01:49:23,820 | telegram.ext._application | INFO | stop:548 | Application.stop() complete
2022-06-15 01:49:32,621 | apscheduler.scheduler | INFO | start:171 | Scheduler started
2022-06-15 01:49:32,622 | telegram.ext._application | INFO | start:492 | Application started
2022-06-15 01:50:31,680 | telegram.ext._application | INFO | stop:523 | Application is stopping. This might take a moment.
2022-06-15 01:50:31,681 | apscheduler.scheduler | INFO | shutdown:202 | Scheduler has been shut down
2022-06-15 01:50:31,692 | telegram.ext._application | INFO | stop:548 | Application.stop() complete
2022-06-15 12:29:25,274 | apscheduler.scheduler | INFO | start:171 | Scheduler started
2022-06-15 12:29:25,294 | telegram.ext._application | INFO | start:492 | Application started
2022-06-15 12:29:34,413 | telegram.ext._application | INFO | stop:523 | Application is stopping. This might take a moment.
2022-06-15 12:29:34,413 | apscheduler.scheduler | INFO | shutdown:202 | Scheduler has been shut down
2022-06-15 12:29:34,424 | telegram.ext._application | INFO | stop:548 | Application.stop() complete
2022-06-15 12:29:49,435 | apscheduler.scheduler | INFO | start:171 | Scheduler started
2022-06-15 12:29:49,437 | telegram.ext._application | INFO | start:492 | Application started
2022-06-15 12:30:13,958 | telegram.ext._application | ERROR | process_error:1484 | No error handlers are registered, logging exception.
Traceback (most recent call last):
  File "/home/bori/.local/lib/python3.7/site-packages/telegram/ext/_application.py", line 970, in process_update
    await coroutine
  File "/home/bori/.local/lib/python3.7/site-packages/telegram/ext/_handler.py", line 137, in handle_update
    return await self.callback(update, context)
  File "/home/bori/dev/py/beud/misc/access_control.py", line 15, in wrapped
    return await func(update, context, *args, **kwargs)
  File "/home/bori/dev/py/beud/beubot/flows/prompt_handlers/nominal_phlr.py", line 207, in view_pending_orders_hlr
    reply_markup=InlineKeyboardMarkup(keyboard))
UnboundLocalError: local variable 'keyboard' referenced before assignment
2022-06-15 12:30:23,154 | apscheduler.scheduler | INFO | start:171 | Scheduler started
2022-06-15 12:30:23,159 | telegram.ext._application | INFO | start:492 | Application started
2022-06-15 12:30:34,738 | telegram.ext._application | INFO | stop:523 | Application is stopping. This might take a moment.
2022-06-15 12:30:34,739 | apscheduler.scheduler | INFO | shutdown:202 | Scheduler has been shut down
2022-06-15 12:30:34,749 | telegram.ext._application | INFO | stop:548 | Application.stop() complete
2022-06-15 12:30:37,243 | apscheduler.scheduler | INFO | start:171 | Scheduler started
2022-06-15 12:30:37,247 | telegram.ext._application | INFO | start:492 | Application started
2022-06-15 12:31:17,681 | apscheduler.scheduler | INFO | start:171 | Scheduler started
2022-06-15 12:31:17,684 | telegram.ext._application | INFO | start:492 | Application started
2022-06-15 12:31:37,793 | apscheduler.scheduler | INFO | start:171 | Scheduler started
2022-06-15 12:31:37,794 | telegram.ext._application | INFO | start:492 | Application started
2022-06-15 12:32:39,246 | apscheduler.scheduler | INFO | start:171 | Scheduler started
2022-06-15 12:32:39,247 | telegram.ext._application | INFO | start:492 | Application started
2022-06-15 12:33:30,647 | apscheduler.scheduler | INFO | start:171 | Scheduler started
2022-06-15 12:33:30,648 | telegram.ext._application | INFO | start:492 | Application started
2022-06-15 12:33:41,305 | apscheduler.scheduler | INFO | start:171 | Scheduler started
2022-06-15 12:33:41,305 | telegram.ext._application | INFO | start:492 | Application started
2022-06-15 12:33:59,142 | apscheduler.scheduler | INFO | start:171 | Scheduler started
2022-06-15 12:33:59,142 | telegram.ext._application | INFO | start:492 | Application started
2022-06-15 12:35:23,813 | apscheduler.scheduler | INFO | start:171 | Scheduler started
2022-06-15 12:35:23,814 | telegram.ext._application | INFO | start:492 | Application started
2022-06-15 12:38:26,818 | apscheduler.scheduler | INFO | start:171 | Scheduler started
2022-06-15 12:38:26,819 | telegram.ext._application | INFO | start:492 | Application started
2022-06-15 12:40:00,712 | apscheduler.scheduler | INFO | start:171 | Scheduler started
2022-06-15 12:40:00,715 | telegram.ext._application | INFO | start:492 | Application started
2022-06-15 12:40:20,446 | apscheduler.scheduler | INFO | start:171 | Scheduler started
2022-06-15 12:40:20,446 | telegram.ext._application | INFO | start:492 | Application started
2022-06-15 12:40:47,357 | apscheduler.scheduler | INFO | start:171 | Scheduler started
2022-06-15 12:40:47,357 | telegram.ext._application | INFO | start:492 | Application started
2022-06-15 12:41:11,190 | apscheduler.scheduler | INFO | start:171 | Scheduler started
2022-06-15 12:41:11,191 | telegram.ext._application | INFO | start:492 | Application started
2022-06-15 12:41:20,648 | apscheduler.scheduler | INFO | start:171 | Scheduler started
2022-06-15 12:41:20,648 | telegram.ext._application | INFO | start:492 | Application started
2022-06-15 12:45:15,445 | apscheduler.scheduler | INFO | start:171 | Scheduler started
2022-06-15 12:45:15,446 | telegram.ext._application | INFO | start:492 | Application started
2022-06-15 12:45:37,188 | apscheduler.scheduler | INFO | start:171 | Scheduler started
2022-06-15 12:45:37,189 | telegram.ext._application | INFO | start:492 | Application started
2022-06-15 12:46:11,427 | apscheduler.scheduler | INFO | start:171 | Scheduler started
2022-06-15 12:46:11,427 | telegram.ext._application | INFO | start:492 | Application started
2022-06-15 12:46:21,545 | apscheduler.scheduler | INFO | start:171 | Scheduler started
2022-06-15 12:46:21,545 | telegram.ext._application | INFO | start:492 | Application started
2022-06-15 12:47:21,405 | apscheduler.scheduler | INFO | start:171 | Scheduler started
2022-06-15 12:47:21,406 | telegram.ext._application | INFO | start:492 | Application started
2022-06-15 12:48:15,736 | apscheduler.scheduler | INFO | start:171 | Scheduler started
2022-06-15 12:48:15,736 | telegram.ext._application | INFO | start:492 | Application started
2022-06-15 12:48:49,370 | apscheduler.scheduler | INFO | start:171 | Scheduler started
2022-06-15 12:48:49,371 | telegram.ext._application | INFO | start:492 | Application started
2022-06-15 12:48:56,481 | telegram.ext._application | ERROR | process_error:1484 | No error handlers are registered, logging exception.
Traceback (most recent call last):
  File "/home/bori/.local/lib/python3.7/site-packages/telegram/ext/_application.py", line 970, in process_update
    await coroutine
  File "/home/bori/.local/lib/python3.7/site-packages/telegram/ext/_handler.py", line 137, in handle_update
    return await self.callback(update, context)
  File "/home/bori/dev/py/beud/misc/access_control.py", line 15, in wrapped
    return await func(update, context, *args, **kwargs)
  File "/home/bori/dev/py/beud/beubot/flows/prompt_handlers/nominal_phlr.py", line 229, in view_accepted_orders_hlr
    reply_markup=InlineKeyboardMarkup(keyboard))
  File "/home/bori/.local/lib/python3.7/site-packages/telegram/_bot.py", line 236, in decorator
    result = await func(*args, **kwargs)
  File "/home/bori/.local/lib/python3.7/site-packages/telegram/_bot.py", line 653, in send_message
    api_kwargs=api_kwargs,
  File "/home/bori/.local/lib/python3.7/site-packages/telegram/ext/_extbot.py", line 266, in _send_message
    api_kwargs=api_kwargs,
  File "/home/bori/.local/lib/python3.7/site-packages/telegram/_bot.py", line 353, in _send_message
    api_kwargs=api_kwargs,
  File "/home/bori/.local/lib/python3.7/site-packages/telegram/_bot.py", line 315, in _post
    pool_timeout=pool_timeout,
  File "/home/bori/.local/lib/python3.7/site-packages/telegram/request/_baserequest.py", line 169, in post
    pool_timeout=pool_timeout,
  File "/home/bori/.local/lib/python3.7/site-packages/telegram/request/_baserequest.py", line 325, in _request_wrapper
    raise BadRequest(message)
telegram.error.BadRequest: Can't parse entities: unexpected end tag at byte offset 60
2022-06-15 12:49:08,153 | apscheduler.scheduler | INFO | start:171 | Scheduler started
2022-06-15 12:49:08,159 | telegram.ext._application | INFO | start:492 | Application started
2022-06-15 12:50:04,532 | apscheduler.scheduler | INFO | start:171 | Scheduler started
2022-06-15 12:50:04,532 | telegram.ext._application | INFO | start:492 | Application started
2022-06-15 12:50:42,584 | apscheduler.scheduler | INFO | start:171 | Scheduler started
2022-06-15 12:50:42,584 | telegram.ext._application | INFO | start:492 | Application started
2022-06-15 12:51:48,933 | apscheduler.scheduler | INFO | start:171 | Scheduler started
2022-06-15 12:51:48,936 | telegram.ext._application | INFO | start:492 | Application started
2022-06-15 12:52:24,964 | apscheduler.scheduler | INFO | start:171 | Scheduler started
2022-06-15 12:52:24,964 | telegram.ext._application | INFO | start:492 | Application started
2022-06-15 12:53:14,054 | apscheduler.scheduler | INFO | start:171 | Scheduler started
2022-06-15 12:53:14,055 | telegram.ext._application | INFO | start:492 | Application started
2022-06-15 12:53:52,545 | apscheduler.scheduler | INFO | start:171 | Scheduler started
2022-06-15 12:53:52,546 | telegram.ext._application | INFO | start:492 | Application started
2022-06-15 12:54:49,790 | apscheduler.scheduler | INFO | start:171 | Scheduler started
2022-06-15 12:54:49,791 | telegram.ext._application | INFO | start:492 | Application started
2022-06-15 12:55:15,861 | apscheduler.scheduler | INFO | start:171 | Scheduler started
2022-06-15 12:55:15,861 | telegram.ext._application | INFO | start:492 | Application started
2022-06-15 12:55:33,396 | apscheduler.scheduler | INFO | start:171 | Scheduler started
2022-06-15 12:55:33,399 | telegram.ext._application | INFO | start:492 | Application started
2022-06-15 12:55:39,076 | telegram.ext._application | ERROR | process_error:1484 | No error handlers are registered, logging exception.
Traceback (most recent call last):
  File "/home/bori/.local/lib/python3.7/site-packages/telegram/ext/_application.py", line 970, in process_update
    await coroutine
  File "/home/bori/.local/lib/python3.7/site-packages/telegram/ext/_handler.py", line 137, in handle_update
    return await self.callback(update, context)
  File "/home/bori/dev/py/beud/misc/access_control.py", line 15, in wrapped
    return await func(update, context, *args, **kwargs)
  File "/home/bori/dev/py/beud/beubot/flows/prompt_handlers/nominal_phlr.py", line 107, in food_inline_hlr
    chat_id=int(for_rest)) + '</b></i>'
  File "/home/bori/.local/lib/python3.7/site-packages/telegram/_bot.py", line 236, in decorator
    result = await func(*args, **kwargs)
  File "/home/bori/.local/lib/python3.7/site-packages/telegram/_bot.py", line 653, in send_message
    api_kwargs=api_kwargs,
  File "/home/bori/.local/lib/python3.7/site-packages/telegram/ext/_extbot.py", line 266, in _send_message
    api_kwargs=api_kwargs,
  File "/home/bori/.local/lib/python3.7/site-packages/telegram/_bot.py", line 353, in _send_message
    api_kwargs=api_kwargs,
  File "/home/bori/.local/lib/python3.7/site-packages/telegram/_bot.py", line 315, in _post
    pool_timeout=pool_timeout,
  File "/home/bori/.local/lib/python3.7/site-packages/telegram/request/_baserequest.py", line 169, in post
    pool_timeout=pool_timeout,
  File "/home/bori/.local/lib/python3.7/site-packages/telegram/request/_baserequest.py", line 325, in _request_wrapper
    raise BadRequest(message)
telegram.error.BadRequest: Can't parse entities: can't find end tag corresponding to start tag b
2022-06-15 12:55:56,510 | telegram.ext._application | ERROR | process_error:1484 | No error handlers are registered, logging exception.
Traceback (most recent call last):
  File "/home/bori/.local/lib/python3.7/site-packages/telegram/ext/_application.py", line 970, in process_update
    await coroutine
  File "/home/bori/.local/lib/python3.7/site-packages/telegram/ext/_handler.py", line 137, in handle_update
    return await self.callback(update, context)
  File "/home/bori/dev/py/beud/misc/access_control.py", line 15, in wrapped
    return await func(update, context, *args, **kwargs)
  File "/home/bori/dev/py/beud/beubot/flows/prompt_handlers/nominal_phlr.py", line 107, in food_inline_hlr
    chat_id=int(for_rest)) + '</b></i>'
  File "/home/bori/.local/lib/python3.7/site-packages/telegram/_bot.py", line 236, in decorator
    result = await func(*args, **kwargs)
  File "/home/bori/.local/lib/python3.7/site-packages/telegram/_bot.py", line 653, in send_message
    api_kwargs=api_kwargs,
  File "/home/bori/.local/lib/python3.7/site-packages/telegram/ext/_extbot.py", line 266, in _send_message
    api_kwargs=api_kwargs,
  File "/home/bori/.local/lib/python3.7/site-packages/telegram/_bot.py", line 353, in _send_message
    api_kwargs=api_kwargs,
  File "/home/bori/.local/lib/python3.7/site-packages/telegram/_bot.py", line 315, in _post
    pool_timeout=pool_timeout,
  File "/home/bori/.local/lib/python3.7/site-packages/telegram/request/_baserequest.py", line 169, in post
    pool_timeout=pool_timeout,
  File "/home/bori/.local/lib/python3.7/site-packages/telegram/request/_baserequest.py", line 325, in _request_wrapper
    raise BadRequest(message)
telegram.error.BadRequest: Can't parse entities: can't find end tag corresponding to start tag b
2022-06-15 12:56:29,889 | apscheduler.scheduler | INFO | start:171 | Scheduler started
2022-06-15 12:56:29,889 | telegram.ext._application | INFO | start:492 | Application started
2022-06-15 12:56:41,278 | apscheduler.scheduler | INFO | start:171 | Scheduler started
2022-06-15 12:56:41,280 | telegram.ext._application | INFO | start:492 | Application started
2022-06-15 12:57:06,332 | apscheduler.scheduler | INFO | start:171 | Scheduler started
2022-06-15 12:57:06,332 | telegram.ext._application | INFO | start:492 | Application started
2022-06-15 12:58:04,639 | apscheduler.scheduler | INFO | start:171 | Scheduler started
2022-06-15 12:58:04,641 | telegram.ext._application | INFO | start:492 | Application started
2022-06-15 13:00:55,703 | apscheduler.scheduler | INFO | start:171 | Scheduler started
2022-06-15 13:00:55,703 | telegram.ext._application | INFO | start:492 | Application started
2022-06-15 13:03:32,820 | apscheduler.scheduler | INFO | start:171 | Scheduler started
2022-06-15 13:03:32,821 | telegram.ext._application | INFO | start:492 | Application started
2022-06-15 13:06:11,755 | apscheduler.scheduler | INFO | start:171 | Scheduler started
2022-06-15 13:06:11,763 | telegram.ext._application | INFO | start:492 | Application started
2022-06-15 13:06:26,787 | telegram.ext._updater | ERROR | _network_loop_retry:569 | Error while getting Updates: httpx HTTPError: [Errno -2] Name or service not known
2022-06-15 13:06:26,788 | telegram.ext._application | ERROR | process_error:1484 | No error handlers are registered, logging exception.
Traceback (most recent call last):
  File "/home/bori/.local/lib/python3.7/site-packages/httpcore/_exceptions.py", line 8, in map_exceptions
    yield
  File "/home/bori/.local/lib/python3.7/site-packages/httpcore/backends/asyncio.py", line 112, in connect_tcp
    local_host=local_address,
  File "/home/bori/.local/lib/python3.7/site-packages/anyio/_core/_sockets.py", line 190, in connect_tcp
    target_host, remote_port, family=family, type=socket.SOCK_STREAM
  File "/home/bori/.local/lib/python3.7/site-packages/anyio/_core/_sockets.py", line 497, in getaddrinfo
    encoded_host, port, family=family, type=type, proto=proto, flags=flags
  File "/home/bori/.local/lib/python3.7/site-packages/anyio/_backends/_asyncio.py", line 1755, in getaddrinfo
    host, port, family=family, type=type, proto=proto, flags=flags
  File "/usr/lib/python3.7/asyncio/base_events.py", line 792, in getaddrinfo
    None, getaddr_func, host, port, family, type, proto, flags)
  File "/usr/lib/python3.7/concurrent/futures/thread.py", line 57, in run
    result = self.fn(*self.args, **self.kwargs)
  File "/usr/lib/python3.7/socket.py", line 752, in getaddrinfo
    for res in _socket.getaddrinfo(host, port, family, type, proto, flags):
socket.gaierror: [Errno -2] Name or service not known

During handling of the above exception, another exception occurred:

Traceback (most recent call last):
  File "/home/bori/.local/lib/python3.7/site-packages/httpx/_transports/default.py", line 60, in map_httpcore_exceptions
    yield
  File "/home/bori/.local/lib/python3.7/site-packages/httpx/_transports/default.py", line 353, in handle_async_request
    resp = await self._pool.handle_async_request(req)
  File "/home/bori/.local/lib/python3.7/site-packages/httpcore/_async/connection_pool.py", line 253, in handle_async_request
    raise exc
  File "/home/bori/.local/lib/python3.7/site-packages/httpcore/_async/connection_pool.py", line 237, in handle_async_request
    response = await connection.handle_async_request(request)
  File "/home/bori/.local/lib/python3.7/site-packages/httpcore/_async/connection.py", line 86, in handle_async_request
    raise exc
  File "/home/bori/.local/lib/python3.7/site-packages/httpcore/_async/connection.py", line 63, in handle_async_request
    stream = await self._connect(request)
  File "/home/bori/.local/lib/python3.7/site-packages/httpcore/_async/connection.py", line 111, in _connect
    stream = await self._network_backend.connect_tcp(**kwargs)
  File "/home/bori/.local/lib/python3.7/site-packages/httpcore/backends/auto.py", line 30, in connect_tcp
    host, port, timeout=timeout, local_address=local_address
  File "/home/bori/.local/lib/python3.7/site-packages/httpcore/backends/asyncio.py", line 112, in connect_tcp
    local_host=local_address,
  File "/usr/lib/python3.7/contextlib.py", line 130, in __exit__
    self.gen.throw(type, value, traceback)
  File "/home/bori/.local/lib/python3.7/site-packages/httpcore/_exceptions.py", line 12, in map_exceptions
    raise to_exc(exc)
httpcore.ConnectError: [Errno -2] Name or service not known

The above exception was the direct cause of the following exception:

Traceback (most recent call last):
  File "/home/bori/.local/lib/python3.7/site-packages/telegram/request/_httpxrequest.py", line 180, in do_request
    data=data,
  File "/home/bori/.local/lib/python3.7/site-packages/httpx/_client.py", line 1527, in request
    return await self.send(request, auth=auth, follow_redirects=follow_redirects)
  File "/home/bori/.local/lib/python3.7/site-packages/httpx/_client.py", line 1618, in send
    history=[],
  File "/home/bori/.local/lib/python3.7/site-packages/httpx/_client.py", line 1645, in _send_handling_auth
    history=history,
  File "/home/bori/.local/lib/python3.7/site-packages/httpx/_client.py", line 1679, in _send_handling_redirects
    response = await self._send_single_request(request)
  File "/home/bori/.local/lib/python3.7/site-packages/httpx/_client.py", line 1716, in _send_single_request
    response = await transport.handle_async_request(request)
  File "/home/bori/.local/lib/python3.7/site-packages/httpx/_transports/default.py", line 353, in handle_async_request
    resp = await self._pool.handle_async_request(req)
  File "/usr/lib/python3.7/contextlib.py", line 130, in __exit__
    self.gen.throw(type, value, traceback)
  File "/home/bori/.local/lib/python3.7/site-packages/httpx/_transports/default.py", line 77, in map_httpcore_exceptions
    raise mapped_exc(message) from exc
httpx.ConnectError: [Errno -2] Name or service not known

The above exception was the direct cause of the following exception:

Traceback (most recent call last):
  File "/home/bori/.local/lib/python3.7/site-packages/telegram/ext/_updater.py", line 556, in _network_loop_retry
    if not await action_cb():
  File "/home/bori/.local/lib/python3.7/site-packages/telegram/ext/_updater.py", line 318, in polling_action_cb
    raise exc
  File "/home/bori/.local/lib/python3.7/site-packages/telegram/ext/_updater.py", line 310, in polling_action_cb
    allowed_updates=allowed_updates,
  File "/home/bori/.local/lib/python3.7/site-packages/telegram/ext/_extbot.py", line 294, in get_updates
    api_kwargs=api_kwargs,
  File "/home/bori/.local/lib/python3.7/site-packages/telegram/_bot.py", line 236, in decorator
    result = await func(*args, **kwargs)
  File "/home/bori/.local/lib/python3.7/site-packages/telegram/_bot.py", line 3778, in get_updates
    api_kwargs=api_kwargs,
  File "/home/bori/.local/lib/python3.7/site-packages/telegram/_bot.py", line 315, in _post
    pool_timeout=pool_timeout,
  File "/home/bori/.local/lib/python3.7/site-packages/telegram/request/_baserequest.py", line 169, in post
    pool_timeout=pool_timeout,
  File "/home/bori/.local/lib/python3.7/site-packages/telegram/request/_baserequest.py", line 285, in _request_wrapper
    raise exc
  File "/home/bori/.local/lib/python3.7/site-packages/telegram/request/_baserequest.py", line 278, in _request_wrapper
    pool_timeout=pool_timeout,
  File "/home/bori/.local/lib/python3.7/site-packages/telegram/request/_httpxrequest.py", line 195, in do_request
    raise NetworkError(f"httpx HTTPError: {err}") from err
telegram.error.NetworkError: httpx HTTPError: [Errno -2] Name or service not known
2022-06-15 13:06:27,794 | telegram.ext._updater | ERROR | _network_loop_retry:569 | Error while getting Updates: httpx HTTPError: [Errno -2] Name or service not known
2022-06-15 13:06:27,795 | telegram.ext._application | ERROR | process_error:1484 | No error handlers are registered, logging exception.
Traceback (most recent call last):
  File "/home/bori/.local/lib/python3.7/site-packages/httpcore/_exceptions.py", line 8, in map_exceptions
    yield
  File "/home/bori/.local/lib/python3.7/site-packages/httpcore/backends/asyncio.py", line 112, in connect_tcp
    local_host=local_address,
  File "/home/bori/.local/lib/python3.7/site-packages/anyio/_core/_sockets.py", line 190, in connect_tcp
    target_host, remote_port, family=family, type=socket.SOCK_STREAM
  File "/home/bori/.local/lib/python3.7/site-packages/anyio/_core/_sockets.py", line 497, in getaddrinfo
    encoded_host, port, family=family, type=type, proto=proto, flags=flags
  File "/home/bori/.local/lib/python3.7/site-packages/anyio/_backends/_asyncio.py", line 1755, in getaddrinfo
    host, port, family=family, type=type, proto=proto, flags=flags
  File "/usr/lib/python3.7/asyncio/base_events.py", line 792, in getaddrinfo
    None, getaddr_func, host, port, family, type, proto, flags)
  File "/usr/lib/python3.7/concurrent/futures/thread.py", line 57, in run
    result = self.fn(*self.args, **self.kwargs)
  File "/usr/lib/python3.7/socket.py", line 752, in getaddrinfo
    for res in _socket.getaddrinfo(host, port, family, type, proto, flags):
socket.gaierror: [Errno -2] Name or service not known

During handling of the above exception, another exception occurred:

Traceback (most recent call last):
  File "/home/bori/.local/lib/python3.7/site-packages/httpx/_transports/default.py", line 60, in map_httpcore_exceptions
    yield
  File "/home/bori/.local/lib/python3.7/site-packages/httpx/_transports/default.py", line 353, in handle_async_request
    resp = await self._pool.handle_async_request(req)
  File "/home/bori/.local/lib/python3.7/site-packages/httpcore/_async/connection_pool.py", line 253, in handle_async_request
    raise exc
  File "/home/bori/.local/lib/python3.7/site-packages/httpcore/_async/connection_pool.py", line 237, in handle_async_request
    response = await connection.handle_async_request(request)
  File "/home/bori/.local/lib/python3.7/site-packages/httpcore/_async/connection.py", line 86, in handle_async_request
    raise exc
  File "/home/bori/.local/lib/python3.7/site-packages/httpcore/_async/connection.py", line 63, in handle_async_request
    stream = await self._connect(request)
  File "/home/bori/.local/lib/python3.7/site-packages/httpcore/_async/connection.py", line 111, in _connect
    stream = await self._network_backend.connect_tcp(**kwargs)
  File "/home/bori/.local/lib/python3.7/site-packages/httpcore/backends/auto.py", line 30, in connect_tcp
    host, port, timeout=timeout, local_address=local_address
  File "/home/bori/.local/lib/python3.7/site-packages/httpcore/backends/asyncio.py", line 112, in connect_tcp
    local_host=local_address,
  File "/usr/lib/python3.7/contextlib.py", line 130, in __exit__
    self.gen.throw(type, value, traceback)
  File "/home/bori/.local/lib/python3.7/site-packages/httpcore/_exceptions.py", line 12, in map_exceptions
    raise to_exc(exc)
httpcore.ConnectError: [Errno -2] Name or service not known

The above exception was the direct cause of the following exception:

Traceback (most recent call last):
  File "/home/bori/.local/lib/python3.7/site-packages/telegram/request/_httpxrequest.py", line 180, in do_request
    data=data,
  File "/home/bori/.local/lib/python3.7/site-packages/httpx/_client.py", line 1527, in request
    return await self.send(request, auth=auth, follow_redirects=follow_redirects)
  File "/home/bori/.local/lib/python3.7/site-packages/httpx/_client.py", line 1618, in send
    history=[],
  File "/home/bori/.local/lib/python3.7/site-packages/httpx/_client.py", line 1645, in _send_handling_auth
    history=history,
  File "/home/bori/.local/lib/python3.7/site-packages/httpx/_client.py", line 1679, in _send_handling_redirects
    response = await self._send_single_request(request)
  File "/home/bori/.local/lib/python3.7/site-packages/httpx/_client.py", line 1716, in _send_single_request
    response = await transport.handle_async_request(request)
  File "/home/bori/.local/lib/python3.7/site-packages/httpx/_transports/default.py", line 353, in handle_async_request
    resp = await self._pool.handle_async_request(req)
  File "/usr/lib/python3.7/contextlib.py", line 130, in __exit__
    self.gen.throw(type, value, traceback)
  File "/home/bori/.local/lib/python3.7/site-packages/httpx/_transports/default.py", line 77, in map_httpcore_exceptions
    raise mapped_exc(message) from exc
httpx.ConnectError: [Errno -2] Name or service not known

The above exception was the direct cause of the following exception:

Traceback (most recent call last):
  File "/home/bori/.local/lib/python3.7/site-packages/telegram/ext/_updater.py", line 556, in _network_loop_retry
    if not await action_cb():
  File "/home/bori/.local/lib/python3.7/site-packages/telegram/ext/_updater.py", line 318, in polling_action_cb
    raise exc
  File "/home/bori/.local/lib/python3.7/site-packages/telegram/ext/_updater.py", line 310, in polling_action_cb
    allowed_updates=allowed_updates,
  File "/home/bori/.local/lib/python3.7/site-packages/telegram/ext/_extbot.py", line 294, in get_updates
    api_kwargs=api_kwargs,
  File "/home/bori/.local/lib/python3.7/site-packages/telegram/_bot.py", line 236, in decorator
    result = await func(*args, **kwargs)
  File "/home/bori/.local/lib/python3.7/site-packages/telegram/_bot.py", line 3778, in get_updates
    api_kwargs=api_kwargs,
  File "/home/bori/.local/lib/python3.7/site-packages/telegram/_bot.py", line 315, in _post
    pool_timeout=pool_timeout,
  File "/home/bori/.local/lib/python3.7/site-packages/telegram/request/_baserequest.py", line 169, in post
    pool_timeout=pool_timeout,
  File "/home/bori/.local/lib/python3.7/site-packages/telegram/request/_baserequest.py", line 285, in _request_wrapper
    raise exc
  File "/home/bori/.local/lib/python3.7/site-packages/telegram/request/_baserequest.py", line 278, in _request_wrapper
    pool_timeout=pool_timeout,
  File "/home/bori/.local/lib/python3.7/site-packages/telegram/request/_httpxrequest.py", line 195, in do_request
    raise NetworkError(f"httpx HTTPError: {err}") from err
telegram.error.NetworkError: httpx HTTPError: [Errno -2] Name or service not known
2022-06-15 13:06:29,300 | telegram.ext._updater | ERROR | _network_loop_retry:569 | Error while getting Updates: httpx HTTPError: [Errno -2] Name or service not known
2022-06-15 13:06:29,301 | telegram.ext._application | ERROR | process_error:1484 | No error handlers are registered, logging exception.
Traceback (most recent call last):
  File "/home/bori/.local/lib/python3.7/site-packages/httpcore/_exceptions.py", line 8, in map_exceptions
    yield
  File "/home/bori/.local/lib/python3.7/site-packages/httpcore/backends/asyncio.py", line 112, in connect_tcp
    local_host=local_address,
  File "/home/bori/.local/lib/python3.7/site-packages/anyio/_core/_sockets.py", line 190, in connect_tcp
    target_host, remote_port, family=family, type=socket.SOCK_STREAM
  File "/home/bori/.local/lib/python3.7/site-packages/anyio/_core/_sockets.py", line 497, in getaddrinfo
    encoded_host, port, family=family, type=type, proto=proto, flags=flags
  File "/home/bori/.local/lib/python3.7/site-packages/anyio/_backends/_asyncio.py", line 1755, in getaddrinfo
    host, port, family=family, type=type, proto=proto, flags=flags
  File "/usr/lib/python3.7/asyncio/base_events.py", line 792, in getaddrinfo
    None, getaddr_func, host, port, family, type, proto, flags)
  File "/usr/lib/python3.7/concurrent/futures/thread.py", line 57, in run
    result = self.fn(*self.args, **self.kwargs)
  File "/usr/lib/python3.7/socket.py", line 752, in getaddrinfo
    for res in _socket.getaddrinfo(host, port, family, type, proto, flags):
socket.gaierror: [Errno -2] Name or service not known

During handling of the above exception, another exception occurred:

Traceback (most recent call last):
  File "/home/bori/.local/lib/python3.7/site-packages/httpx/_transports/default.py", line 60, in map_httpcore_exceptions
    yield
  File "/home/bori/.local/lib/python3.7/site-packages/httpx/_transports/default.py", line 353, in handle_async_request
    resp = await self._pool.handle_async_request(req)
  File "/home/bori/.local/lib/python3.7/site-packages/httpcore/_async/connection_pool.py", line 253, in handle_async_request
    raise exc
  File "/home/bori/.local/lib/python3.7/site-packages/httpcore/_async/connection_pool.py", line 237, in handle_async_request
    response = await connection.handle_async_request(request)
  File "/home/bori/.local/lib/python3.7/site-packages/httpcore/_async/connection.py", line 86, in handle_async_request
    raise exc
  File "/home/bori/.local/lib/python3.7/site-packages/httpcore/_async/connection.py", line 63, in handle_async_request
    stream = await self._connect(request)
  File "/home/bori/.local/lib/python3.7/site-packages/httpcore/_async/connection.py", line 111, in _connect
    stream = await self._network_backend.connect_tcp(**kwargs)
  File "/home/bori/.local/lib/python3.7/site-packages/httpcore/backends/auto.py", line 30, in connect_tcp
    host, port, timeout=timeout, local_address=local_address
  File "/home/bori/.local/lib/python3.7/site-packages/httpcore/backends/asyncio.py", line 112, in connect_tcp
    local_host=local_address,
  File "/usr/lib/python3.7/contextlib.py", line 130, in __exit__
    self.gen.throw(type, value, traceback)
  File "/home/bori/.local/lib/python3.7/site-packages/httpcore/_exceptions.py", line 12, in map_exceptions
    raise to_exc(exc)
httpcore.ConnectError: [Errno -2] Name or service not known

The above exception was the direct cause of the following exception:

Traceback (most recent call last):
  File "/home/bori/.local/lib/python3.7/site-packages/telegram/request/_httpxrequest.py", line 180, in do_request
    data=data,
  File "/home/bori/.local/lib/python3.7/site-packages/httpx/_client.py", line 1527, in request
    return await self.send(request, auth=auth, follow_redirects=follow_redirects)
  File "/home/bori/.local/lib/python3.7/site-packages/httpx/_client.py", line 1618, in send
    history=[],
  File "/home/bori/.local/lib/python3.7/site-packages/httpx/_client.py", line 1645, in _send_handling_auth
    history=history,
  File "/home/bori/.local/lib/python3.7/site-packages/httpx/_client.py", line 1679, in _send_handling_redirects
    response = await self._send_single_request(request)
  File "/home/bori/.local/lib/python3.7/site-packages/httpx/_client.py", line 1716, in _send_single_request
    response = await transport.handle_async_request(request)
  File "/home/bori/.local/lib/python3.7/site-packages/httpx/_transports/default.py", line 353, in handle_async_request
    resp = await self._pool.handle_async_request(req)
  File "/usr/lib/python3.7/contextlib.py", line 130, in __exit__
    self.gen.throw(type, value, traceback)
  File "/home/bori/.local/lib/python3.7/site-packages/httpx/_transports/default.py", line 77, in map_httpcore_exceptions
    raise mapped_exc(message) from exc
httpx.ConnectError: [Errno -2] Name or service not known

The above exception was the direct cause of the following exception:

Traceback (most recent call last):
  File "/home/bori/.local/lib/python3.7/site-packages/telegram/ext/_updater.py", line 556, in _network_loop_retry
    if not await action_cb():
  File "/home/bori/.local/lib/python3.7/site-packages/telegram/ext/_updater.py", line 318, in polling_action_cb
    raise exc
  File "/home/bori/.local/lib/python3.7/site-packages/telegram/ext/_updater.py", line 310, in polling_action_cb
    allowed_updates=allowed_updates,
  File "/home/bori/.local/lib/python3.7/site-packages/telegram/ext/_extbot.py", line 294, in get_updates
    api_kwargs=api_kwargs,
  File "/home/bori/.local/lib/python3.7/site-packages/telegram/_bot.py", line 236, in decorator
    result = await func(*args, **kwargs)
  File "/home/bori/.local/lib/python3.7/site-packages/telegram/_bot.py", line 3778, in get_updates
    api_kwargs=api_kwargs,
  File "/home/bori/.local/lib/python3.7/site-packages/telegram/_bot.py", line 315, in _post
    pool_timeout=pool_timeout,
  File "/home/bori/.local/lib/python3.7/site-packages/telegram/request/_baserequest.py", line 169, in post
    pool_timeout=pool_timeout,
  File "/home/bori/.local/lib/python3.7/site-packages/telegram/request/_baserequest.py", line 285, in _request_wrapper
    raise exc
  File "/home/bori/.local/lib/python3.7/site-packages/telegram/request/_baserequest.py", line 278, in _request_wrapper
    pool_timeout=pool_timeout,
  File "/home/bori/.local/lib/python3.7/site-packages/telegram/request/_httpxrequest.py", line 195, in do_request
    raise NetworkError(f"httpx HTTPError: {err}") from err
telegram.error.NetworkError: httpx HTTPError: [Errno -2] Name or service not known
2022-06-15 13:06:30,294 | telegram.ext._application | INFO | stop:523 | Application is stopping. This might take a moment.
2022-06-15 13:06:30,295 | apscheduler.scheduler | INFO | shutdown:202 | Scheduler has been shut down
2022-06-15 13:06:30,306 | telegram.ext._application | INFO | stop:548 | Application.stop() complete
2022-06-15 13:24:23,030 | apscheduler.scheduler | INFO | start:171 | Scheduler started
2022-06-15 13:24:23,031 | telegram.ext._application | INFO | start:492 | Application started
