2022-06-13 19:39:40,265 | apscheduler.scheduler | INFO | start:171 | Scheduler started
2022-06-13 19:39:40,265 | telegram.ext._application | INFO | start:492 | Application started
2022-06-13 19:40:14,937 | telegram.ext._application | INFO | stop:523 | Application is stopping. This might take a moment.
2022-06-13 19:40:14,938 | apscheduler.scheduler | INFO | shutdown:202 | Scheduler has been shut down
2022-06-13 19:40:14,948 | telegram.ext._application | INFO | stop:548 | Application.stop() complete
2022-06-13 19:40:18,012 | apscheduler.scheduler | INFO | start:171 | Scheduler started
2022-06-13 19:40:18,012 | telegram.ext._application | INFO | start:492 | Application started
2022-06-13 19:40:59,004 | telegram.ext._application | INFO | stop:523 | Application is stopping. This might take a moment.
2022-06-13 19:40:59,005 | apscheduler.scheduler | INFO | shutdown:202 | Scheduler has been shut down
2022-06-13 19:40:59,016 | telegram.ext._application | INFO | stop:548 | Application.stop() complete
2022-06-13 19:42:13,558 | apscheduler.scheduler | INFO | start:171 | Scheduler started
2022-06-13 19:42:13,559 | telegram.ext._application | INFO | start:492 | Application started
2022-06-13 19:43:28,803 | telegram.ext._application | INFO | stop:523 | Application is stopping. This might take a moment.
2022-06-13 19:43:28,803 | apscheduler.scheduler | INFO | shutdown:202 | Scheduler has been shut down
2022-06-13 19:43:28,814 | telegram.ext._application | INFO | stop:548 | Application.stop() complete
2022-06-13 19:43:32,410 | apscheduler.scheduler | INFO | start:171 | Scheduler started
2022-06-13 19:43:32,410 | telegram.ext._application | INFO | start:492 | Application started
2022-06-13 19:43:33,522 | telegram.ext._application | ERROR | process_error:1484 | No error handlers are registered, logging exception.
Traceback (most recent call last):
  File "/home/bori/.local/lib/python3.7/site-packages/telegram/ext/_application.py", line 970, in process_update
    await coroutine
  File "/home/bori/.local/lib/python3.7/site-packages/telegram/ext/_handler.py", line 137, in handle_update
    return await self.callback(update, context)
  File "/home/bori/dev/py/beud/beubot/start.py", line 8, in start
    context.user_data = {"name" : 'Thick dumbass'}
  File "/home/bori/.local/lib/python3.7/site-packages/telegram/ext/_callbackcontext.py", line 187, in user_data
    f"You can not assign a new value to user_data, see {_STORING_DATA_WIKI}"
AttributeError: You can not assign a new value to user_data, see https://github.com/python-telegram-bot/python-telegram-bot/wiki/Storing-bot%2C-user-and-chat-related-data
2022-06-13 19:44:40,815 | telegram.ext._application | INFO | stop:523 | Application is stopping. This might take a moment.
2022-06-13 19:44:40,815 | apscheduler.scheduler | INFO | shutdown:202 | Scheduler has been shut down
2022-06-13 19:44:40,825 | telegram.ext._application | INFO | stop:548 | Application.stop() complete
2022-06-13 19:45:33,520 | apscheduler.scheduler | INFO | start:171 | Scheduler started
2022-06-13 19:45:33,520 | telegram.ext._application | INFO | start:492 | Application started
2022-06-13 19:45:41,331 | telegram.ext._application | INFO | stop:523 | Application is stopping. This might take a moment.
2022-06-13 19:45:41,331 | apscheduler.scheduler | INFO | shutdown:202 | Scheduler has been shut down
2022-06-13 19:45:41,342 | telegram.ext._application | INFO | stop:548 | Application.stop() complete
2022-06-13 19:45:48,787 | apscheduler.scheduler | INFO | start:171 | Scheduler started
2022-06-13 19:45:48,787 | telegram.ext._application | INFO | start:492 | Application started
2022-06-13 19:46:10,754 | telegram.ext._application | INFO | stop:523 | Application is stopping. This might take a moment.
2022-06-13 19:46:10,754 | apscheduler.scheduler | INFO | shutdown:202 | Scheduler has been shut down
2022-06-13 19:46:10,765 | telegram.ext._application | INFO | stop:548 | Application.stop() complete
2022-06-13 19:46:19,022 | apscheduler.scheduler | INFO | start:171 | Scheduler started
2022-06-13 19:46:19,022 | telegram.ext._application | INFO | start:492 | Application started
2022-06-13 19:46:28,922 | telegram.ext._application | INFO | stop:523 | Application is stopping. This might take a moment.
2022-06-13 19:46:28,923 | apscheduler.scheduler | INFO | shutdown:202 | Scheduler has been shut down
2022-06-13 19:46:28,933 | telegram.ext._application | INFO | stop:548 | Application.stop() complete
2022-06-13 19:46:36,377 | apscheduler.scheduler | INFO | start:171 | Scheduler started
2022-06-13 19:46:36,378 | telegram.ext._application | INFO | start:492 | Application started
2022-06-13 19:46:40,672 | telegram.ext._application | INFO | stop:523 | Application is stopping. This might take a moment.
2022-06-13 19:46:40,672 | apscheduler.scheduler | INFO | shutdown:202 | Scheduler has been shut down
2022-06-13 19:46:40,683 | telegram.ext._application | INFO | stop:548 | Application.stop() complete
2022-06-13 19:46:47,512 | apscheduler.scheduler | INFO | start:171 | Scheduler started
2022-06-13 19:46:47,512 | telegram.ext._application | INFO | start:492 | Application started
2022-06-13 19:56:13,879 | telegram.ext._updater | ERROR | _network_loop_retry:569 | Error while getting Updates: httpx HTTPError: All connection attempts failed
2022-06-13 19:56:13,879 | telegram.ext._application | ERROR | process_error:1484 | No error handlers are registered, logging exception.
anyio._backends._asyncio.ExceptionGroup: 4 exceptions were raised in the task group:
----------------------------
Traceback (most recent call last):
  File "/home/bori/.local/lib/python3.7/site-packages/anyio/_core/_sockets.py", line 164, in try_connect
    stream = await asynclib.connect_tcp(remote_host, remote_port, local_address)
  File "/home/bori/.local/lib/python3.7/site-packages/anyio/_backends/_asyncio.py", line 1692, in connect_tcp
    StreamProtocol, host, port, local_addr=local_addr
  File "/usr/lib/python3.7/asyncio/base_events.py", line 962, in create_connection
    raise exceptions[0]
  File "/usr/lib/python3.7/asyncio/base_events.py", line 949, in create_connection
    await self.sock_connect(sock, address)
  File "/usr/lib/python3.7/asyncio/selector_events.py", line 473, in sock_connect
    return await fut
  File "/usr/lib/python3.7/asyncio/selector_events.py", line 478, in _sock_connect
    sock.connect(address)
OSError: [Errno 101] Network is unreachable
----------------------------
Traceback (most recent call last):
  File "/home/bori/.local/lib/python3.7/site-packages/anyio/_core/_sockets.py", line 164, in try_connect
    stream = await asynclib.connect_tcp(remote_host, remote_port, local_address)
  File "/home/bori/.local/lib/python3.7/site-packages/anyio/_backends/_asyncio.py", line 1692, in connect_tcp
    StreamProtocol, host, port, local_addr=local_addr
  File "/usr/lib/python3.7/asyncio/base_events.py", line 962, in create_connection
    raise exceptions[0]
  File "/usr/lib/python3.7/asyncio/base_events.py", line 949, in create_connection
    await self.sock_connect(sock, address)
  File "/usr/lib/python3.7/asyncio/selector_events.py", line 473, in sock_connect
    return await fut
  File "/usr/lib/python3.7/asyncio/selector_events.py", line 478, in _sock_connect
    sock.connect(address)
OSError: [Errno 101] Network is unreachable
----------------------------
Traceback (most recent call last):
  File "/home/bori/.local/lib/python3.7/site-packages/anyio/_core/_sockets.py", line 164, in try_connect
    stream = await asynclib.connect_tcp(remote_host, remote_port, local_address)
  File "/home/bori/.local/lib/python3.7/site-packages/anyio/_backends/_asyncio.py", line 1692, in connect_tcp
    StreamProtocol, host, port, local_addr=local_addr
  File "/usr/lib/python3.7/asyncio/base_events.py", line 962, in create_connection
    raise exceptions[0]
  File "/usr/lib/python3.7/asyncio/base_events.py", line 949, in create_connection
    await self.sock_connect(sock, address)
  File "/usr/lib/python3.7/asyncio/selector_events.py", line 473, in sock_connect
    return await fut
  File "/usr/lib/python3.7/asyncio/selector_events.py", line 478, in _sock_connect
    sock.connect(address)
OSError: [Errno 101] Network is unreachable
----------------------------
Traceback (most recent call last):
  File "/home/bori/.local/lib/python3.7/site-packages/anyio/_core/_sockets.py", line 164, in try_connect
    stream = await asynclib.connect_tcp(remote_host, remote_port, local_address)
  File "/home/bori/.local/lib/python3.7/site-packages/anyio/_backends/_asyncio.py", line 1692, in connect_tcp
    StreamProtocol, host, port, local_addr=local_addr
  File "/usr/lib/python3.7/asyncio/base_events.py", line 962, in create_connection
    raise exceptions[0]
  File "/usr/lib/python3.7/asyncio/base_events.py", line 949, in create_connection
    await self.sock_connect(sock, address)
  File "/usr/lib/python3.7/asyncio/selector_events.py", line 473, in sock_connect
    return await fut
  File "/usr/lib/python3.7/asyncio/selector_events.py", line 478, in _sock_connect
    sock.connect(address)
OSError: [Errno 101] Network is unreachable


The above exception was the direct cause of the following exception:

Traceback (most recent call last):
  File "/home/bori/.local/lib/python3.7/site-packages/httpcore/_exceptions.py", line 8, in map_exceptions
    yield
  File "/home/bori/.local/lib/python3.7/site-packages/httpcore/backends/asyncio.py", line 112, in connect_tcp
    local_host=local_address,
  File "/home/bori/.local/lib/python3.7/site-packages/anyio/_core/_sockets.py", line 222, in connect_tcp
    raise OSError("All connection attempts failed") from cause
OSError: All connection attempts failed

During handling of the above exception, another exception occurred:

Traceback (most recent call last):
  File "/home/bori/.local/lib/python3.7/site-packages/httpx/_transports/default.py", line 60, in map_httpcore_exceptions
    yield
  File "/home/bori/.local/lib/python3.7/site-packages/httpx/_transports/default.py", line 353, in handle_async_request
    resp = await self._pool.handle_async_request(req)
  File "/home/bori/.local/lib/python3.7/site-packages/httpcore/_async/connection_pool.py", line 253, in handle_async_request
    raise exc
  File "/home/bori/.local/lib/python3.7/site-packages/httpcore/_async/connection_pool.py", line 237, in handle_async_request
    response = await connection.handle_async_request(request)
  File "/home/bori/.local/lib/python3.7/site-packages/httpcore/_async/connection.py", line 86, in handle_async_request
    raise exc
  File "/home/bori/.local/lib/python3.7/site-packages/httpcore/_async/connection.py", line 63, in handle_async_request
    stream = await self._connect(request)
  File "/home/bori/.local/lib/python3.7/site-packages/httpcore/_async/connection.py", line 111, in _connect
    stream = await self._network_backend.connect_tcp(**kwargs)
  File "/home/bori/.local/lib/python3.7/site-packages/httpcore/backends/auto.py", line 30, in connect_tcp
    host, port, timeout=timeout, local_address=local_address
  File "/home/bori/.local/lib/python3.7/site-packages/httpcore/backends/asyncio.py", line 112, in connect_tcp
    local_host=local_address,
  File "/usr/lib/python3.7/contextlib.py", line 130, in __exit__
    self.gen.throw(type, value, traceback)
  File "/home/bori/.local/lib/python3.7/site-packages/httpcore/_exceptions.py", line 12, in map_exceptions
    raise to_exc(exc)
httpcore.ConnectError: All connection attempts failed

The above exception was the direct cause of the following exception:

Traceback (most recent call last):
  File "/home/bori/.local/lib/python3.7/site-packages/telegram/request/_httpxrequest.py", line 180, in do_request
    data=data,
  File "/home/bori/.local/lib/python3.7/site-packages/httpx/_client.py", line 1527, in request
    return await self.send(request, auth=auth, follow_redirects=follow_redirects)
  File "/home/bori/.local/lib/python3.7/site-packages/httpx/_client.py", line 1618, in send
    history=[],
  File "/home/bori/.local/lib/python3.7/site-packages/httpx/_client.py", line 1645, in _send_handling_auth
    history=history,
  File "/home/bori/.local/lib/python3.7/site-packages/httpx/_client.py", line 1679, in _send_handling_redirects
    response = await self._send_single_request(request)
  File "/home/bori/.local/lib/python3.7/site-packages/httpx/_client.py", line 1716, in _send_single_request
    response = await transport.handle_async_request(request)
  File "/home/bori/.local/lib/python3.7/site-packages/httpx/_transports/default.py", line 353, in handle_async_request
    resp = await self._pool.handle_async_request(req)
  File "/usr/lib/python3.7/contextlib.py", line 130, in __exit__
    self.gen.throw(type, value, traceback)
  File "/home/bori/.local/lib/python3.7/site-packages/httpx/_transports/default.py", line 77, in map_httpcore_exceptions
    raise mapped_exc(message) from exc
httpx.ConnectError: All connection attempts failed

The above exception was the direct cause of the following exception:

Traceback (most recent call last):
  File "/home/bori/.local/lib/python3.7/site-packages/telegram/ext/_updater.py", line 556, in _network_loop_retry
    if not await action_cb():
  File "/home/bori/.local/lib/python3.7/site-packages/telegram/ext/_updater.py", line 318, in polling_action_cb
    raise exc
  File "/home/bori/.local/lib/python3.7/site-packages/telegram/ext/_updater.py", line 310, in polling_action_cb
    allowed_updates=allowed_updates,
  File "/home/bori/.local/lib/python3.7/site-packages/telegram/ext/_extbot.py", line 294, in get_updates
    api_kwargs=api_kwargs,
  File "/home/bori/.local/lib/python3.7/site-packages/telegram/_bot.py", line 236, in decorator
    result = await func(*args, **kwargs)
  File "/home/bori/.local/lib/python3.7/site-packages/telegram/_bot.py", line 3778, in get_updates
    api_kwargs=api_kwargs,
  File "/home/bori/.local/lib/python3.7/site-packages/telegram/_bot.py", line 315, in _post
    pool_timeout=pool_timeout,
  File "/home/bori/.local/lib/python3.7/site-packages/telegram/request/_baserequest.py", line 169, in post
    pool_timeout=pool_timeout,
  File "/home/bori/.local/lib/python3.7/site-packages/telegram/request/_baserequest.py", line 285, in _request_wrapper
    raise exc
  File "/home/bori/.local/lib/python3.7/site-packages/telegram/request/_baserequest.py", line 278, in _request_wrapper
    pool_timeout=pool_timeout,
  File "/home/bori/.local/lib/python3.7/site-packages/telegram/request/_httpxrequest.py", line 195, in do_request
    raise NetworkError(f"httpx HTTPError: {err}") from err
telegram.error.NetworkError: httpx HTTPError: All connection attempts failed
2022-06-13 19:56:14,881 | telegram.ext._application | INFO | stop:523 | Application is stopping. This might take a moment.
2022-06-13 19:56:14,881 | apscheduler.scheduler | INFO | shutdown:202 | Scheduler has been shut down
2022-06-13 19:56:14,892 | telegram.ext._application | INFO | stop:548 | Application.stop() complete
2022-06-13 20:00:26,449 | apscheduler.scheduler | INFO | start:171 | Scheduler started
2022-06-13 20:00:26,450 | telegram.ext._application | INFO | start:492 | Application started
2022-06-13 20:00:30,209 | telegram.ext._application | ERROR | process_error:1484 | No error handlers are registered, logging exception.
Traceback (most recent call last):
  File "/home/bori/.local/lib/python3.7/site-packages/telegram/ext/_application.py", line 970, in process_update
    await coroutine
  File "/home/bori/.local/lib/python3.7/site-packages/telegram/ext/_handler.py", line 137, in handle_update
    return await self.callback(update, context)
  File "/home/bori/dev/py/beud/beubot/start.py", line 35, in start
    await context.bot.send_message( "A two-column menu", reply_markup=reply_markup)
  File "/home/bori/.local/lib/python3.7/site-packages/telegram/_bot.py", line 236, in decorator
    result = await func(*args, **kwargs)
TypeError: send_message() missing 1 required positional argument: 'text'
2022-06-13 20:00:39,258 | telegram.ext._application | INFO | stop:523 | Application is stopping. This might take a moment.
2022-06-13 20:00:39,259 | apscheduler.scheduler | INFO | shutdown:202 | Scheduler has been shut down
2022-06-13 20:00:39,269 | telegram.ext._application | INFO | stop:548 | Application.stop() complete
2022-06-13 20:00:42,533 | apscheduler.scheduler | INFO | start:171 | Scheduler started
2022-06-13 20:00:42,533 | telegram.ext._application | INFO | start:492 | Application started
2022-06-13 20:00:43,447 | telegram.ext._application | ERROR | process_error:1484 | No error handlers are registered, logging exception.
Traceback (most recent call last):
  File "/home/bori/.local/lib/python3.7/site-packages/telegram/ext/_application.py", line 970, in process_update
    await coroutine
  File "/home/bori/.local/lib/python3.7/site-packages/telegram/ext/_handler.py", line 137, in handle_update
    return await self.callback(update, context)
  File "/home/bori/dev/py/beud/beubot/start.py", line 35, in start
    await context.bot.send_message( text="A two-column menu", reply_markup=reply_markup)
  File "/home/bori/.local/lib/python3.7/site-packages/telegram/_bot.py", line 236, in decorator
    result = await func(*args, **kwargs)
TypeError: send_message() missing 1 required positional argument: 'chat_id'
2022-06-13 20:01:04,240 | telegram.ext._application | INFO | stop:523 | Application is stopping. This might take a moment.
2022-06-13 20:01:04,241 | apscheduler.scheduler | INFO | shutdown:202 | Scheduler has been shut down
2022-06-13 20:01:04,252 | telegram.ext._application | INFO | stop:548 | Application.stop() complete
2022-06-13 20:01:08,212 | apscheduler.scheduler | INFO | start:171 | Scheduler started
2022-06-13 20:01:08,212 | telegram.ext._application | INFO | start:492 | Application started
2022-06-13 20:01:09,047 | telegram.ext._application | ERROR | process_error:1484 | No error handlers are registered, logging exception.
Traceback (most recent call last):
  File "/home/bori/.local/lib/python3.7/site-packages/telegram/request/_baserequest.py", line 278, in _request_wrapper
    pool_timeout=pool_timeout,
  File "/home/bori/.local/lib/python3.7/site-packages/telegram/request/_httpxrequest.py", line 171, in do_request
    data = request_data.json_parameters if request_data else None
  File "/home/bori/.local/lib/python3.7/site-packages/telegram/request/_requestdata.py", line 75, in json_parameters
    for param in self._parameters
  File "/home/bori/.local/lib/python3.7/site-packages/telegram/request/_requestdata.py", line 76, in <dictcomp>
    if param.json_value is not None
  File "/home/bori/.local/lib/python3.7/site-packages/telegram/request/_requestparameter.py", line 74, in json_value
    return json.dumps(self.value)
  File "/usr/lib/python3.7/json/__init__.py", line 231, in dumps
    return _default_encoder.encode(obj)
  File "/usr/lib/python3.7/json/encoder.py", line 199, in encode
    chunks = self.iterencode(o, _one_shot=True)
  File "/usr/lib/python3.7/json/encoder.py", line 257, in iterencode
    return _iterencode(o, 0)
  File "/usr/lib/python3.7/json/encoder.py", line 179, in default
    raise TypeError(f'Object of type {o.__class__.__name__} '
TypeError: Object of type ellipsis is not JSON serializable

The above exception was the direct cause of the following exception:

Traceback (most recent call last):
  File "/home/bori/.local/lib/python3.7/site-packages/telegram/ext/_application.py", line 970, in process_update
    await coroutine
  File "/home/bori/.local/lib/python3.7/site-packages/telegram/ext/_handler.py", line 137, in handle_update
    return await self.callback(update, context)
  File "/home/bori/dev/py/beud/beubot/start.py", line 38, in start
    reply_markup=reply_markup)
  File "/home/bori/.local/lib/python3.7/site-packages/telegram/_bot.py", line 236, in decorator
    result = await func(*args, **kwargs)
  File "/home/bori/.local/lib/python3.7/site-packages/telegram/_bot.py", line 653, in send_message
    api_kwargs=api_kwargs,
  File "/home/bori/.local/lib/python3.7/site-packages/telegram/ext/_extbot.py", line 266, in _send_message
    api_kwargs=api_kwargs,
  File "/home/bori/.local/lib/python3.7/site-packages/telegram/_bot.py", line 353, in _send_message
    api_kwargs=api_kwargs,
  File "/home/bori/.local/lib/python3.7/site-packages/telegram/_bot.py", line 315, in _post
    pool_timeout=pool_timeout,
  File "/home/bori/.local/lib/python3.7/site-packages/telegram/request/_baserequest.py", line 169, in post
    pool_timeout=pool_timeout,
  File "/home/bori/.local/lib/python3.7/site-packages/telegram/request/_baserequest.py", line 287, in _request_wrapper
    raise NetworkError(f"Unknown error in HTTP implementation: {repr(exc)}") from exc
telegram.error.NetworkError: Unknown error in HTTP implementation: TypeError('Object of type ellipsis is not JSON serializable')
2022-06-13 20:01:11,902 | telegram.ext._application | ERROR | process_error:1484 | No error handlers are registered, logging exception.
Traceback (most recent call last):
  File "/home/bori/.local/lib/python3.7/site-packages/telegram/request/_baserequest.py", line 278, in _request_wrapper
    pool_timeout=pool_timeout,
  File "/home/bori/.local/lib/python3.7/site-packages/telegram/request/_httpxrequest.py", line 171, in do_request
    data = request_data.json_parameters if request_data else None
  File "/home/bori/.local/lib/python3.7/site-packages/telegram/request/_requestdata.py", line 75, in json_parameters
    for param in self._parameters
  File "/home/bori/.local/lib/python3.7/site-packages/telegram/request/_requestdata.py", line 76, in <dictcomp>
    if param.json_value is not None
  File "/home/bori/.local/lib/python3.7/site-packages/telegram/request/_requestparameter.py", line 74, in json_value
    return json.dumps(self.value)
  File "/usr/lib/python3.7/json/__init__.py", line 231, in dumps
    return _default_encoder.encode(obj)
  File "/usr/lib/python3.7/json/encoder.py", line 199, in encode
    chunks = self.iterencode(o, _one_shot=True)
  File "/usr/lib/python3.7/json/encoder.py", line 257, in iterencode
    return _iterencode(o, 0)
  File "/usr/lib/python3.7/json/encoder.py", line 179, in default
    raise TypeError(f'Object of type {o.__class__.__name__} '
TypeError: Object of type ellipsis is not JSON serializable

The above exception was the direct cause of the following exception:

Traceback (most recent call last):
  File "/home/bori/.local/lib/python3.7/site-packages/telegram/ext/_application.py", line 970, in process_update
    await coroutine
  File "/home/bori/.local/lib/python3.7/site-packages/telegram/ext/_handler.py", line 137, in handle_update
    return await self.callback(update, context)
  File "/home/bori/dev/py/beud/beubot/start.py", line 38, in start
    reply_markup=reply_markup)
  File "/home/bori/.local/lib/python3.7/site-packages/telegram/_bot.py", line 236, in decorator
    result = await func(*args, **kwargs)
  File "/home/bori/.local/lib/python3.7/site-packages/telegram/_bot.py", line 653, in send_message
    api_kwargs=api_kwargs,
  File "/home/bori/.local/lib/python3.7/site-packages/telegram/ext/_extbot.py", line 266, in _send_message
    api_kwargs=api_kwargs,
  File "/home/bori/.local/lib/python3.7/site-packages/telegram/_bot.py", line 353, in _send_message
    api_kwargs=api_kwargs,
  File "/home/bori/.local/lib/python3.7/site-packages/telegram/_bot.py", line 315, in _post
    pool_timeout=pool_timeout,
  File "/home/bori/.local/lib/python3.7/site-packages/telegram/request/_baserequest.py", line 169, in post
    pool_timeout=pool_timeout,
  File "/home/bori/.local/lib/python3.7/site-packages/telegram/request/_baserequest.py", line 287, in _request_wrapper
    raise NetworkError(f"Unknown error in HTTP implementation: {repr(exc)}") from exc
telegram.error.NetworkError: Unknown error in HTTP implementation: TypeError('Object of type ellipsis is not JSON serializable')
2022-06-13 20:01:30,971 | telegram.ext._application | INFO | stop:523 | Application is stopping. This might take a moment.
2022-06-13 20:01:30,972 | apscheduler.scheduler | INFO | shutdown:202 | Scheduler has been shut down
2022-06-13 20:01:30,982 | telegram.ext._application | INFO | stop:548 | Application.stop() complete
2022-06-13 20:01:37,605 | apscheduler.scheduler | INFO | start:171 | Scheduler started
2022-06-13 20:01:37,605 | telegram.ext._application | INFO | start:492 | Application started
2022-06-13 20:02:39,494 | telegram.ext._application | INFO | stop:523 | Application is stopping. This might take a moment.
2022-06-13 20:02:39,494 | apscheduler.scheduler | INFO | shutdown:202 | Scheduler has been shut down
2022-06-13 20:02:39,505 | telegram.ext._application | INFO | stop:548 | Application.stop() complete
2022-06-13 20:02:42,543 | apscheduler.scheduler | INFO | start:171 | Scheduler started
2022-06-13 20:02:42,543 | telegram.ext._application | INFO | start:492 | Application started
2022-06-13 20:02:44,760 | telegram.ext._application | ERROR | process_error:1484 | No error handlers are registered, logging exception.
Traceback (most recent call last):
  File "/home/bori/.local/lib/python3.7/site-packages/telegram/ext/_application.py", line 970, in process_update
    await coroutine
  File "/home/bori/.local/lib/python3.7/site-packages/telegram/ext/_handler.py", line 137, in handle_update
    return await self.callback(update, context)
  File "/home/bori/dev/py/beud/beubot/start.py", line 43, in start
    reply_markup=reply_markup)
  File "/home/bori/.local/lib/python3.7/site-packages/telegram/_bot.py", line 236, in decorator
    result = await func(*args, **kwargs)
  File "/home/bori/.local/lib/python3.7/site-packages/telegram/_bot.py", line 653, in send_message
    api_kwargs=api_kwargs,
  File "/home/bori/.local/lib/python3.7/site-packages/telegram/ext/_extbot.py", line 266, in _send_message
    api_kwargs=api_kwargs,
  File "/home/bori/.local/lib/python3.7/site-packages/telegram/_bot.py", line 353, in _send_message
    api_kwargs=api_kwargs,
  File "/home/bori/.local/lib/python3.7/site-packages/telegram/_bot.py", line 315, in _post
    pool_timeout=pool_timeout,
  File "/home/bori/.local/lib/python3.7/site-packages/telegram/request/_baserequest.py", line 169, in post
    pool_timeout=pool_timeout,
  File "/home/bori/.local/lib/python3.7/site-packages/telegram/request/_baserequest.py", line 325, in _request_wrapper
    raise BadRequest(message)
telegram.error.BadRequest: Can't parse keyboard button: field "text" must be of type string
2022-06-13 20:03:49,433 | telegram.ext._application | INFO | stop:523 | Application is stopping. This might take a moment.
2022-06-13 20:03:49,433 | apscheduler.scheduler | INFO | shutdown:202 | Scheduler has been shut down
2022-06-13 20:03:49,444 | telegram.ext._application | INFO | stop:548 | Application.stop() complete
2022-06-13 20:04:14,090 | apscheduler.scheduler | INFO | start:171 | Scheduler started
2022-06-13 20:04:14,090 | telegram.ext._application | INFO | start:492 | Application started
2022-06-13 20:10:28,229 | telegram.ext._application | INFO | stop:523 | Application is stopping. This might take a moment.
2022-06-13 20:10:28,230 | apscheduler.scheduler | INFO | shutdown:202 | Scheduler has been shut down
2022-06-13 20:10:28,241 | telegram.ext._application | INFO | stop:548 | Application.stop() complete
2022-06-13 20:10:31,340 | apscheduler.scheduler | INFO | start:171 | Scheduler started
2022-06-13 20:10:31,340 | telegram.ext._application | INFO | start:492 | Application started
2022-06-13 20:10:56,121 | telegram.ext._application | INFO | stop:523 | Application is stopping. This might take a moment.
2022-06-13 20:10:56,122 | apscheduler.scheduler | INFO | shutdown:202 | Scheduler has been shut down
2022-06-13 20:10:56,132 | telegram.ext._application | INFO | stop:548 | Application.stop() complete
2022-06-13 20:10:58,886 | apscheduler.scheduler | INFO | start:171 | Scheduler started
2022-06-13 20:10:58,887 | telegram.ext._application | INFO | start:492 | Application started
2022-06-13 20:17:30,014 | telegram.ext._application | INFO | stop:523 | Application is stopping. This might take a moment.
2022-06-13 20:17:30,014 | apscheduler.scheduler | INFO | shutdown:202 | Scheduler has been shut down
2022-06-13 20:17:30,025 | telegram.ext._application | INFO | stop:548 | Application.stop() complete
2022-06-13 21:00:05,583 | apscheduler.scheduler | INFO | start:171 | Scheduler started
2022-06-13 21:00:05,584 | telegram.ext._application | INFO | start:492 | Application started
2022-06-13 21:02:57,726 | telegram.ext._application | INFO | stop:523 | Application is stopping. This might take a moment.
2022-06-13 21:02:57,727 | apscheduler.scheduler | INFO | shutdown:202 | Scheduler has been shut down
2022-06-13 21:02:57,738 | telegram.ext._application | INFO | stop:548 | Application.stop() complete
2022-06-13 21:14:29,318 | apscheduler.scheduler | INFO | start:171 | Scheduler started
2022-06-13 21:14:29,318 | telegram.ext._application | INFO | start:492 | Application started
2022-06-13 21:15:16,011 | apscheduler.scheduler | INFO | start:171 | Scheduler started
2022-06-13 21:15:16,011 | telegram.ext._application | INFO | start:492 | Application started
2022-06-13 21:15:52,032 | apscheduler.scheduler | INFO | start:171 | Scheduler started
2022-06-13 21:15:52,033 | telegram.ext._application | INFO | start:492 | Application started
2022-06-13 21:21:12,255 | apscheduler.scheduler | INFO | start:171 | Scheduler started
2022-06-13 21:21:12,259 | telegram.ext._application | INFO | start:492 | Application started
2022-06-13 21:28:22,979 | apscheduler.scheduler | INFO | start:171 | Scheduler started
2022-06-13 21:28:22,980 | telegram.ext._application | INFO | start:492 | Application started
2022-06-13 21:28:32,999 | telegram.ext._updater | ERROR | _network_loop_retry:569 | Error while getting Updates: httpx HTTPError: [Errno -2] Name or service not known
2022-06-13 21:28:32,999 | telegram.ext._application | ERROR | process_error:1480 | An error was raised and an uncaught error was raised while handling the error with an error_handler.
Traceback (most recent call last):
  File "/home/bori/.local/lib/python3.7/site-packages/telegram/ext/_application.py", line 1473, in process_error
    await callback(update, context)
TypeError: object NoneType can't be used in 'await' expression
2022-06-13 21:28:34,006 | telegram.ext._updater | ERROR | _network_loop_retry:569 | Error while getting Updates: httpx HTTPError: [Errno -2] Name or service not known
2022-06-13 21:28:34,006 | telegram.ext._application | ERROR | process_error:1480 | An error was raised and an uncaught error was raised while handling the error with an error_handler.
Traceback (most recent call last):
  File "/home/bori/.local/lib/python3.7/site-packages/telegram/ext/_application.py", line 1473, in process_error
    await callback(update, context)
TypeError: object NoneType can't be used in 'await' expression
2022-06-13 21:28:35,514 | telegram.ext._updater | ERROR | _network_loop_retry:569 | Error while getting Updates: httpx HTTPError: [Errno -2] Name or service not known
2022-06-13 21:28:35,515 | telegram.ext._application | ERROR | process_error:1480 | An error was raised and an uncaught error was raised while handling the error with an error_handler.
Traceback (most recent call last):
  File "/home/bori/.local/lib/python3.7/site-packages/telegram/ext/_application.py", line 1473, in process_error
    await callback(update, context)
TypeError: object NoneType can't be used in 'await' expression
2022-06-13 21:28:37,769 | telegram.ext._updater | ERROR | _network_loop_retry:569 | Error while getting Updates: httpx HTTPError: [Errno -2] Name or service not known
2022-06-13 21:28:37,769 | telegram.ext._application | ERROR | process_error:1480 | An error was raised and an uncaught error was raised while handling the error with an error_handler.
Traceback (most recent call last):
  File "/home/bori/.local/lib/python3.7/site-packages/telegram/ext/_application.py", line 1473, in process_error
    await callback(update, context)
TypeError: object NoneType can't be used in 'await' expression
2022-06-13 21:28:41,152 | telegram.ext._updater | ERROR | _network_loop_retry:569 | Error while getting Updates: httpx HTTPError: [Errno -2] Name or service not known
2022-06-13 21:28:41,152 | telegram.ext._application | ERROR | process_error:1480 | An error was raised and an uncaught error was raised while handling the error with an error_handler.
Traceback (most recent call last):
  File "/home/bori/.local/lib/python3.7/site-packages/telegram/ext/_application.py", line 1473, in process_error
    await callback(update, context)
TypeError: object NoneType can't be used in 'await' expression
2022-06-13 21:28:46,221 | telegram.ext._updater | ERROR | _network_loop_retry:569 | Error while getting Updates: httpx HTTPError: [Errno -2] Name or service not known
2022-06-13 21:28:46,221 | telegram.ext._application | ERROR | process_error:1480 | An error was raised and an uncaught error was raised while handling the error with an error_handler.
Traceback (most recent call last):
  File "/home/bori/.local/lib/python3.7/site-packages/telegram/ext/_application.py", line 1473, in process_error
    await callback(update, context)
TypeError: object NoneType can't be used in 'await' expression
2022-06-13 21:28:53,829 | telegram.ext._updater | ERROR | _network_loop_retry:569 | Error while getting Updates: httpx HTTPError: [Errno -2] Name or service not known
2022-06-13 21:28:53,842 | telegram.ext._application | ERROR | process_error:1480 | An error was raised and an uncaught error was raised while handling the error with an error_handler.
Traceback (most recent call last):
  File "/home/bori/.local/lib/python3.7/site-packages/telegram/ext/_application.py", line 1473, in process_error
    await callback(update, context)
TypeError: object NoneType can't be used in 'await' expression
2022-06-13 21:29:01,316 | apscheduler.scheduler | INFO | start:171 | Scheduler started
2022-06-13 21:29:01,316 | telegram.ext._application | INFO | start:492 | Application started
2022-06-13 21:29:14,068 | telegram.ext._updater | ERROR | _network_loop_retry:569 | Error while getting Updates: httpx HTTPError: [Errno -2] Name or service not known
2022-06-13 21:29:14,069 | telegram.ext._application | ERROR | process_error:1480 | An error was raised and an uncaught error was raised while handling the error with an error_handler.
Traceback (most recent call last):
  File "/home/bori/.local/lib/python3.7/site-packages/telegram/ext/_application.py", line 1473, in process_error
    await callback(update, context)
TypeError: object NoneType can't be used in 'await' expression
2022-06-13 21:29:15,074 | telegram.ext._updater | ERROR | _network_loop_retry:569 | Error while getting Updates: httpx HTTPError: [Errno -2] Name or service not known
2022-06-13 21:29:15,074 | telegram.ext._application | ERROR | process_error:1480 | An error was raised and an uncaught error was raised while handling the error with an error_handler.
Traceback (most recent call last):
  File "/home/bori/.local/lib/python3.7/site-packages/telegram/ext/_application.py", line 1473, in process_error
    await callback(update, context)
TypeError: object NoneType can't be used in 'await' expression
2022-06-13 21:30:05,255 | telegram.ext._updater | ERROR | _network_loop_retry:569 | Error while bootstrap del webhook: httpx HTTPError: [Errno -2] Name or service not known
2022-06-13 21:30:05,255 | telegram.ext._updater | WARNING | bootstrap_on_err_cb:630 | Failed bootstrap phase; try=1 max_retries=-1
2022-06-13 21:30:07,044 | apscheduler.scheduler | INFO | start:171 | Scheduler started
2022-06-13 21:30:07,048 | telegram.ext._application | INFO | start:492 | Application started
2022-06-13 21:51:43,082 | apscheduler.scheduler | INFO | start:171 | Scheduler started
2022-06-13 21:51:43,084 | telegram.ext._application | INFO | start:492 | Application started
2022-06-13 21:53:29,821 | apscheduler.scheduler | INFO | start:171 | Scheduler started
2022-06-13 21:53:29,821 | telegram.ext._application | INFO | start:492 | Application started
2022-06-13 21:57:07,296 | apscheduler.scheduler | INFO | start:171 | Scheduler started
2022-06-13 21:57:07,296 | telegram.ext._application | INFO | start:492 | Application started
2022-06-13 21:58:05,724 | apscheduler.scheduler | INFO | start:171 | Scheduler started
2022-06-13 21:58:05,725 | telegram.ext._application | INFO | start:492 | Application started
2022-06-13 21:58:40,845 | apscheduler.scheduler | INFO | start:171 | Scheduler started
2022-06-13 21:58:40,845 | telegram.ext._application | INFO | start:492 | Application started
2022-06-13 21:58:44,582 | telegram.ext._application | ERROR | process_error:1480 | An error was raised and an uncaught error was raised while handling the error with an error_handler.
Traceback (most recent call last):
  File "/home/bori/.local/lib/python3.7/site-packages/telegram/ext/_application.py", line 970, in process_update
    await coroutine
  File "/home/bori/.local/lib/python3.7/site-packages/telegram/ext/_handler.py", line 137, in handle_update
    return await self.callback(update, context)
  File "/home/bori/dev/py/beud/beubot/start.py", line 48, in start_hlr
    reply_markup=reply_markup)
  File "/home/bori/.local/lib/python3.7/site-packages/telegram/_bot.py", line 236, in decorator
    result = await func(*args, **kwargs)
  File "/home/bori/.local/lib/python3.7/site-packages/telegram/_bot.py", line 653, in send_message
    api_kwargs=api_kwargs,
  File "/home/bori/.local/lib/python3.7/site-packages/telegram/ext/_extbot.py", line 266, in _send_message
    api_kwargs=api_kwargs,
  File "/home/bori/.local/lib/python3.7/site-packages/telegram/_bot.py", line 353, in _send_message
    api_kwargs=api_kwargs,
  File "/home/bori/.local/lib/python3.7/site-packages/telegram/_bot.py", line 315, in _post
    pool_timeout=pool_timeout,
  File "/home/bori/.local/lib/python3.7/site-packages/telegram/request/_baserequest.py", line 169, in post
    pool_timeout=pool_timeout,
  File "/home/bori/.local/lib/python3.7/site-packages/telegram/request/_baserequest.py", line 325, in _request_wrapper
    raise BadRequest(message)
telegram.error.BadRequest: Can't parse keyboard button: field "text" must be of type string

During handling of the above exception, another exception occurred:

Traceback (most recent call last):
  File "/home/bori/.local/lib/python3.7/site-packages/telegram/ext/_application.py", line 1473, in process_error
    await callback(update, context)
TypeError: object NoneType can't be used in 'await' expression
2022-06-13 21:59:15,085 | apscheduler.scheduler | INFO | start:171 | Scheduler started
2022-06-13 21:59:15,093 | telegram.ext._application | INFO | start:492 | Application started
2022-06-13 21:59:16,811 | telegram.ext._application | ERROR | process_error:1480 | An error was raised and an uncaught error was raised while handling the error with an error_handler.
Traceback (most recent call last):
  File "/home/bori/.local/lib/python3.7/site-packages/telegram/ext/_application.py", line 970, in process_update
    await coroutine
  File "/home/bori/.local/lib/python3.7/site-packages/telegram/ext/_handler.py", line 137, in handle_update
    return await self.callback(update, context)
  File "/home/bori/dev/py/beud/beubot/start.py", line 48, in start_hlr
    reply_markup=reply_markup)
  File "/home/bori/.local/lib/python3.7/site-packages/telegram/_bot.py", line 236, in decorator
    result = await func(*args, **kwargs)
  File "/home/bori/.local/lib/python3.7/site-packages/telegram/_bot.py", line 653, in send_message
    api_kwargs=api_kwargs,
  File "/home/bori/.local/lib/python3.7/site-packages/telegram/ext/_extbot.py", line 266, in _send_message
    api_kwargs=api_kwargs,
  File "/home/bori/.local/lib/python3.7/site-packages/telegram/_bot.py", line 353, in _send_message
    api_kwargs=api_kwargs,
  File "/home/bori/.local/lib/python3.7/site-packages/telegram/_bot.py", line 315, in _post
    pool_timeout=pool_timeout,
  File "/home/bori/.local/lib/python3.7/site-packages/telegram/request/_baserequest.py", line 169, in post
    pool_timeout=pool_timeout,
  File "/home/bori/.local/lib/python3.7/site-packages/telegram/request/_baserequest.py", line 325, in _request_wrapper
    raise BadRequest(message)
telegram.error.BadRequest: Can't parse keyboard button: field "text" must be of type string

During handling of the above exception, another exception occurred:

Traceback (most recent call last):
  File "/home/bori/.local/lib/python3.7/site-packages/telegram/ext/_application.py", line 1473, in process_error
    await callback(update, context)
TypeError: object NoneType can't be used in 'await' expression
2022-06-13 21:59:38,427 | apscheduler.scheduler | INFO | start:171 | Scheduler started
2022-06-13 21:59:38,428 | telegram.ext._application | INFO | start:492 | Application started
2022-06-13 22:01:32,902 | apscheduler.scheduler | INFO | start:171 | Scheduler started
2022-06-13 22:01:32,903 | telegram.ext._application | INFO | start:492 | Application started
2022-06-13 22:01:42,477 | telegram.ext._application | ERROR | process_error:1480 | An error was raised and an uncaught error was raised while handling the error with an error_handler.
Traceback (most recent call last):
  File "/home/bori/.local/lib/python3.7/site-packages/telegram/ext/_application.py", line 970, in process_update
    await coroutine
  File "/home/bori/.local/lib/python3.7/site-packages/telegram/ext/_handler.py", line 137, in handle_update
    return await self.callback(update, context)
  File "/home/bori/dev/py/beud/beubot/start.py", line 39, in start_hlr
    reply_markup = ReplyKeyboardMarkup(build_menu(button_list,))
TypeError: build_menu() missing 1 required positional argument: 'n_cols'

During handling of the above exception, another exception occurred:

Traceback (most recent call last):
  File "/home/bori/.local/lib/python3.7/site-packages/telegram/ext/_application.py", line 1473, in process_error
    await callback(update, context)
TypeError: object NoneType can't be used in 'await' expression
2022-06-13 22:01:42,480 | telegram.ext._application | ERROR | process_error:1480 | An error was raised and an uncaught error was raised while handling the error with an error_handler.
Traceback (most recent call last):
  File "/home/bori/.local/lib/python3.7/site-packages/telegram/ext/_application.py", line 970, in process_update
    await coroutine
  File "/home/bori/.local/lib/python3.7/site-packages/telegram/ext/_handler.py", line 137, in handle_update
    return await self.callback(update, context)
  File "/home/bori/dev/py/beud/beubot/start.py", line 39, in start_hlr
    reply_markup = ReplyKeyboardMarkup(build_menu(button_list,))
TypeError: build_menu() missing 1 required positional argument: 'n_cols'

During handling of the above exception, another exception occurred:

Traceback (most recent call last):
  File "/home/bori/.local/lib/python3.7/site-packages/telegram/ext/_application.py", line 1473, in process_error
    await callback(update, context)
TypeError: object NoneType can't be used in 'await' expression
2022-06-13 22:01:44,892 | telegram.ext._application | ERROR | process_error:1480 | An error was raised and an uncaught error was raised while handling the error with an error_handler.
Traceback (most recent call last):
  File "/home/bori/.local/lib/python3.7/site-packages/telegram/ext/_application.py", line 970, in process_update
    await coroutine
  File "/home/bori/.local/lib/python3.7/site-packages/telegram/ext/_handler.py", line 137, in handle_update
    return await self.callback(update, context)
  File "/home/bori/dev/py/beud/beubot/start.py", line 39, in start_hlr
    reply_markup = ReplyKeyboardMarkup(build_menu(button_list,))
TypeError: build_menu() missing 1 required positional argument: 'n_cols'

During handling of the above exception, another exception occurred:

Traceback (most recent call last):
  File "/home/bori/.local/lib/python3.7/site-packages/telegram/ext/_application.py", line 1473, in process_error
    await callback(update, context)
TypeError: object NoneType can't be used in 'await' expression
2022-06-13 22:02:00,286 | apscheduler.scheduler | INFO | start:171 | Scheduler started
2022-06-13 22:02:00,287 | telegram.ext._application | INFO | start:492 | Application started
2022-06-13 22:02:38,577 | apscheduler.scheduler | INFO | start:171 | Scheduler started
2022-06-13 22:02:38,577 | telegram.ext._application | INFO | start:492 | Application started
2022-06-13 22:07:06,746 | apscheduler.scheduler | INFO | start:171 | Scheduler started
2022-06-13 22:07:06,748 | telegram.ext._application | INFO | start:492 | Application started
2022-06-13 22:07:08,124 | telegram.ext._application | ERROR | process_error:1480 | An error was raised and an uncaught error was raised while handling the error with an error_handler.
Traceback (most recent call last):
  File "/home/bori/.local/lib/python3.7/site-packages/telegram/ext/_application.py", line 970, in process_update
    await coroutine
  File "/home/bori/.local/lib/python3.7/site-packages/telegram/ext/_handler.py", line 137, in handle_update
    return await self.callback(update, context)
TypeError: object NoneType can't be used in 'await' expression

During handling of the above exception, another exception occurred:

Traceback (most recent call last):
  File "/home/bori/.local/lib/python3.7/site-packages/telegram/ext/_application.py", line 1473, in process_error
    await callback(update, context)
TypeError: object NoneType can't be used in 'await' expression
2022-06-13 22:07:08,125 | telegram.ext._application | ERROR | process_error:1480 | An error was raised and an uncaught error was raised while handling the error with an error_handler.
Traceback (most recent call last):
  File "/home/bori/.local/lib/python3.7/site-packages/telegram/ext/_application.py", line 970, in process_update
    await coroutine
  File "/home/bori/.local/lib/python3.7/site-packages/telegram/ext/_handler.py", line 137, in handle_update
    return await self.callback(update, context)
TypeError: object NoneType can't be used in 'await' expression

During handling of the above exception, another exception occurred:

Traceback (most recent call last):
  File "/home/bori/.local/lib/python3.7/site-packages/telegram/ext/_application.py", line 1473, in process_error
    await callback(update, context)
TypeError: object NoneType can't be used in 'await' expression
2022-06-13 22:07:08,126 | telegram.ext._application | ERROR | process_error:1480 | An error was raised and an uncaught error was raised while handling the error with an error_handler.
Traceback (most recent call last):
  File "/home/bori/.local/lib/python3.7/site-packages/telegram/ext/_application.py", line 970, in process_update
    await coroutine
  File "/home/bori/.local/lib/python3.7/site-packages/telegram/ext/_handler.py", line 137, in handle_update
    return await self.callback(update, context)
TypeError: object NoneType can't be used in 'await' expression

During handling of the above exception, another exception occurred:

Traceback (most recent call last):
  File "/home/bori/.local/lib/python3.7/site-packages/telegram/ext/_application.py", line 1473, in process_error
    await callback(update, context)
TypeError: object NoneType can't be used in 'await' expression
2022-06-13 22:07:08,127 | telegram.ext._application | ERROR | process_error:1480 | An error was raised and an uncaught error was raised while handling the error with an error_handler.
Traceback (most recent call last):
  File "/home/bori/.local/lib/python3.7/site-packages/telegram/ext/_application.py", line 970, in process_update
    await coroutine
  File "/home/bori/.local/lib/python3.7/site-packages/telegram/ext/_handler.py", line 137, in handle_update
    return await self.callback(update, context)
TypeError: object NoneType can't be used in 'await' expression

During handling of the above exception, another exception occurred:

Traceback (most recent call last):
  File "/home/bori/.local/lib/python3.7/site-packages/telegram/ext/_application.py", line 1473, in process_error
    await callback(update, context)
TypeError: object NoneType can't be used in 'await' expression
2022-06-13 22:07:08,128 | telegram.ext._application | ERROR | process_error:1480 | An error was raised and an uncaught error was raised while handling the error with an error_handler.
Traceback (most recent call last):
  File "/home/bori/.local/lib/python3.7/site-packages/telegram/ext/_application.py", line 970, in process_update
    await coroutine
  File "/home/bori/.local/lib/python3.7/site-packages/telegram/ext/_handler.py", line 137, in handle_update
    return await self.callback(update, context)
TypeError: object NoneType can't be used in 'await' expression

During handling of the above exception, another exception occurred:

Traceback (most recent call last):
  File "/home/bori/.local/lib/python3.7/site-packages/telegram/ext/_application.py", line 1473, in process_error
    await callback(update, context)
TypeError: object NoneType can't be used in 'await' expression
2022-06-13 22:07:09,012 | telegram.ext._application | ERROR | process_error:1480 | An error was raised and an uncaught error was raised while handling the error with an error_handler.
Traceback (most recent call last):
  File "/home/bori/.local/lib/python3.7/site-packages/telegram/ext/_application.py", line 970, in process_update
    await coroutine
  File "/home/bori/.local/lib/python3.7/site-packages/telegram/ext/_handler.py", line 137, in handle_update
    return await self.callback(update, context)
TypeError: object NoneType can't be used in 'await' expression

During handling of the above exception, another exception occurred:

Traceback (most recent call last):
  File "/home/bori/.local/lib/python3.7/site-packages/telegram/ext/_application.py", line 1473, in process_error
    await callback(update, context)
TypeError: object NoneType can't be used in 'await' expression
2022-06-13 22:08:06,751 | telegram.ext._application | ERROR | process_error:1480 | An error was raised and an uncaught error was raised while handling the error with an error_handler.
Traceback (most recent call last):
  File "/home/bori/.local/lib/python3.7/site-packages/telegram/ext/_application.py", line 970, in process_update
    await coroutine
  File "/home/bori/.local/lib/python3.7/site-packages/telegram/ext/_handler.py", line 137, in handle_update
    return await self.callback(update, context)
TypeError: object NoneType can't be used in 'await' expression

During handling of the above exception, another exception occurred:

Traceback (most recent call last):
  File "/home/bori/.local/lib/python3.7/site-packages/telegram/ext/_application.py", line 1473, in process_error
    await callback(update, context)
TypeError: object NoneType can't be used in 'await' expression
2022-06-13 22:08:48,249 | apscheduler.scheduler | INFO | start:171 | Scheduler started
2022-06-13 22:08:48,250 | telegram.ext._application | INFO | start:492 | Application started
2022-06-13 22:09:00,790 | apscheduler.scheduler | INFO | start:171 | Scheduler started
2022-06-13 22:09:00,791 | telegram.ext._application | INFO | start:492 | Application started
2022-06-13 22:09:01,567 | telegram.ext._application | ERROR | process_error:1480 | An error was raised and an uncaught error was raised while handling the error with an error_handler.
Traceback (most recent call last):
  File "/home/bori/.local/lib/python3.7/site-packages/telegram/ext/_application.py", line 970, in process_update
    await coroutine
  File "/home/bori/.local/lib/python3.7/site-packages/telegram/ext/_handler.py", line 137, in handle_update
    return await self.callback(update, context)
TypeError: object NoneType can't be used in 'await' expression

During handling of the above exception, another exception occurred:

Traceback (most recent call last):
  File "/home/bori/.local/lib/python3.7/site-packages/telegram/ext/_application.py", line 1473, in process_error
    await callback(update, context)
TypeError: object NoneType can't be used in 'await' expression
2022-06-13 22:09:01,570 | telegram.ext._application | ERROR | process_error:1480 | An error was raised and an uncaught error was raised while handling the error with an error_handler.
Traceback (most recent call last):
  File "/home/bori/.local/lib/python3.7/site-packages/telegram/ext/_application.py", line 970, in process_update
    await coroutine
  File "/home/bori/.local/lib/python3.7/site-packages/telegram/ext/_handler.py", line 137, in handle_update
    return await self.callback(update, context)
TypeError: object NoneType can't be used in 'await' expression

During handling of the above exception, another exception occurred:

Traceback (most recent call last):
  File "/home/bori/.local/lib/python3.7/site-packages/telegram/ext/_application.py", line 1473, in process_error
    await callback(update, context)
TypeError: object NoneType can't be used in 'await' expression
2022-06-13 22:09:02,241 | telegram.ext._application | ERROR | process_error:1480 | An error was raised and an uncaught error was raised while handling the error with an error_handler.
Traceback (most recent call last):
  File "/home/bori/.local/lib/python3.7/site-packages/telegram/ext/_application.py", line 970, in process_update
    await coroutine
  File "/home/bori/.local/lib/python3.7/site-packages/telegram/ext/_handler.py", line 137, in handle_update
    return await self.callback(update, context)
TypeError: object NoneType can't be used in 'await' expression

During handling of the above exception, another exception occurred:

Traceback (most recent call last):
  File "/home/bori/.local/lib/python3.7/site-packages/telegram/ext/_application.py", line 1473, in process_error
    await callback(update, context)
TypeError: object NoneType can't be used in 'await' expression
2022-06-13 22:09:02,684 | telegram.ext._application | ERROR | process_error:1480 | An error was raised and an uncaught error was raised while handling the error with an error_handler.
Traceback (most recent call last):
  File "/home/bori/.local/lib/python3.7/site-packages/telegram/ext/_application.py", line 970, in process_update
    await coroutine
  File "/home/bori/.local/lib/python3.7/site-packages/telegram/ext/_handler.py", line 137, in handle_update
    return await self.callback(update, context)
TypeError: object NoneType can't be used in 'await' expression

During handling of the above exception, another exception occurred:

Traceback (most recent call last):
  File "/home/bori/.local/lib/python3.7/site-packages/telegram/ext/_application.py", line 1473, in process_error
    await callback(update, context)
TypeError: object NoneType can't be used in 'await' expression
2022-06-13 22:09:30,149 | apscheduler.scheduler | INFO | start:171 | Scheduler started
2022-06-13 22:09:30,152 | telegram.ext._application | INFO | start:492 | Application started
2022-06-13 22:09:31,709 | telegram.ext._application | ERROR | process_error:1480 | An error was raised and an uncaught error was raised while handling the error with an error_handler.
Traceback (most recent call last):
  File "/home/bori/.local/lib/python3.7/site-packages/telegram/ext/_application.py", line 970, in process_update
    await coroutine
  File "/home/bori/.local/lib/python3.7/site-packages/telegram/ext/_handler.py", line 137, in handle_update
    return await self.callback(update, context)
TypeError: object NoneType can't be used in 'await' expression

During handling of the above exception, another exception occurred:

Traceback (most recent call last):
  File "/home/bori/.local/lib/python3.7/site-packages/telegram/ext/_application.py", line 1473, in process_error
    await callback(update, context)
TypeError: object NoneType can't be used in 'await' expression
2022-06-13 22:09:31,713 | telegram.ext._application | ERROR | process_error:1480 | An error was raised and an uncaught error was raised while handling the error with an error_handler.
Traceback (most recent call last):
  File "/home/bori/.local/lib/python3.7/site-packages/telegram/ext/_application.py", line 970, in process_update
    await coroutine
  File "/home/bori/.local/lib/python3.7/site-packages/telegram/ext/_handler.py", line 137, in handle_update
    return await self.callback(update, context)
TypeError: object NoneType can't be used in 'await' expression

During handling of the above exception, another exception occurred:

Traceback (most recent call last):
  File "/home/bori/.local/lib/python3.7/site-packages/telegram/ext/_application.py", line 1473, in process_error
    await callback(update, context)
TypeError: object NoneType can't be used in 'await' expression
2022-06-13 22:10:38,661 | apscheduler.scheduler | INFO | start:171 | Scheduler started
2022-06-13 22:10:38,662 | telegram.ext._application | INFO | start:492 | Application started
2022-06-13 22:10:58,159 | apscheduler.scheduler | INFO | start:171 | Scheduler started
2022-06-13 22:10:58,161 | telegram.ext._application | INFO | start:492 | Application started
2022-06-13 22:12:50,600 | apscheduler.scheduler | INFO | start:171 | Scheduler started
2022-06-13 22:12:50,601 | telegram.ext._application | INFO | start:492 | Application started
2022-06-13 22:14:09,174 | apscheduler.scheduler | INFO | start:171 | Scheduler started
2022-06-13 22:14:09,174 | telegram.ext._application | INFO | start:492 | Application started
2022-06-13 22:14:25,993 | telegram.ext._application | INFO | stop:523 | Application is stopping. This might take a moment.
2022-06-13 22:14:25,994 | apscheduler.scheduler | INFO | shutdown:202 | Scheduler has been shut down
2022-06-13 22:14:26,004 | telegram.ext._application | INFO | stop:548 | Application.stop() complete
2022-06-13 22:14:29,977 | apscheduler.scheduler | INFO | start:171 | Scheduler started
2022-06-13 22:14:29,978 | telegram.ext._application | INFO | start:492 | Application started
2022-06-13 22:15:19,492 | apscheduler.scheduler | INFO | start:171 | Scheduler started
2022-06-13 22:15:19,493 | telegram.ext._application | INFO | start:492 | Application started
2022-06-13 22:15:44,028 | apscheduler.scheduler | INFO | start:171 | Scheduler started
2022-06-13 22:15:44,029 | telegram.ext._application | INFO | start:492 | Application started
2022-06-13 22:16:04,219 | apscheduler.scheduler | INFO | start:171 | Scheduler started
2022-06-13 22:16:04,221 | telegram.ext._application | INFO | start:492 | Application started
2022-06-13 22:17:12,161 | apscheduler.scheduler | INFO | start:171 | Scheduler started
2022-06-13 22:17:12,161 | telegram.ext._application | INFO | start:492 | Application started
2022-06-13 22:19:35,757 | apscheduler.scheduler | INFO | start:171 | Scheduler started
2022-06-13 22:19:35,758 | telegram.ext._application | INFO | start:492 | Application started
2022-06-13 22:20:33,564 | apscheduler.scheduler | INFO | start:171 | Scheduler started
2022-06-13 22:20:33,566 | telegram.ext._application | INFO | start:492 | Application started
2022-06-13 22:21:10,019 | apscheduler.scheduler | INFO | start:171 | Scheduler started
2022-06-13 22:21:10,019 | telegram.ext._application | INFO | start:492 | Application started
2022-06-13 22:21:42,628 | apscheduler.scheduler | INFO | start:171 | Scheduler started
2022-06-13 22:21:42,629 | telegram.ext._application | INFO | start:492 | Application started
2022-06-13 22:22:35,097 | apscheduler.scheduler | INFO | start:171 | Scheduler started
2022-06-13 22:22:35,097 | telegram.ext._application | INFO | start:492 | Application started
2022-06-13 22:22:58,233 | apscheduler.scheduler | INFO | start:171 | Scheduler started
2022-06-13 22:22:58,236 | telegram.ext._application | INFO | start:492 | Application started
2022-06-13 22:23:11,928 | apscheduler.scheduler | INFO | start:171 | Scheduler started
2022-06-13 22:23:11,928 | telegram.ext._application | INFO | start:492 | Application started
2022-06-13 22:23:38,774 | apscheduler.scheduler | INFO | start:171 | Scheduler started
2022-06-13 22:23:38,775 | telegram.ext._application | INFO | start:492 | Application started
2022-06-13 22:24:03,324 | apscheduler.scheduler | INFO | start:171 | Scheduler started
2022-06-13 22:24:03,324 | telegram.ext._application | INFO | start:492 | Application started
2022-06-13 22:24:20,669 | apscheduler.scheduler | INFO | start:171 | Scheduler started
2022-06-13 22:24:20,669 | telegram.ext._application | INFO | start:492 | Application started
2022-06-13 22:24:46,894 | apscheduler.scheduler | INFO | start:171 | Scheduler started
2022-06-13 22:24:46,894 | telegram.ext._application | INFO | start:492 | Application started
2022-06-13 22:25:41,192 | apscheduler.scheduler | INFO | start:171 | Scheduler started
2022-06-13 22:25:41,192 | telegram.ext._application | INFO | start:492 | Application started
2022-06-13 22:25:51,671 | apscheduler.scheduler | INFO | start:171 | Scheduler started
2022-06-13 22:25:51,672 | telegram.ext._application | INFO | start:492 | Application started
2022-06-13 22:26:04,627 | apscheduler.scheduler | INFO | start:171 | Scheduler started
2022-06-13 22:26:04,627 | telegram.ext._application | INFO | start:492 | Application started
2022-06-13 22:27:22,213 | apscheduler.scheduler | INFO | start:171 | Scheduler started
2022-06-13 22:27:22,213 | telegram.ext._application | INFO | start:492 | Application started
2022-06-13 22:27:30,502 | apscheduler.scheduler | INFO | start:171 | Scheduler started
2022-06-13 22:27:30,502 | telegram.ext._application | INFO | start:492 | Application started
2022-06-13 22:27:52,797 | apscheduler.scheduler | INFO | start:171 | Scheduler started
2022-06-13 22:27:52,798 | telegram.ext._application | INFO | start:492 | Application started
2022-06-13 22:28:12,601 | apscheduler.scheduler | INFO | start:171 | Scheduler started
2022-06-13 22:28:12,601 | telegram.ext._application | INFO | start:492 | Application started
2022-06-13 22:28:58,014 | apscheduler.scheduler | INFO | start:171 | Scheduler started
2022-06-13 22:28:58,014 | telegram.ext._application | INFO | start:492 | Application started
2022-06-13 22:33:16,160 | apscheduler.scheduler | INFO | start:171 | Scheduler started
2022-06-13 22:33:16,161 | telegram.ext._application | INFO | start:492 | Application started
2022-06-13 22:35:35,279 | apscheduler.scheduler | INFO | start:171 | Scheduler started
2022-06-13 22:35:35,279 | telegram.ext._application | INFO | start:492 | Application started
2022-06-13 22:35:52,933 | apscheduler.scheduler | INFO | start:171 | Scheduler started
2022-06-13 22:35:52,934 | telegram.ext._application | INFO | start:492 | Application started
2022-06-13 22:36:43,198 | apscheduler.scheduler | INFO | start:171 | Scheduler started
2022-06-13 22:36:43,203 | telegram.ext._application | INFO | start:492 | Application started
2022-06-13 22:37:26,311 | apscheduler.scheduler | INFO | start:171 | Scheduler started
2022-06-13 22:37:26,314 | telegram.ext._application | INFO | start:492 | Application started
2022-06-13 22:38:09,770 | apscheduler.scheduler | INFO | start:171 | Scheduler started
2022-06-13 22:38:09,771 | telegram.ext._application | INFO | start:492 | Application started
2022-06-13 22:38:26,301 | apscheduler.scheduler | INFO | start:171 | Scheduler started
2022-06-13 22:38:26,303 | telegram.ext._application | INFO | start:492 | Application started
2022-06-13 22:39:05,270 | telegram.ext._updater | ERROR | _network_loop_retry:569 | Error while getting Updates: httpx HTTPError: [Errno -2] Name or service not known
2022-06-13 22:39:06,274 | telegram.ext._updater | ERROR | _network_loop_retry:569 | Error while getting Updates: httpx HTTPError: [Errno -2] Name or service not known
2022-06-13 22:39:07,779 | telegram.ext._updater | ERROR | _network_loop_retry:569 | Error while getting Updates: httpx HTTPError: [Errno -2] Name or service not known
2022-06-13 22:39:10,033 | telegram.ext._updater | ERROR | _network_loop_retry:569 | Error while getting Updates: httpx HTTPError: [Errno -2] Name or service not known
2022-06-13 22:40:29,877 | telegram.ext._updater | ERROR | _network_loop_retry:569 | Error while getting Updates: httpx HTTPError: [Errno -2] Name or service not known
2022-06-13 22:40:30,882 | telegram.ext._updater | ERROR | _network_loop_retry:569 | Error while getting Updates: httpx HTTPError: [Errno -2] Name or service not known
2022-06-13 22:40:32,387 | telegram.ext._updater | ERROR | _network_loop_retry:569 | Error while getting Updates: httpx HTTPError: [Errno -2] Name or service not known
2022-06-13 22:43:47,623 | apscheduler.scheduler | INFO | start:171 | Scheduler started
2022-06-13 22:43:47,623 | telegram.ext._application | INFO | start:492 | Application started
2022-06-13 22:57:38,522 | apscheduler.scheduler | INFO | start:171 | Scheduler started
2022-06-13 22:57:38,522 | telegram.ext._application | INFO | start:492 | Application started
2022-06-13 22:57:57,266 | apscheduler.scheduler | INFO | start:171 | Scheduler started
2022-06-13 22:57:57,272 | telegram.ext._application | INFO | start:492 | Application started
2022-06-13 22:58:15,309 | apscheduler.scheduler | INFO | start:171 | Scheduler started
2022-06-13 22:58:15,319 | telegram.ext._application | INFO | start:492 | Application started
2022-06-13 22:58:37,670 | apscheduler.scheduler | INFO | start:171 | Scheduler started
2022-06-13 22:58:37,670 | telegram.ext._application | INFO | start:492 | Application started
2022-06-13 22:58:50,584 | apscheduler.scheduler | INFO | start:171 | Scheduler started
2022-06-13 22:58:50,584 | telegram.ext._application | INFO | start:492 | Application started
2022-06-13 23:01:01,197 | apscheduler.scheduler | INFO | start:171 | Scheduler started
2022-06-13 23:01:01,199 | telegram.ext._application | INFO | start:492 | Application started
2022-06-13 23:01:37,977 | apscheduler.scheduler | INFO | start:171 | Scheduler started
2022-06-13 23:01:37,978 | telegram.ext._application | INFO | start:492 | Application started
2022-06-13 23:07:42,361 | apscheduler.scheduler | INFO | start:171 | Scheduler started
2022-06-13 23:07:42,361 | telegram.ext._application | INFO | start:492 | Application started
2022-06-13 23:07:47,573 | apscheduler.scheduler | INFO | start:171 | Scheduler started
2022-06-13 23:07:47,573 | telegram.ext._application | INFO | start:492 | Application started
2022-06-13 23:08:22,157 | apscheduler.scheduler | INFO | start:171 | Scheduler started
2022-06-13 23:08:22,158 | telegram.ext._application | INFO | start:492 | Application started
2022-06-13 23:09:02,426 | apscheduler.scheduler | INFO | start:171 | Scheduler started
2022-06-13 23:09:02,426 | telegram.ext._application | INFO | start:492 | Application started
2022-06-13 23:09:22,132 | apscheduler.scheduler | INFO | start:171 | Scheduler started
2022-06-13 23:09:22,133 | telegram.ext._application | INFO | start:492 | Application started
2022-06-13 23:09:43,607 | apscheduler.scheduler | INFO | start:171 | Scheduler started
2022-06-13 23:09:43,608 | telegram.ext._application | INFO | start:492 | Application started
2022-06-13 23:10:06,407 | apscheduler.scheduler | INFO | start:171 | Scheduler started
2022-06-13 23:10:06,409 | telegram.ext._application | INFO | start:492 | Application started
2022-06-13 23:11:02,347 | apscheduler.scheduler | INFO | start:171 | Scheduler started
2022-06-13 23:11:02,347 | telegram.ext._application | INFO | start:492 | Application started
2022-06-13 23:12:12,391 | apscheduler.scheduler | INFO | start:171 | Scheduler started
2022-06-13 23:12:12,391 | telegram.ext._application | INFO | start:492 | Application started
2022-06-13 23:13:01,405 | apscheduler.scheduler | INFO | start:171 | Scheduler started
2022-06-13 23:13:01,405 | telegram.ext._application | INFO | start:492 | Application started
2022-06-13 23:15:46,121 | apscheduler.scheduler | INFO | start:171 | Scheduler started
2022-06-13 23:15:46,122 | telegram.ext._application | INFO | start:492 | Application started
2022-06-13 23:15:50,870 | apscheduler.scheduler | INFO | start:171 | Scheduler started
2022-06-13 23:15:50,871 | telegram.ext._application | INFO | start:492 | Application started
2022-06-13 23:16:11,591 | apscheduler.scheduler | INFO | start:171 | Scheduler started
2022-06-13 23:16:11,591 | telegram.ext._application | INFO | start:492 | Application started
2022-06-13 23:17:04,464 | apscheduler.scheduler | INFO | start:171 | Scheduler started
2022-06-13 23:17:04,464 | telegram.ext._application | INFO | start:492 | Application started
2022-06-13 23:18:05,736 | apscheduler.scheduler | INFO | start:171 | Scheduler started
2022-06-13 23:18:05,737 | telegram.ext._application | INFO | start:492 | Application started
2022-06-13 23:18:28,809 | apscheduler.scheduler | INFO | start:171 | Scheduler started
2022-06-13 23:18:28,810 | telegram.ext._application | INFO | start:492 | Application started
2022-06-13 23:19:39,836 | apscheduler.scheduler | INFO | start:171 | Scheduler started
2022-06-13 23:19:39,836 | telegram.ext._application | INFO | start:492 | Application started
2022-06-13 23:21:09,566 | apscheduler.scheduler | INFO | start:171 | Scheduler started
2022-06-13 23:21:09,567 | telegram.ext._application | INFO | start:492 | Application started
2022-06-13 23:21:30,260 | apscheduler.scheduler | INFO | start:171 | Scheduler started
2022-06-13 23:21:30,261 | telegram.ext._application | INFO | start:492 | Application started
2022-06-13 23:22:13,387 | apscheduler.scheduler | INFO | start:171 | Scheduler started
2022-06-13 23:22:13,387 | telegram.ext._application | INFO | start:492 | Application started
2022-06-13 23:25:22,311 | apscheduler.scheduler | INFO | start:171 | Scheduler started
2022-06-13 23:25:22,317 | telegram.ext._application | INFO | start:492 | Application started
2022-06-13 23:25:31,395 | apscheduler.scheduler | INFO | start:171 | Scheduler started
2022-06-13 23:25:31,396 | telegram.ext._application | INFO | start:492 | Application started
2022-06-13 23:25:43,610 | apscheduler.scheduler | INFO | start:171 | Scheduler started
2022-06-13 23:25:43,610 | telegram.ext._application | INFO | start:492 | Application started
2022-06-13 23:26:22,685 | apscheduler.scheduler | INFO | start:171 | Scheduler started
2022-06-13 23:26:22,686 | telegram.ext._application | INFO | start:492 | Application started
2022-06-13 23:26:33,837 | apscheduler.scheduler | INFO | start:171 | Scheduler started
2022-06-13 23:26:33,839 | telegram.ext._application | INFO | start:492 | Application started
2022-06-13 23:26:39,416 | apscheduler.scheduler | INFO | start:171 | Scheduler started
2022-06-13 23:26:39,416 | telegram.ext._application | INFO | start:492 | Application started
2022-06-13 23:26:58,761 | apscheduler.scheduler | INFO | start:171 | Scheduler started
2022-06-13 23:26:58,762 | telegram.ext._application | INFO | start:492 | Application started
2022-06-13 23:27:16,384 | apscheduler.scheduler | INFO | start:171 | Scheduler started
2022-06-13 23:27:16,385 | telegram.ext._application | INFO | start:492 | Application started
2022-06-13 23:27:38,307 | apscheduler.scheduler | INFO | start:171 | Scheduler started
2022-06-13 23:27:38,308 | telegram.ext._application | INFO | start:492 | Application started
