2022-06-14 00:02:24,077 | apscheduler.scheduler | INFO | start:171 | Scheduler started
2022-06-14 00:02:24,083 | telegram.ext._application | INFO | start:492 | Application started
2022-06-14 00:02:47,833 | apscheduler.scheduler | INFO | start:171 | Scheduler started
2022-06-14 00:02:47,834 | telegram.ext._application | INFO | start:492 | Application started
2022-06-14 00:06:48,863 | apscheduler.scheduler | INFO | start:171 | Scheduler started
2022-06-14 00:06:48,863 | telegram.ext._application | INFO | start:492 | Application started
2022-06-14 01:06:40,362 | telegram.ext._application | INFO | stop:523 | Application is stopping. This might take a moment.
2022-06-14 01:06:40,476 | apscheduler.scheduler | INFO | shutdown:202 | Scheduler has been shut down
2022-06-14 01:06:40,487 | telegram.ext._application | INFO | stop:548 | Application.stop() complete
2022-06-14 10:38:35,432 | apscheduler.scheduler | INFO | start:171 | Scheduler started
2022-06-14 10:38:35,495 | telegram.ext._application | INFO | start:492 | Application started
2022-06-14 10:39:45,651 | apscheduler.scheduler | INFO | start:171 | Scheduler started
2022-06-14 10:39:45,651 | telegram.ext._application | INFO | start:492 | Application started
2022-06-14 10:43:01,333 | apscheduler.scheduler | INFO | start:171 | Scheduler started
2022-06-14 10:43:01,335 | telegram.ext._application | INFO | start:492 | Application started
2022-06-14 10:44:11,649 | apscheduler.scheduler | INFO | start:171 | Scheduler started
2022-06-14 10:44:11,650 | telegram.ext._application | INFO | start:492 | Application started
2022-06-14 11:17:02,980 | apscheduler.scheduler | INFO | start:171 | Scheduler started
2022-06-14 11:17:02,981 | telegram.ext._application | INFO | start:492 | Application started
2022-06-14 11:18:54,028 | apscheduler.scheduler | INFO | start:171 | Scheduler started
2022-06-14 11:18:54,029 | telegram.ext._application | INFO | start:492 | Application started
2022-06-14 11:20:55,813 | apscheduler.scheduler | INFO | start:171 | Scheduler started
2022-06-14 11:20:55,815 | telegram.ext._application | INFO | start:492 | Application started
2022-06-14 11:21:01,378 | apscheduler.scheduler | INFO | start:171 | Scheduler started
2022-06-14 11:21:01,388 | telegram.ext._application | INFO | start:492 | Application started
2022-06-14 11:24:08,209 | apscheduler.scheduler | INFO | start:171 | Scheduler started
2022-06-14 11:24:08,211 | telegram.ext._application | INFO | start:492 | Application started
2022-06-14 11:25:55,386 | apscheduler.scheduler | INFO | start:171 | Scheduler started
2022-06-14 11:25:55,386 | telegram.ext._application | INFO | start:492 | Application started
2022-06-14 11:26:13,019 | apscheduler.scheduler | INFO | start:171 | Scheduler started
2022-06-14 11:26:13,022 | telegram.ext._application | INFO | start:492 | Application started
2022-06-14 11:28:39,636 | apscheduler.scheduler | INFO | start:171 | Scheduler started
2022-06-14 11:28:39,637 | telegram.ext._application | INFO | start:492 | Application started
2022-06-14 11:33:49,309 | apscheduler.scheduler | INFO | start:171 | Scheduler started
2022-06-14 11:33:49,309 | telegram.ext._application | INFO | start:492 | Application started
2022-06-14 11:33:52,159 | apscheduler.scheduler | INFO | start:171 | Scheduler started
2022-06-14 11:33:52,159 | telegram.ext._application | INFO | start:492 | Application started
2022-06-14 11:34:47,782 | apscheduler.scheduler | INFO | start:171 | Scheduler started
2022-06-14 11:34:47,782 | telegram.ext._application | INFO | start:492 | Application started
2022-06-14 11:36:52,664 | apscheduler.scheduler | INFO | start:171 | Scheduler started
2022-06-14 11:36:52,697 | telegram.ext._application | INFO | start:492 | Application started
2022-06-14 11:37:26,612 | apscheduler.scheduler | INFO | start:171 | Scheduler started
2022-06-14 11:37:26,684 | telegram.ext._application | INFO | start:492 | Application started
2022-06-14 11:37:36,388 | apscheduler.scheduler | INFO | start:171 | Scheduler started
2022-06-14 11:37:36,420 | telegram.ext._application | INFO | start:492 | Application started
2022-06-14 11:38:01,789 | apscheduler.scheduler | INFO | start:171 | Scheduler started
2022-06-14 11:38:01,831 | telegram.ext._application | INFO | start:492 | Application started
2022-06-14 11:42:01,569 | apscheduler.scheduler | INFO | start:171 | Scheduler started
2022-06-14 11:42:01,569 | telegram.ext._application | INFO | start:492 | Application started
2022-06-14 11:42:10,361 | apscheduler.scheduler | INFO | start:171 | Scheduler started
2022-06-14 11:42:10,363 | telegram.ext._application | INFO | start:492 | Application started
2022-06-14 11:42:30,630 | apscheduler.scheduler | INFO | start:171 | Scheduler started
2022-06-14 11:42:30,632 | telegram.ext._application | INFO | start:492 | Application started
2022-06-14 11:46:59,337 | apscheduler.scheduler | INFO | start:171 | Scheduler started
2022-06-14 11:46:59,337 | telegram.ext._application | INFO | start:492 | Application started
2022-06-14 11:47:28,497 | apscheduler.scheduler | INFO | start:171 | Scheduler started
2022-06-14 11:47:28,587 | telegram.ext._application | INFO | start:492 | Application started
2022-06-14 11:47:42,563 | apscheduler.scheduler | INFO | start:171 | Scheduler started
2022-06-14 11:47:42,567 | telegram.ext._application | INFO | start:492 | Application started
2022-06-14 11:59:43,576 | apscheduler.scheduler | INFO | start:171 | Scheduler started
2022-06-14 11:59:43,576 | telegram.ext._application | INFO | start:492 | Application started
2022-06-14 12:08:37,958 | telegram.ext._updater | ERROR | _network_loop_retry:569 | Error while getting Updates: httpx HTTPError: [Errno -2] Name or service not known
2022-06-14 12:08:38,965 | telegram.ext._updater | ERROR | _network_loop_retry:569 | Error while getting Updates: httpx HTTPError: [Errno -2] Name or service not known
2022-06-14 12:08:40,475 | telegram.ext._updater | ERROR | _network_loop_retry:569 | Error while getting Updates: httpx HTTPError: [Errno -2] Name or service not known
2022-06-14 12:08:42,734 | telegram.ext._updater | ERROR | _network_loop_retry:569 | Error while getting Updates: httpx HTTPError: [Errno -2] Name or service not known
2022-06-14 12:08:51,125 | telegram.ext._updater | ERROR | _network_loop_retry:569 | Error while getting Updates: httpx HTTPError: [Errno -2] Name or service not known
2022-06-14 12:08:57,136 | telegram.ext._updater | ERROR | _network_loop_retry:569 | Error while getting Updates: httpx HTTPError: [Errno -2] Name or service not known
2022-06-14 12:08:58,143 | telegram.ext._updater | ERROR | _network_loop_retry:569 | Error while getting Updates: httpx HTTPError: [Errno -2] Name or service not known
2022-06-14 12:08:59,649 | telegram.ext._updater | ERROR | _network_loop_retry:569 | Error while getting Updates: httpx HTTPError: [Errno -2] Name or service not known
2022-06-14 12:09:01,908 | telegram.ext._updater | ERROR | _network_loop_retry:569 | Error while getting Updates: httpx HTTPError: [Errno -2] Name or service not known
2022-06-14 12:09:05,289 | telegram.ext._updater | ERROR | _network_loop_retry:569 | Error while getting Updates: httpx HTTPError: [Errno -2] Name or service not known
2022-06-14 12:09:10,360 | telegram.ext._updater | ERROR | _network_loop_retry:569 | Error while getting Updates: httpx HTTPError: [Errno -2] Name or service not known
2022-06-14 12:09:17,965 | telegram.ext._updater | ERROR | _network_loop_retry:569 | Error while getting Updates: httpx HTTPError: [Errno -2] Name or service not known
2022-06-14 12:09:29,373 | telegram.ext._updater | ERROR | _network_loop_retry:569 | Error while getting Updates: httpx HTTPError: [Errno -2] Name or service not known
2022-06-14 12:09:46,465 | telegram.ext._updater | ERROR | _network_loop_retry:569 | Error while getting Updates: httpx HTTPError: [Errno -2] Name or service not known
2022-06-14 12:10:17,128 | telegram.ext._updater | ERROR | _network_loop_retry:569 | Error while getting Updates: httpx HTTPError: [Errno -2] Name or service not known
2022-06-14 12:10:18,136 | telegram.ext._updater | ERROR | _network_loop_retry:569 | Error while getting Updates: httpx HTTPError: [Errno -2] Name or service not known
2022-06-14 12:10:19,643 | telegram.ext._updater | ERROR | _network_loop_retry:569 | Error while getting Updates: httpx HTTPError: [Errno -2] Name or service not known
2022-06-14 12:10:21,899 | telegram.ext._updater | ERROR | _network_loop_retry:569 | Error while getting Updates: httpx HTTPError: [Errno -2] Name or service not known
2022-06-14 12:10:25,282 | telegram.ext._updater | ERROR | _network_loop_retry:569 | Error while getting Updates: httpx HTTPError: [Errno -2] Name or service not known
2022-06-14 12:10:30,354 | telegram.ext._updater | ERROR | _network_loop_retry:569 | Error while getting Updates: httpx HTTPError: [Errno -2] Name or service not known
2022-06-14 12:10:37,959 | telegram.ext._updater | ERROR | _network_loop_retry:569 | Error while getting Updates: httpx HTTPError: [Errno -2] Name or service not known
2022-06-14 12:10:49,359 | telegram.ext._updater | ERROR | _network_loop_retry:569 | Error while getting Updates: httpx HTTPError: [Errno -2] Name or service not known
2022-06-14 12:11:06,467 | telegram.ext._updater | ERROR | _network_loop_retry:569 | Error while getting Updates: httpx HTTPError: [Errno -2] Name or service not known
2022-06-14 12:11:32,125 | telegram.ext._updater | ERROR | _network_loop_retry:569 | Error while getting Updates: httpx HTTPError: [Errno -2] Name or service not known
2022-06-14 12:12:02,147 | telegram.ext._updater | ERROR | _network_loop_retry:569 | Error while getting Updates: httpx HTTPError: [Errno -2] Name or service not known
2022-06-14 12:12:32,176 | telegram.ext._updater | ERROR | _network_loop_retry:569 | Error while getting Updates: httpx HTTPError: [Errno -2] Name or service not known
2022-06-14 12:13:02,199 | telegram.ext._updater | ERROR | _network_loop_retry:569 | Error while getting Updates: httpx HTTPError: [Errno -2] Name or service not known
2022-06-14 12:13:32,236 | telegram.ext._updater | ERROR | _network_loop_retry:569 | Error while getting Updates: httpx HTTPError: [Errno -2] Name or service not known
2022-06-14 12:14:02,259 | telegram.ext._updater | ERROR | _network_loop_retry:569 | Error while getting Updates: httpx HTTPError: [Errno -2] Name or service not known
2022-06-14 12:14:32,295 | telegram.ext._updater | ERROR | _network_loop_retry:569 | Error while getting Updates: httpx HTTPError: [Errno -2] Name or service not known
2022-06-14 12:15:02,318 | telegram.ext._updater | ERROR | _network_loop_retry:569 | Error while getting Updates: httpx HTTPError: [Errno -2] Name or service not known
2022-06-14 12:15:32,349 | telegram.ext._updater | ERROR | _network_loop_retry:569 | Error while getting Updates: httpx HTTPError: [Errno -2] Name or service not known
2022-06-14 12:16:02,370 | telegram.ext._updater | ERROR | _network_loop_retry:569 | Error while getting Updates: httpx HTTPError: [Errno -2] Name or service not known
2022-06-14 12:16:32,400 | telegram.ext._updater | ERROR | _network_loop_retry:569 | Error while getting Updates: httpx HTTPError: [Errno -2] Name or service not known
2022-06-14 12:17:02,422 | telegram.ext._updater | ERROR | _network_loop_retry:569 | Error while getting Updates: httpx HTTPError: [Errno -2] Name or service not known
2022-06-14 12:17:32,457 | telegram.ext._updater | ERROR | _network_loop_retry:569 | Error while getting Updates: httpx HTTPError: [Errno -2] Name or service not known
2022-06-14 12:18:12,492 | telegram.ext._updater | ERROR | _network_loop_retry:569 | Error while getting Updates: httpx HTTPError: [Errno -2] Name or service not known
2022-06-14 12:18:13,501 | telegram.ext._updater | ERROR | _network_loop_retry:569 | Error while getting Updates: httpx HTTPError: [Errno -2] Name or service not known
2022-06-14 12:18:15,005 | telegram.ext._updater | ERROR | _network_loop_retry:569 | Error while getting Updates: httpx HTTPError: [Errno -2] Name or service not known
2022-06-14 12:18:17,261 | telegram.ext._updater | ERROR | _network_loop_retry:569 | Error while getting Updates: httpx HTTPError: [Errno -2] Name or service not known
2022-06-14 12:18:20,640 | telegram.ext._updater | ERROR | _network_loop_retry:569 | Error while getting Updates: httpx HTTPError: [Errno -2] Name or service not known
2022-06-14 12:18:25,713 | telegram.ext._updater | ERROR | _network_loop_retry:569 | Error while getting Updates: httpx HTTPError: [Errno -2] Name or service not known
2022-06-14 12:18:33,317 | telegram.ext._updater | ERROR | _network_loop_retry:569 | Error while getting Updates: httpx HTTPError: [Errno -2] Name or service not known
2022-06-14 12:18:44,714 | telegram.ext._updater | ERROR | _network_loop_retry:569 | Error while getting Updates: httpx HTTPError: [Errno -2] Name or service not known
2022-06-14 12:19:01,822 | telegram.ext._updater | ERROR | _network_loop_retry:569 | Error while getting Updates: httpx HTTPError: [Errno -2] Name or service not known
2022-06-14 12:19:32,484 | telegram.ext._updater | ERROR | _network_loop_retry:569 | Error while getting Updates: httpx HTTPError: [Errno -2] Name or service not known
2022-06-14 12:19:33,491 | telegram.ext._updater | ERROR | _network_loop_retry:569 | Error while getting Updates: httpx HTTPError: [Errno -2] Name or service not known
2022-06-14 12:19:34,996 | telegram.ext._updater | ERROR | _network_loop_retry:569 | Error while getting Updates: httpx HTTPError: [Errno -2] Name or service not known
2022-06-14 12:19:37,252 | telegram.ext._updater | ERROR | _network_loop_retry:569 | Error while getting Updates: httpx HTTPError: [Errno -2] Name or service not known
2022-06-14 12:19:40,633 | telegram.ext._updater | ERROR | _network_loop_retry:569 | Error while getting Updates: httpx HTTPError: [Errno -2] Name or service not known
2022-06-14 12:19:45,700 | telegram.ext._updater | ERROR | _network_loop_retry:569 | Error while getting Updates: httpx HTTPError: [Errno -2] Name or service not known
2022-06-14 12:19:53,305 | telegram.ext._updater | ERROR | _network_loop_retry:569 | Error while getting Updates: httpx HTTPError: [Errno -2] Name or service not known
2022-06-14 12:20:04,710 | telegram.ext._updater | ERROR | _network_loop_retry:569 | Error while getting Updates: httpx HTTPError: [Errno -2] Name or service not known
2022-06-14 12:20:21,817 | telegram.ext._updater | ERROR | _network_loop_retry:569 | Error while getting Updates: httpx HTTPError: [Errno -2] Name or service not known
2022-06-14 12:20:47,454 | telegram.ext._updater | ERROR | _network_loop_retry:569 | Error while getting Updates: httpx HTTPError: [Errno -2] Name or service not known
2022-06-14 12:21:17,489 | telegram.ext._updater | ERROR | _network_loop_retry:569 | Error while getting Updates: httpx HTTPError: [Errno -2] Name or service not known
2022-06-14 12:21:47,496 | telegram.ext._updater | ERROR | _network_loop_retry:569 | Error while getting Updates: httpx HTTPError: [Errno -2] Name or service not known
2022-06-14 12:22:17,537 | telegram.ext._updater | ERROR | _network_loop_retry:569 | Error while getting Updates: httpx HTTPError: [Errno -2] Name or service not known
2022-06-14 12:22:47,545 | telegram.ext._updater | ERROR | _network_loop_retry:569 | Error while getting Updates: httpx HTTPError: [Errno -2] Name or service not known
2022-06-14 12:23:17,582 | telegram.ext._updater | ERROR | _network_loop_retry:569 | Error while getting Updates: httpx HTTPError: [Errno -2] Name or service not known
2022-06-14 12:23:47,591 | telegram.ext._updater | ERROR | _network_loop_retry:569 | Error while getting Updates: httpx HTTPError: [Errno -2] Name or service not known
2022-06-14 12:24:17,625 | telegram.ext._updater | ERROR | _network_loop_retry:569 | Error while getting Updates: httpx HTTPError: [Errno -2] Name or service not known
2022-06-14 12:24:47,631 | telegram.ext._updater | ERROR | _network_loop_retry:569 | Error while getting Updates: httpx HTTPError: [Errno -2] Name or service not known
2022-06-14 12:25:17,665 | telegram.ext._updater | ERROR | _network_loop_retry:569 | Error while getting Updates: httpx HTTPError: [Errno -2] Name or service not known
2022-06-14 12:25:47,675 | telegram.ext._updater | ERROR | _network_loop_retry:569 | Error while getting Updates: httpx HTTPError: [Errno -2] Name or service not known
2022-06-14 12:26:17,712 | telegram.ext._updater | ERROR | _network_loop_retry:569 | Error while getting Updates: httpx HTTPError: [Errno -2] Name or service not known
2022-06-14 12:26:47,720 | telegram.ext._updater | ERROR | _network_loop_retry:569 | Error while getting Updates: httpx HTTPError: [Errno -2] Name or service not known
2022-06-14 12:27:27,767 | telegram.ext._updater | ERROR | _network_loop_retry:569 | Error while getting Updates: httpx HTTPError: [Errno -2] Name or service not known
2022-06-14 12:27:28,774 | telegram.ext._updater | ERROR | _network_loop_retry:569 | Error while getting Updates: httpx HTTPError: [Errno -2] Name or service not known
2022-06-14 12:27:30,282 | telegram.ext._updater | ERROR | _network_loop_retry:569 | Error while getting Updates: httpx HTTPError: [Errno -2] Name or service not known
2022-06-14 12:27:32,539 | telegram.ext._updater | ERROR | _network_loop_retry:569 | Error while getting Updates: httpx HTTPError: [Errno -2] Name or service not known
2022-06-14 12:27:35,924 | telegram.ext._updater | ERROR | _network_loop_retry:569 | Error while getting Updates: httpx HTTPError: [Errno -2] Name or service not known
2022-06-14 12:27:40,995 | telegram.ext._updater | ERROR | _network_loop_retry:569 | Error while getting Updates: httpx HTTPError: [Errno -2] Name or service not known
2022-06-14 12:27:48,600 | telegram.ext._updater | ERROR | _network_loop_retry:569 | Error while getting Updates: httpx HTTPError: [Errno -2] Name or service not known
2022-06-14 12:28:00,010 | telegram.ext._updater | ERROR | _network_loop_retry:569 | Error while getting Updates: httpx HTTPError: [Errno -2] Name or service not known
2022-06-14 12:28:17,120 | telegram.ext._updater | ERROR | _network_loop_retry:569 | Error while getting Updates: httpx HTTPError: [Errno -2] Name or service not known
2022-06-14 12:28:47,785 | telegram.ext._updater | ERROR | _network_loop_retry:569 | Error while getting Updates: httpx HTTPError: [Errno -2] Name or service not known
2022-06-14 12:28:48,793 | telegram.ext._updater | ERROR | _network_loop_retry:569 | Error while getting Updates: httpx HTTPError: [Errno -2] Name or service not known
2022-06-14 12:28:50,300 | telegram.ext._updater | ERROR | _network_loop_retry:569 | Error while getting Updates: httpx HTTPError: [Errno -2] Name or service not known
2022-06-14 12:28:52,560 | telegram.ext._updater | ERROR | _network_loop_retry:569 | Error while getting Updates: httpx HTTPError: [Errno -2] Name or service not known
2022-06-14 12:28:55,944 | telegram.ext._updater | ERROR | _network_loop_retry:569 | Error while getting Updates: httpx HTTPError: [Errno -2] Name or service not known
2022-06-14 12:29:01,013 | telegram.ext._updater | ERROR | _network_loop_retry:569 | Error while getting Updates: httpx HTTPError: [Errno -2] Name or service not known
2022-06-14 12:29:08,620 | telegram.ext._updater | ERROR | _network_loop_retry:569 | Error while getting Updates: httpx HTTPError: [Errno -2] Name or service not known
2022-06-14 12:29:20,025 | telegram.ext._updater | ERROR | _network_loop_retry:569 | Error while getting Updates: httpx HTTPError: [Errno -2] Name or service not known
2022-06-14 12:29:37,131 | telegram.ext._updater | ERROR | _network_loop_retry:569 | Error while getting Updates: httpx HTTPError: [Errno -2] Name or service not known
2022-06-14 12:30:02,783 | telegram.ext._updater | ERROR | _network_loop_retry:569 | Error while getting Updates: httpx HTTPError: [Errno -2] Name or service not known
2022-06-14 12:30:32,814 | telegram.ext._updater | ERROR | _network_loop_retry:569 | Error while getting Updates: httpx HTTPError: [Errno -2] Name or service not known
2022-06-14 12:31:02,834 | telegram.ext._updater | ERROR | _network_loop_retry:569 | Error while getting Updates: httpx HTTPError: [Errno -2] Name or service not known
2022-06-14 12:31:32,868 | telegram.ext._updater | ERROR | _network_loop_retry:569 | Error while getting Updates: httpx HTTPError: [Errno -2] Name or service not known
2022-06-14 12:32:02,891 | telegram.ext._updater | ERROR | _network_loop_retry:569 | Error while getting Updates: httpx HTTPError: [Errno -2] Name or service not known
2022-06-14 12:32:32,923 | telegram.ext._updater | ERROR | _network_loop_retry:569 | Error while getting Updates: httpx HTTPError: [Errno -2] Name or service not known
2022-06-14 12:33:02,947 | telegram.ext._updater | ERROR | _network_loop_retry:569 | Error while getting Updates: httpx HTTPError: [Errno -2] Name or service not known
2022-06-14 12:33:32,983 | telegram.ext._updater | ERROR | _network_loop_retry:569 | Error while getting Updates: httpx HTTPError: [Errno -2] Name or service not known
2022-06-14 12:34:03,007 | telegram.ext._updater | ERROR | _network_loop_retry:569 | Error while getting Updates: httpx HTTPError: [Errno -2] Name or service not known
2022-06-14 12:34:33,041 | telegram.ext._updater | ERROR | _network_loop_retry:569 | Error while getting Updates: httpx HTTPError: [Errno -2] Name or service not known
2022-06-14 12:35:03,061 | telegram.ext._updater | ERROR | _network_loop_retry:569 | Error while getting Updates: httpx HTTPError: [Errno -2] Name or service not known
2022-06-14 12:35:33,095 | telegram.ext._updater | ERROR | _network_loop_retry:569 | Error while getting Updates: httpx HTTPError: [Errno -2] Name or service not known
2022-06-14 12:36:03,120 | telegram.ext._updater | ERROR | _network_loop_retry:569 | Error while getting Updates: httpx HTTPError: [Errno -2] Name or service not known
2022-06-14 12:36:43,170 | telegram.ext._updater | ERROR | _network_loop_retry:569 | Error while getting Updates: httpx HTTPError: [Errno -2] Name or service not known
2022-06-14 12:36:44,176 | telegram.ext._updater | ERROR | _network_loop_retry:569 | Error while getting Updates: httpx HTTPError: [Errno -2] Name or service not known
2022-06-14 12:36:45,683 | telegram.ext._updater | ERROR | _network_loop_retry:569 | Error while getting Updates: httpx HTTPError: [Errno -2] Name or service not known
2022-06-14 12:36:47,939 | telegram.ext._updater | ERROR | _network_loop_retry:569 | Error while getting Updates: httpx HTTPError: [Errno -2] Name or service not known
2022-06-14 12:36:51,321 | telegram.ext._updater | ERROR | _network_loop_retry:569 | Error while getting Updates: httpx HTTPError: [Errno -2] Name or service not known
2022-06-14 12:36:56,393 | telegram.ext._updater | ERROR | _network_loop_retry:569 | Error while getting Updates: httpx HTTPError: [Errno -2] Name or service not known
2022-06-14 12:37:04,000 | telegram.ext._updater | ERROR | _network_loop_retry:569 | Error while getting Updates: httpx HTTPError: [Errno -2] Name or service not known
2022-06-14 12:37:15,407 | telegram.ext._updater | ERROR | _network_loop_retry:569 | Error while getting Updates: httpx HTTPError: [Errno -2] Name or service not known
2022-06-14 12:37:32,516 | telegram.ext._updater | ERROR | _network_loop_retry:569 | Error while getting Updates: httpx HTTPError: [Errno -2] Name or service not known
2022-06-14 12:38:03,171 | telegram.ext._updater | ERROR | _network_loop_retry:569 | Error while getting Updates: httpx HTTPError: [Errno -2] Name or service not known
2022-06-14 12:38:04,178 | telegram.ext._updater | ERROR | _network_loop_retry:569 | Error while getting Updates: httpx HTTPError: [Errno -2] Name or service not known
2022-06-14 12:38:05,684 | telegram.ext._updater | ERROR | _network_loop_retry:569 | Error while getting Updates: httpx HTTPError: [Errno -2] Name or service not known
2022-06-14 12:38:07,943 | telegram.ext._updater | ERROR | _network_loop_retry:569 | Error while getting Updates: httpx HTTPError: [Errno -2] Name or service not known
2022-06-14 12:38:11,324 | telegram.ext._updater | ERROR | _network_loop_retry:569 | Error while getting Updates: httpx HTTPError: [Errno -2] Name or service not known
2022-06-14 12:38:16,393 | telegram.ext._updater | ERROR | _network_loop_retry:569 | Error while getting Updates: httpx HTTPError: [Errno -2] Name or service not known
2022-06-14 12:38:24,000 | telegram.ext._updater | ERROR | _network_loop_retry:569 | Error while getting Updates: httpx HTTPError: [Errno -2] Name or service not known
2022-06-14 12:38:35,399 | telegram.ext._updater | ERROR | _network_loop_retry:569 | Error while getting Updates: httpx HTTPError: [Errno -2] Name or service not known
2022-06-14 12:38:52,499 | telegram.ext._updater | ERROR | _network_loop_retry:569 | Error while getting Updates: httpx HTTPError: [Errno -2] Name or service not known
2022-06-14 12:39:18,159 | telegram.ext._updater | ERROR | _network_loop_retry:569 | Error while getting Updates: httpx HTTPError: [Errno -2] Name or service not known
2022-06-14 12:39:48,170 | telegram.ext._updater | ERROR | _network_loop_retry:569 | Error while getting Updates: httpx HTTPError: [Errno -2] Name or service not known
2022-06-14 12:40:18,198 | telegram.ext._updater | ERROR | _network_loop_retry:569 | Error while getting Updates: httpx HTTPError: [Errno -2] Name or service not known
2022-06-14 12:40:48,207 | telegram.ext._updater | ERROR | _network_loop_retry:569 | Error while getting Updates: httpx HTTPError: [Errno -2] Name or service not known
2022-06-14 12:41:18,240 | telegram.ext._updater | ERROR | _network_loop_retry:569 | Error while getting Updates: httpx HTTPError: [Errno -2] Name or service not known
2022-06-14 12:41:48,247 | telegram.ext._updater | ERROR | _network_loop_retry:569 | Error while getting Updates: httpx HTTPError: [Errno -2] Name or service not known
2022-06-14 12:42:18,279 | telegram.ext._updater | ERROR | _network_loop_retry:569 | Error while getting Updates: httpx HTTPError: [Errno -2] Name or service not known
2022-06-14 12:42:48,287 | telegram.ext._updater | ERROR | _network_loop_retry:569 | Error while getting Updates: httpx HTTPError: [Errno -2] Name or service not known
2022-06-14 12:43:18,321 | telegram.ext._updater | ERROR | _network_loop_retry:569 | Error while getting Updates: httpx HTTPError: [Errno -2] Name or service not known
2022-06-14 12:43:48,331 | telegram.ext._updater | ERROR | _network_loop_retry:569 | Error while getting Updates: httpx HTTPError: [Errno -2] Name or service not known
2022-06-14 12:44:18,363 | telegram.ext._updater | ERROR | _network_loop_retry:569 | Error while getting Updates: httpx HTTPError: [Errno -2] Name or service not known
2022-06-14 12:44:48,372 | telegram.ext._updater | ERROR | _network_loop_retry:569 | Error while getting Updates: httpx HTTPError: [Errno -2] Name or service not known
2022-06-14 12:45:18,405 | telegram.ext._updater | ERROR | _network_loop_retry:569 | Error while getting Updates: httpx HTTPError: [Errno -2] Name or service not known
2022-06-14 12:45:58,430 | telegram.ext._updater | ERROR | _network_loop_retry:569 | Error while getting Updates: httpx HTTPError: [Errno -2] Name or service not known
2022-06-14 12:45:59,436 | telegram.ext._updater | ERROR | _network_loop_retry:569 | Error while getting Updates: httpx HTTPError: [Errno -2] Name or service not known
2022-06-14 12:46:00,943 | telegram.ext._updater | ERROR | _network_loop_retry:569 | Error while getting Updates: httpx HTTPError: [Errno -2] Name or service not known
2022-06-14 12:46:03,202 | telegram.ext._updater | ERROR | _network_loop_retry:569 | Error while getting Updates: httpx HTTPError: [Errno -2] Name or service not known
2022-06-14 12:46:06,588 | telegram.ext._updater | ERROR | _network_loop_retry:569 | Error while getting Updates: httpx HTTPError: [Errno -2] Name or service not known
2022-06-14 12:46:11,659 | telegram.ext._updater | ERROR | _network_loop_retry:569 | Error while getting Updates: httpx HTTPError: [Errno -2] Name or service not known
2022-06-14 12:46:19,263 | telegram.ext._updater | ERROR | _network_loop_retry:569 | Error while getting Updates: httpx HTTPError: [Errno -2] Name or service not known
2022-06-14 12:46:30,671 | telegram.ext._updater | ERROR | _network_loop_retry:569 | Error while getting Updates: httpx HTTPError: [Errno -2] Name or service not known
2022-06-14 12:46:47,767 | telegram.ext._updater | ERROR | _network_loop_retry:569 | Error while getting Updates: httpx HTTPError: [Errno -2] Name or service not known
2022-06-14 12:47:18,436 | telegram.ext._updater | ERROR | _network_loop_retry:569 | Error while getting Updates: httpx HTTPError: [Errno -2] Name or service not known
2022-06-14 12:47:19,443 | telegram.ext._updater | ERROR | _network_loop_retry:569 | Error while getting Updates: httpx HTTPError: [Errno -2] Name or service not known
2022-06-14 12:47:20,951 | telegram.ext._updater | ERROR | _network_loop_retry:569 | Error while getting Updates: httpx HTTPError: [Errno -2] Name or service not known
2022-06-14 12:47:23,208 | telegram.ext._updater | ERROR | _network_loop_retry:569 | Error while getting Updates: httpx HTTPError: [Errno -2] Name or service not known
2022-06-14 12:47:26,591 | telegram.ext._updater | ERROR | _network_loop_retry:569 | Error while getting Updates: httpx HTTPError: [Errno -2] Name or service not known
2022-06-14 12:47:31,663 | telegram.ext._updater | ERROR | _network_loop_retry:569 | Error while getting Updates: httpx HTTPError: [Errno -2] Name or service not known
2022-06-14 12:47:39,269 | telegram.ext._updater | ERROR | _network_loop_retry:569 | Error while getting Updates: httpx HTTPError: [Errno -2] Name or service not known
2022-06-14 12:47:50,671 | telegram.ext._updater | ERROR | _network_loop_retry:569 | Error while getting Updates: httpx HTTPError: [Errno -2] Name or service not known
2022-06-14 12:48:07,779 | telegram.ext._updater | ERROR | _network_loop_retry:569 | Error while getting Updates: httpx HTTPError: [Errno -2] Name or service not known
2022-06-14 12:48:33,440 | telegram.ext._updater | ERROR | _network_loop_retry:569 | Error while getting Updates: httpx HTTPError: [Errno -2] Name or service not known
2022-06-14 12:49:03,464 | telegram.ext._updater | ERROR | _network_loop_retry:569 | Error while getting Updates: httpx HTTPError: [Errno -2] Name or service not known
2022-06-14 12:49:33,499 | telegram.ext._updater | ERROR | _network_loop_retry:569 | Error while getting Updates: httpx HTTPError: [Errno -2] Name or service not known
2022-06-14 12:50:03,524 | telegram.ext._updater | ERROR | _network_loop_retry:569 | Error while getting Updates: httpx HTTPError: [Errno -2] Name or service not known
2022-06-14 12:50:33,558 | telegram.ext._updater | ERROR | _network_loop_retry:569 | Error while getting Updates: httpx HTTPError: [Errno -2] Name or service not known
2022-06-14 12:51:03,581 | telegram.ext._updater | ERROR | _network_loop_retry:569 | Error while getting Updates: httpx HTTPError: [Errno -2] Name or service not known
2022-06-14 12:51:33,612 | telegram.ext._updater | ERROR | _network_loop_retry:569 | Error while getting Updates: httpx HTTPError: [Errno -2] Name or service not known
2022-06-14 12:52:03,635 | telegram.ext._updater | ERROR | _network_loop_retry:569 | Error while getting Updates: httpx HTTPError: [Errno -2] Name or service not known
2022-06-14 12:52:33,668 | telegram.ext._updater | ERROR | _network_loop_retry:569 | Error while getting Updates: httpx HTTPError: [Errno -2] Name or service not known
2022-06-14 12:53:03,690 | telegram.ext._updater | ERROR | _network_loop_retry:569 | Error while getting Updates: httpx HTTPError: [Errno -2] Name or service not known
2022-06-14 12:53:33,726 | telegram.ext._updater | ERROR | _network_loop_retry:569 | Error while getting Updates: httpx HTTPError: [Errno -2] Name or service not known
2022-06-14 12:54:03,751 | telegram.ext._updater | ERROR | _network_loop_retry:569 | Error while getting Updates: httpx HTTPError: [Errno -2] Name or service not known
2022-06-14 12:54:33,793 | telegram.ext._updater | ERROR | _network_loop_retry:569 | Error while getting Updates: httpx HTTPError: [Errno -2] Name or service not known
2022-06-14 12:55:18,838 | telegram.ext._updater | ERROR | _network_loop_retry:569 | Error while getting Updates: httpx HTTPError: [Errno -2] Name or service not known
2022-06-14 12:55:19,842 | telegram.ext._updater | ERROR | _network_loop_retry:569 | Error while getting Updates: httpx HTTPError: [Errno -2] Name or service not known
2022-06-14 12:55:21,347 | telegram.ext._updater | ERROR | _network_loop_retry:569 | Error while getting Updates: httpx HTTPError: [Errno -2] Name or service not known
2022-06-14 12:55:23,604 | telegram.ext._updater | ERROR | _network_loop_retry:569 | Error while getting Updates: httpx HTTPError: [Errno -2] Name or service not known
2022-06-14 12:55:26,988 | telegram.ext._updater | ERROR | _network_loop_retry:569 | Error while getting Updates: httpx HTTPError: [Errno -2] Name or service not known
2022-06-14 12:55:32,058 | telegram.ext._updater | ERROR | _network_loop_retry:569 | Error while getting Updates: httpx HTTPError: [Errno -2] Name or service not known
2022-06-14 12:55:39,663 | telegram.ext._updater | ERROR | _network_loop_retry:569 | Error while getting Updates: httpx HTTPError: [Errno -2] Name or service not known
2022-06-14 12:55:51,064 | telegram.ext._updater | ERROR | _network_loop_retry:569 | Error while getting Updates: httpx HTTPError: [Errno -2] Name or service not known
2022-06-14 12:56:08,170 | telegram.ext._updater | ERROR | _network_loop_retry:569 | Error while getting Updates: httpx HTTPError: [Errno -2] Name or service not known
2022-06-14 12:56:38,832 | telegram.ext._updater | ERROR | _network_loop_retry:569 | Error while getting Updates: httpx HTTPError: [Errno -2] Name or service not known
2022-06-14 12:56:39,840 | telegram.ext._updater | ERROR | _network_loop_retry:569 | Error while getting Updates: httpx HTTPError: [Errno -2] Name or service not known
2022-06-14 12:56:41,347 | telegram.ext._updater | ERROR | _network_loop_retry:569 | Error while getting Updates: httpx HTTPError: [Errno -2] Name or service not known
2022-06-14 12:56:43,610 | telegram.ext._updater | ERROR | _network_loop_retry:569 | Error while getting Updates: httpx HTTPError: [Errno -2] Name or service not known
2022-06-14 12:56:46,994 | telegram.ext._updater | ERROR | _network_loop_retry:569 | Error while getting Updates: httpx HTTPError: [Errno -2] Name or service not known
2022-06-14 12:56:52,069 | telegram.ext._updater | ERROR | _network_loop_retry:569 | Error while getting Updates: httpx HTTPError: [Errno -2] Name or service not known
2022-06-14 12:56:59,677 | telegram.ext._updater | ERROR | _network_loop_retry:569 | Error while getting Updates: httpx HTTPError: [Errno -2] Name or service not known
2022-06-14 12:57:11,082 | telegram.ext._updater | ERROR | _network_loop_retry:569 | Error while getting Updates: httpx HTTPError: [Errno -2] Name or service not known
2022-06-14 12:57:28,189 | telegram.ext._updater | ERROR | _network_loop_retry:569 | Error while getting Updates: httpx HTTPError: [Errno -2] Name or service not known
2022-06-14 12:57:53,828 | telegram.ext._updater | ERROR | _network_loop_retry:569 | Error while getting Updates: httpx HTTPError: [Errno -2] Name or service not known
2022-06-14 12:58:23,867 | telegram.ext._updater | ERROR | _network_loop_retry:569 | Error while getting Updates: httpx HTTPError: [Errno -2] Name or service not known
2022-06-14 12:58:53,882 | telegram.ext._updater | ERROR | _network_loop_retry:569 | Error while getting Updates: httpx HTTPError: [Errno -2] Name or service not known
2022-06-14 12:59:23,913 | telegram.ext._updater | ERROR | _network_loop_retry:569 | Error while getting Updates: httpx HTTPError: [Errno -2] Name or service not known
2022-06-14 12:59:53,928 | telegram.ext._updater | ERROR | _network_loop_retry:569 | Error while getting Updates: httpx HTTPError: [Errno -2] Name or service not known
2022-06-14 13:00:23,961 | telegram.ext._updater | ERROR | _network_loop_retry:569 | Error while getting Updates: httpx HTTPError: [Errno -2] Name or service not known
2022-06-14 13:00:53,974 | telegram.ext._updater | ERROR | _network_loop_retry:569 | Error while getting Updates: httpx HTTPError: [Errno -2] Name or service not known
2022-06-14 13:01:24,012 | telegram.ext._updater | ERROR | _network_loop_retry:569 | Error while getting Updates: httpx HTTPError: [Errno -2] Name or service not known
2022-06-14 13:01:54,028 | telegram.ext._updater | ERROR | _network_loop_retry:569 | Error while getting Updates: httpx HTTPError: [Errno -2] Name or service not known
2022-06-14 13:02:24,061 | telegram.ext._updater | ERROR | _network_loop_retry:569 | Error while getting Updates: httpx HTTPError: [Errno -2] Name or service not known
2022-06-14 13:02:54,080 | telegram.ext._updater | ERROR | _network_loop_retry:569 | Error while getting Updates: httpx HTTPError: [Errno -2] Name or service not known
2022-06-14 13:03:24,113 | telegram.ext._updater | ERROR | _network_loop_retry:569 | Error while getting Updates: httpx HTTPError: [Errno -2] Name or service not known
2022-06-14 13:03:54,126 | telegram.ext._updater | ERROR | _network_loop_retry:569 | Error while getting Updates: httpx HTTPError: [Errno -2] Name or service not known
2022-06-14 13:04:34,172 | telegram.ext._updater | ERROR | _network_loop_retry:569 | Error while getting Updates: httpx HTTPError: [Errno -2] Name or service not known
2022-06-14 13:04:35,178 | telegram.ext._updater | ERROR | _network_loop_retry:569 | Error while getting Updates: httpx HTTPError: [Errno -2] Name or service not known
2022-06-14 13:04:36,683 | telegram.ext._updater | ERROR | _network_loop_retry:569 | Error while getting Updates: httpx HTTPError: [Errno -2] Name or service not known
2022-06-14 13:04:38,939 | telegram.ext._updater | ERROR | _network_loop_retry:569 | Error while getting Updates: httpx HTTPError: [Errno -2] Name or service not known
2022-06-14 13:04:42,325 | telegram.ext._updater | ERROR | _network_loop_retry:569 | Error while getting Updates: httpx HTTPError: [Errno -2] Name or service not known
2022-06-14 13:04:47,395 | telegram.ext._updater | ERROR | _network_loop_retry:569 | Error while getting Updates: httpx HTTPError: [Errno -2] Name or service not known
2022-06-14 13:04:55,002 | telegram.ext._updater | ERROR | _network_loop_retry:569 | Error while getting Updates: httpx HTTPError: [Errno -2] Name or service not known
2022-06-14 13:05:06,410 | telegram.ext._updater | ERROR | _network_loop_retry:569 | Error while getting Updates: httpx HTTPError: [Errno -2] Name or service not known
2022-06-14 13:05:23,516 | telegram.ext._updater | ERROR | _network_loop_retry:569 | Error while getting Updates: httpx HTTPError: [Errno -2] Name or service not known
2022-06-14 13:05:54,162 | telegram.ext._updater | ERROR | _network_loop_retry:569 | Error while getting Updates: httpx HTTPError: [Errno -2] Name or service not known
2022-06-14 13:05:55,168 | telegram.ext._updater | ERROR | _network_loop_retry:569 | Error while getting Updates: httpx HTTPError: [Errno -2] Name or service not known
2022-06-14 13:05:56,673 | telegram.ext._updater | ERROR | _network_loop_retry:569 | Error while getting Updates: httpx HTTPError: [Errno -2] Name or service not known
2022-06-14 13:05:58,930 | telegram.ext._updater | ERROR | _network_loop_retry:569 | Error while getting Updates: httpx HTTPError: [Errno -2] Name or service not known
2022-06-14 13:06:02,313 | telegram.ext._updater | ERROR | _network_loop_retry:569 | Error while getting Updates: httpx HTTPError: [Errno -2] Name or service not known
2022-06-14 13:06:07,382 | telegram.ext._updater | ERROR | _network_loop_retry:569 | Error while getting Updates: httpx HTTPError: [Errno -2] Name or service not known
2022-06-14 13:06:14,987 | telegram.ext._updater | ERROR | _network_loop_retry:569 | Error while getting Updates: httpx HTTPError: [Errno -2] Name or service not known
2022-06-14 13:06:26,394 | telegram.ext._updater | ERROR | _network_loop_retry:569 | Error while getting Updates: httpx HTTPError: [Errno -2] Name or service not known
2022-06-14 13:06:43,506 | telegram.ext._updater | ERROR | _network_loop_retry:569 | Error while getting Updates: httpx HTTPError: [Errno -2] Name or service not known
2022-06-14 13:07:09,161 | telegram.ext._updater | ERROR | _network_loop_retry:569 | Error while getting Updates: httpx HTTPError: [Errno -2] Name or service not known
2022-06-14 13:07:39,200 | telegram.ext._updater | ERROR | _network_loop_retry:569 | Error while getting Updates: httpx HTTPError: [Errno -2] Name or service not known
2022-06-14 13:08:09,227 | telegram.ext._updater | ERROR | _network_loop_retry:569 | Error while getting Updates: httpx HTTPError: [Errno -2] Name or service not known
2022-06-14 13:08:39,265 | telegram.ext._updater | ERROR | _network_loop_retry:569 | Error while getting Updates: httpx HTTPError: [Errno -2] Name or service not known
2022-06-14 13:09:09,301 | telegram.ext._updater | ERROR | _network_loop_retry:569 | Error while getting Updates: httpx HTTPError: [Errno -2] Name or service not known
2022-06-14 13:09:39,334 | telegram.ext._updater | ERROR | _network_loop_retry:569 | Error while getting Updates: httpx HTTPError: [Errno -2] Name or service not known
2022-06-14 13:10:09,365 | telegram.ext._updater | ERROR | _network_loop_retry:569 | Error while getting Updates: httpx HTTPError: [Errno -2] Name or service not known
2022-06-14 13:10:39,403 | telegram.ext._updater | ERROR | _network_loop_retry:569 | Error while getting Updates: httpx HTTPError: [Errno -2] Name or service not known
2022-06-14 13:11:09,437 | telegram.ext._updater | ERROR | _network_loop_retry:569 | Error while getting Updates: httpx HTTPError: [Errno -2] Name or service not known
2022-06-14 13:11:39,470 | telegram.ext._updater | ERROR | _network_loop_retry:569 | Error while getting Updates: httpx HTTPError: [Errno -2] Name or service not known
2022-06-14 13:12:09,503 | telegram.ext._updater | ERROR | _network_loop_retry:569 | Error while getting Updates: httpx HTTPError: [Errno -2] Name or service not known
2022-06-14 13:12:39,539 | telegram.ext._updater | ERROR | _network_loop_retry:569 | Error while getting Updates: httpx HTTPError: [Errno -2] Name or service not known
2022-06-14 13:13:09,568 | telegram.ext._updater | ERROR | _network_loop_retry:569 | Error while getting Updates: httpx HTTPError: [Errno -2] Name or service not known
2022-06-14 13:13:49,614 | telegram.ext._updater | ERROR | _network_loop_retry:569 | Error while getting Updates: httpx HTTPError: [Errno -2] Name or service not known
2022-06-14 13:13:50,621 | telegram.ext._updater | ERROR | _network_loop_retry:569 | Error while getting Updates: httpx HTTPError: [Errno -2] Name or service not known
2022-06-14 13:13:52,125 | telegram.ext._updater | ERROR | _network_loop_retry:569 | Error while getting Updates: httpx HTTPError: [Errno -2] Name or service not known
2022-06-14 13:13:54,386 | telegram.ext._updater | ERROR | _network_loop_retry:569 | Error while getting Updates: httpx HTTPError: [Errno -2] Name or service not known
2022-06-14 13:13:57,766 | telegram.ext._updater | ERROR | _network_loop_retry:569 | Error while getting Updates: httpx HTTPError: [Errno -2] Name or service not known
2022-06-14 13:14:02,838 | telegram.ext._updater | ERROR | _network_loop_retry:569 | Error while getting Updates: httpx HTTPError: [Errno -2] Name or service not known
2022-06-14 13:14:10,442 | telegram.ext._updater | ERROR | _network_loop_retry:569 | Error while getting Updates: httpx HTTPError: [Errno -2] Name or service not known
2022-06-14 13:14:21,853 | telegram.ext._updater | ERROR | _network_loop_retry:569 | Error while getting Updates: httpx HTTPError: [Errno -2] Name or service not known
2022-06-14 13:14:38,960 | telegram.ext._updater | ERROR | _network_loop_retry:569 | Error while getting Updates: httpx HTTPError: [Errno -2] Name or service not known
2022-06-14 13:15:09,620 | telegram.ext._updater | ERROR | _network_loop_retry:569 | Error while getting Updates: httpx HTTPError: [Errno -2] Name or service not known
2022-06-14 13:15:10,626 | telegram.ext._updater | ERROR | _network_loop_retry:569 | Error while getting Updates: httpx HTTPError: [Errno -2] Name or service not known
2022-06-14 13:15:12,136 | telegram.ext._updater | ERROR | _network_loop_retry:569 | Error while getting Updates: httpx HTTPError: [Errno -2] Name or service not known
2022-06-14 13:15:14,389 | telegram.ext._updater | ERROR | _network_loop_retry:569 | Error while getting Updates: httpx HTTPError: [Errno -2] Name or service not known
2022-06-14 13:15:17,777 | telegram.ext._updater | ERROR | _network_loop_retry:569 | Error while getting Updates: httpx HTTPError: [Errno -2] Name or service not known
2022-06-14 13:15:22,847 | telegram.ext._updater | ERROR | _network_loop_retry:569 | Error while getting Updates: httpx HTTPError: [Errno -2] Name or service not known
2022-06-14 13:15:30,454 | telegram.ext._updater | ERROR | _network_loop_retry:569 | Error while getting Updates: httpx HTTPError: [Errno -2] Name or service not known
2022-06-14 13:15:41,857 | telegram.ext._updater | ERROR | _network_loop_retry:569 | Error while getting Updates: httpx HTTPError: [Errno -2] Name or service not known
2022-06-14 13:15:58,956 | telegram.ext._updater | ERROR | _network_loop_retry:569 | Error while getting Updates: httpx HTTPError: [Errno -2] Name or service not known
2022-06-14 13:16:24,615 | telegram.ext._updater | ERROR | _network_loop_retry:569 | Error while getting Updates: httpx HTTPError: [Errno -2] Name or service not known
2022-06-14 13:16:54,630 | telegram.ext._updater | ERROR | _network_loop_retry:569 | Error while getting Updates: httpx HTTPError: [Errno -2] Name or service not known
2022-06-14 13:17:24,665 | telegram.ext._updater | ERROR | _network_loop_retry:569 | Error while getting Updates: httpx HTTPError: [Errno -2] Name or service not known
2022-06-14 13:17:54,679 | telegram.ext._updater | ERROR | _network_loop_retry:569 | Error while getting Updates: httpx HTTPError: [Errno -2] Name or service not known
2022-06-14 13:18:24,713 | telegram.ext._updater | ERROR | _network_loop_retry:569 | Error while getting Updates: httpx HTTPError: [Errno -2] Name or service not known
2022-06-14 13:18:54,726 | telegram.ext._updater | ERROR | _network_loop_retry:569 | Error while getting Updates: httpx HTTPError: [Errno -2] Name or service not known
2022-06-14 13:19:24,763 | telegram.ext._updater | ERROR | _network_loop_retry:569 | Error while getting Updates: httpx HTTPError: [Errno -2] Name or service not known
2022-06-14 13:19:54,775 | telegram.ext._updater | ERROR | _network_loop_retry:569 | Error while getting Updates: httpx HTTPError: [Errno -2] Name or service not known
2022-06-14 13:20:24,807 | telegram.ext._updater | ERROR | _network_loop_retry:569 | Error while getting Updates: httpx HTTPError: [Errno -2] Name or service not known
2022-06-14 13:20:54,817 | telegram.ext._updater | ERROR | _network_loop_retry:569 | Error while getting Updates: httpx HTTPError: [Errno -2] Name or service not known
2022-06-14 13:21:24,850 | telegram.ext._updater | ERROR | _network_loop_retry:569 | Error while getting Updates: httpx HTTPError: [Errno -2] Name or service not known
2022-06-14 13:21:54,867 | telegram.ext._updater | ERROR | _network_loop_retry:569 | Error while getting Updates: httpx HTTPError: [Errno -2] Name or service not known
2022-06-14 13:58:21,232 | telegram.ext._updater | ERROR | _network_loop_retry:569 | Error while getting Updates: httpx HTTPError: All connection attempts failed
2022-06-14 13:58:31,239 | telegram.ext._updater | ERROR | _network_loop_retry:569 | Error while getting Updates: httpx HTTPError: All connection attempts failed
2022-06-14 14:00:46,104 | apscheduler.scheduler | INFO | start:171 | Scheduler started
2022-06-14 14:00:46,104 | telegram.ext._application | INFO | start:492 | Application started
2022-06-14 14:04:19,157 | apscheduler.scheduler | INFO | start:171 | Scheduler started
2022-06-14 14:04:19,157 | telegram.ext._application | INFO | start:492 | Application started
2022-06-14 14:04:57,326 | apscheduler.scheduler | INFO | start:171 | Scheduler started
2022-06-14 14:04:57,326 | telegram.ext._application | INFO | start:492 | Application started
2022-06-14 14:05:13,953 | apscheduler.scheduler | INFO | start:171 | Scheduler started
2022-06-14 14:05:13,956 | telegram.ext._application | INFO | start:492 | Application started
2022-06-14 14:09:39,768 | apscheduler.scheduler | INFO | start:171 | Scheduler started
2022-06-14 14:09:39,769 | telegram.ext._application | INFO | start:492 | Application started
2022-06-14 14:12:43,973 | apscheduler.scheduler | INFO | start:171 | Scheduler started
2022-06-14 14:12:43,975 | telegram.ext._application | INFO | start:492 | Application started
2022-06-14 14:12:44,528 | telegram.ext._updater | ERROR | _network_loop_retry:569 | Error while getting Updates: Conflict: terminated by other getUpdates request; make sure that only one bot instance is running
2022-06-14 14:12:48,718 | telegram.ext._updater | ERROR | _network_loop_retry:569 | Error while getting Updates: Conflict: terminated by other getUpdates request; make sure that only one bot instance is running
2022-06-14 14:12:50,005 | telegram.ext._updater | ERROR | _network_loop_retry:569 | Error while getting Updates: Conflict: terminated by other getUpdates request; make sure that only one bot instance is running
2022-06-14 14:12:54,676 | telegram.ext._updater | ERROR | _network_loop_retry:569 | Error while getting Updates: Conflict: terminated by other getUpdates request; make sure that only one bot instance is running
2022-06-14 14:12:56,465 | telegram.ext._updater | ERROR | _network_loop_retry:569 | Error while getting Updates: Conflict: terminated by other getUpdates request; make sure that only one bot instance is running
2022-06-14 14:13:01,947 | telegram.ext._updater | ERROR | _network_loop_retry:569 | Error while getting Updates: Conflict: terminated by other getUpdates request; make sure that only one bot instance is running
2022-06-14 14:13:04,393 | telegram.ext._updater | ERROR | _network_loop_retry:569 | Error while getting Updates: Conflict: terminated by other getUpdates request; make sure that only one bot instance is running
2022-06-14 14:13:08,457 | telegram.ext._updater | ERROR | _network_loop_retry:569 | Error while getting Updates: Conflict: terminated by other getUpdates request; make sure that only one bot instance is running
2022-06-14 14:13:12,045 | telegram.ext._updater | ERROR | _network_loop_retry:569 | Error while getting Updates: Conflict: terminated by other getUpdates request; make sure that only one bot instance is running
2022-06-14 14:13:15,483 | telegram.ext._application | INFO | stop:523 | Application is stopping. This might take a moment.
2022-06-14 14:13:15,483 | apscheduler.scheduler | INFO | shutdown:202 | Scheduler has been shut down
2022-06-14 14:13:15,494 | telegram.ext._application | INFO | stop:548 | Application.stop() complete
2022-06-14 14:15:05,073 | telegram.ext._application | INFO | stop:523 | Application is stopping. This might take a moment.
2022-06-14 14:15:05,075 | apscheduler.scheduler | INFO | shutdown:202 | Scheduler has been shut down
2022-06-14 14:15:05,087 | telegram.ext._application | INFO | stop:548 | Application.stop() complete
2022-06-14 14:15:09,332 | apscheduler.scheduler | INFO | start:171 | Scheduler started
2022-06-14 14:15:09,332 | telegram.ext._application | INFO | start:492 | Application started
2022-06-14 14:15:53,811 | telegram.ext._application | INFO | stop:523 | Application is stopping. This might take a moment.
2022-06-14 14:15:53,812 | apscheduler.scheduler | INFO | shutdown:202 | Scheduler has been shut down
2022-06-14 14:15:53,825 | telegram.ext._application | INFO | stop:548 | Application.stop() complete
2022-06-14 14:15:57,956 | apscheduler.scheduler | INFO | start:171 | Scheduler started
2022-06-14 14:15:57,956 | telegram.ext._application | INFO | start:492 | Application started
2022-06-14 14:31:47,873 | apscheduler.scheduler | INFO | start:171 | Scheduler started
2022-06-14 14:31:48,226 | telegram.ext._application | INFO | start:492 | Application started
2022-06-14 14:34:31,995 | apscheduler.scheduler | INFO | start:171 | Scheduler started
2022-06-14 14:34:32,099 | telegram.ext._application | INFO | start:492 | Application started
2022-06-14 14:35:06,208 | telegram.ext._application | INFO | stop:523 | Application is stopping. This might take a moment.
2022-06-14 14:35:06,208 | apscheduler.scheduler | INFO | shutdown:202 | Scheduler has been shut down
2022-06-14 14:35:06,219 | telegram.ext._application | INFO | stop:548 | Application.stop() complete
2022-06-14 14:35:23,350 | apscheduler.scheduler | INFO | start:171 | Scheduler started
2022-06-14 14:35:23,399 | telegram.ext._application | INFO | start:492 | Application started
2022-06-14 14:36:54,938 | apscheduler.scheduler | INFO | start:171 | Scheduler started
2022-06-14 14:36:55,009 | telegram.ext._application | INFO | start:492 | Application started
2022-06-14 14:37:14,939 | telegram.ext._application | INFO | stop:523 | Application is stopping. This might take a moment.
2022-06-14 14:37:14,940 | apscheduler.scheduler | INFO | shutdown:202 | Scheduler has been shut down
2022-06-14 14:37:14,950 | telegram.ext._application | INFO | stop:548 | Application.stop() complete
2022-06-14 14:37:17,285 | apscheduler.scheduler | INFO | start:171 | Scheduler started
2022-06-14 14:37:17,329 | telegram.ext._application | INFO | start:492 | Application started
2022-06-14 14:37:49,917 | telegram.ext._application | INFO | stop:523 | Application is stopping. This might take a moment.
2022-06-14 14:37:49,917 | apscheduler.scheduler | INFO | shutdown:202 | Scheduler has been shut down
2022-06-14 14:37:49,928 | telegram.ext._application | INFO | stop:548 | Application.stop() complete
2022-06-14 14:38:03,849 | apscheduler.scheduler | INFO | start:171 | Scheduler started
2022-06-14 14:38:03,867 | telegram.ext._application | INFO | start:492 | Application started
2022-06-14 14:38:22,130 | apscheduler.scheduler | INFO | start:171 | Scheduler started
2022-06-14 14:38:22,205 | telegram.ext._application | INFO | start:492 | Application started
2022-06-14 14:39:04,060 | apscheduler.scheduler | INFO | start:171 | Scheduler started
2022-06-14 14:39:04,197 | telegram.ext._application | INFO | start:492 | Application started
2022-06-14 14:39:04,848 | telegram.ext._application | ERROR | process_error:1484 | No error handlers are registered, logging exception.
Traceback (most recent call last):
  File "/home/bori/.local/lib/python3.7/site-packages/telegram/ext/_application.py", line 970, in process_update
    await coroutine
  File "/home/bori/.local/lib/python3.7/site-packages/telegram/ext/_handler.py", line 137, in handle_update
    return await self.callback(update, context)
  File "/home/bori/dev/py/beud/beubot/scopes/general/start.py", line 20, in start_hlr
    await exec_genesis_new_user_flow(update, context)
  File "/home/bori/dev/py/beud/beubot/scopes/general/flows/genesis_flow.py", line 109, in exec_genesis_new_user_flow
    await flowelement(update, context)
TypeError: object NoneType can't be used in 'await' expression
2022-06-14 14:39:53,487 | apscheduler.scheduler | INFO | start:171 | Scheduler started
2022-06-14 14:39:53,590 | telegram.ext._application | INFO | start:492 | Application started
2022-06-14 14:40:01,050 | telegram.ext._application | ERROR | process_error:1484 | No error handlers are registered, logging exception.
Traceback (most recent call last):
  File "/home/bori/.local/lib/python3.7/site-packages/telegram/ext/_application.py", line 970, in process_update
    await coroutine
  File "/home/bori/.local/lib/python3.7/site-packages/telegram/ext/_handler.py", line 137, in handle_update
    return await self.callback(update, context)
  File "/home/bori/dev/py/beud/beubot/scopes/general/start.py", line 20, in start_hlr
    await exec_genesis_new_user_flow(update, context)
  File "/home/bori/dev/py/beud/beubot/scopes/general/flows/genesis_flow.py", line 109, in exec_genesis_new_user_flow
    await flowelement(update, context)
TypeError: object NoneType can't be used in 'await' expression
2022-06-14 14:43:32,652 | telegram.ext._application | ERROR | process_error:1480 | An error was raised and an uncaught error was raised while handling the error with an error_handler.
Traceback (most recent call last):
  File "/home/bori/.local/lib/python3.7/site-packages/telegram/ext/_application.py", line 970, in process_update
    await coroutine
  File "/home/bori/.local/lib/python3.7/site-packages/telegram/ext/_handler.py", line 137, in handle_update
    return await self.callback(update, context)
  File "/home/bori/dev/py/beud/beubot/scopes/general/start.py", line 17, in start_hlr
    async def start_hlr(update: Update, context: ContextTypes.DEFAULT_TYPE):
KeyError: 'state'

During handling of the above exception, another exception occurred:

Traceback (most recent call last):
  File "/home/bori/.local/lib/python3.7/site-packages/telegram/ext/_application.py", line 1473, in process_error
    await callback(update, context)
  File "/home/bori/dev/py/beud/main.py", line 53, in error_handler
    p.o(c.red, context.error)
  File "/home/bori/dev/py/beud/misc/colors.py", line 39, in o
    print(f'{data}')
BrokenPipeError: [Errno 32] Broken pipe
2022-06-14 14:43:33,318 | telegram.ext._application | INFO | stop:523 | Application is stopping. This might take a moment.
2022-06-14 14:43:33,319 | apscheduler.scheduler | INFO | shutdown:202 | Scheduler has been shut down
2022-06-14 14:43:33,330 | telegram.ext._application | INFO | stop:548 | Application.stop() complete
2022-06-14 14:43:54,309 | apscheduler.scheduler | INFO | start:171 | Scheduler started
2022-06-14 14:43:54,361 | telegram.ext._application | INFO | start:492 | Application started
2022-06-14 14:48:07,287 | apscheduler.scheduler | INFO | start:171 | Scheduler started
2022-06-14 14:48:07,332 | telegram.ext._application | INFO | start:492 | Application started
2022-06-14 14:48:47,810 | apscheduler.scheduler | INFO | start:171 | Scheduler started
2022-06-14 14:48:47,935 | telegram.ext._application | INFO | start:492 | Application started
2022-06-14 14:49:26,690 | apscheduler.scheduler | INFO | start:171 | Scheduler started
2022-06-14 14:49:26,754 | telegram.ext._application | INFO | start:492 | Application started
2022-06-14 14:50:06,560 | apscheduler.scheduler | INFO | start:171 | Scheduler started
2022-06-14 14:50:06,622 | telegram.ext._application | INFO | start:492 | Application started
2022-06-14 14:50:08,292 | telegram.ext._application | ERROR | process_error:1484 | No error handlers are registered, logging exception.
Traceback (most recent call last):
  File "/home/bori/.local/lib/python3.7/site-packages/telegram/ext/_application.py", line 970, in process_update
    await coroutine
  File "/home/bori/.local/lib/python3.7/site-packages/telegram/ext/_handler.py", line 137, in handle_update
    return await self.callback(update, context)
  File "/home/bori/dev/py/beud/beubot/scopes/general/start.py", line 20, in start_hlr
    await exec_genesis_new_user_flow(update, context)
  File "/home/bori/dev/py/beud/beubot/scopes/general/flows/genesis_flow.py", line 109, in exec_genesis_new_user_flow
    await flowelement(update, context)
TypeError: object NoneType can't be used in 'await' expression
2022-06-14 14:50:34,578 | apscheduler.scheduler | INFO | start:171 | Scheduler started
2022-06-14 14:50:34,694 | telegram.ext._application | INFO | start:492 | Application started
2022-06-14 14:50:36,010 | telegram.ext._application | ERROR | process_error:1484 | No error handlers are registered, logging exception.
Traceback (most recent call last):
  File "/home/bori/.local/lib/python3.7/site-packages/telegram/ext/_application.py", line 970, in process_update
    await coroutine
  File "/home/bori/.local/lib/python3.7/site-packages/telegram/ext/_handler.py", line 137, in handle_update
    return await self.callback(update, context)
  File "/home/bori/dev/py/beud/beubot/scopes/general/start.py", line 20, in start_hlr
    await exec_genesis_new_user_flow(update, context)
  File "/home/bori/dev/py/beud/beubot/scopes/general/flows/genesis_flow.py", line 111, in exec_genesis_new_user_flow
    await flowelement(update, context)
TypeError: object NoneType can't be used in 'await' expression
2022-06-14 14:51:19,184 | apscheduler.scheduler | INFO | start:171 | Scheduler started
2022-06-14 14:51:19,217 | telegram.ext._application | INFO | start:492 | Application started
2022-06-14 14:51:24,697 | telegram.ext._application | ERROR | process_error:1484 | No error handlers are registered, logging exception.
Traceback (most recent call last):
  File "/home/bori/.local/lib/python3.7/site-packages/telegram/ext/_application.py", line 970, in process_update
    await coroutine
  File "/home/bori/.local/lib/python3.7/site-packages/telegram/ext/_handler.py", line 137, in handle_update
    return await self.callback(update, context)
  File "/home/bori/dev/py/beud/beubot/scopes/general/start.py", line 20, in start_hlr
    await exec_genesis_new_user_flow(update, context)
  File "/home/bori/dev/py/beud/beubot/scopes/general/flows/genesis_flow.py", line 111, in exec_genesis_new_user_flow
    await flowelement(update, context)
TypeError: object NoneType can't be used in 'await' expression
2022-06-14 14:51:38,326 | apscheduler.scheduler | INFO | start:171 | Scheduler started
2022-06-14 14:51:38,459 | telegram.ext._application | INFO | start:492 | Application started
2022-06-14 14:51:39,628 | telegram.ext._application | ERROR | process_error:1484 | No error handlers are registered, logging exception.
Traceback (most recent call last):
  File "/home/bori/.local/lib/python3.7/site-packages/telegram/ext/_application.py", line 970, in process_update
    await coroutine
  File "/home/bori/.local/lib/python3.7/site-packages/telegram/ext/_handler.py", line 137, in handle_update
    return await self.callback(update, context)
  File "/home/bori/dev/py/beud/beubot/scopes/general/start.py", line 20, in start_hlr
    await exec_genesis_new_user_flow(update, context)
  File "/home/bori/dev/py/beud/beubot/scopes/general/flows/genesis_flow.py", line 112, in exec_genesis_new_user_flow
    await flowelement(update, context)
TypeError: object NoneType can't be used in 'await' expression
2022-06-14 14:53:06,377 | apscheduler.scheduler | INFO | start:171 | Scheduler started
2022-06-14 14:53:06,377 | telegram.ext._application | INFO | start:492 | Application started
2022-06-14 14:58:58,861 | apscheduler.scheduler | INFO | start:171 | Scheduler started
2022-06-14 14:58:58,861 | telegram.ext._application | INFO | start:492 | Application started
2022-06-14 14:59:15,478 | apscheduler.scheduler | INFO | start:171 | Scheduler started
2022-06-14 14:59:15,479 | telegram.ext._application | INFO | start:492 | Application started
2022-06-14 14:59:38,080 | apscheduler.scheduler | INFO | start:171 | Scheduler started
2022-06-14 14:59:38,080 | telegram.ext._application | INFO | start:492 | Application started
2022-06-14 15:00:21,257 | apscheduler.scheduler | INFO | start:171 | Scheduler started
2022-06-14 15:00:21,257 | telegram.ext._application | INFO | start:492 | Application started
2022-06-14 15:00:37,871 | apscheduler.scheduler | INFO | start:171 | Scheduler started
2022-06-14 15:00:37,872 | telegram.ext._application | INFO | start:492 | Application started
2022-06-14 15:01:32,752 | apscheduler.scheduler | INFO | start:171 | Scheduler started
2022-06-14 15:01:32,752 | telegram.ext._application | INFO | start:492 | Application started
2022-06-14 15:02:15,767 | apscheduler.scheduler | INFO | start:171 | Scheduler started
2022-06-14 15:02:15,768 | telegram.ext._application | INFO | start:492 | Application started
2022-06-14 15:03:36,959 | apscheduler.scheduler | INFO | start:171 | Scheduler started
2022-06-14 15:03:36,960 | telegram.ext._application | INFO | start:492 | Application started
2022-06-14 15:04:57,554 | apscheduler.scheduler | INFO | start:171 | Scheduler started
2022-06-14 15:04:57,554 | telegram.ext._application | INFO | start:492 | Application started
2022-06-14 15:05:32,383 | apscheduler.scheduler | INFO | start:171 | Scheduler started
2022-06-14 15:05:32,384 | telegram.ext._application | INFO | start:492 | Application started
2022-06-14 15:05:45,352 | apscheduler.scheduler | INFO | start:171 | Scheduler started
2022-06-14 15:05:45,352 | telegram.ext._application | INFO | start:492 | Application started
2022-06-14 15:06:23,950 | apscheduler.scheduler | INFO | start:171 | Scheduler started
2022-06-14 15:06:23,950 | telegram.ext._application | INFO | start:492 | Application started
2022-06-14 15:07:28,180 | apscheduler.scheduler | INFO | start:171 | Scheduler started
2022-06-14 15:07:28,186 | telegram.ext._application | INFO | start:492 | Application started
2022-06-14 15:08:22,160 | apscheduler.scheduler | INFO | start:171 | Scheduler started
2022-06-14 15:08:22,160 | telegram.ext._application | INFO | start:492 | Application started
2022-06-14 15:08:38,514 | apscheduler.scheduler | INFO | start:171 | Scheduler started
2022-06-14 15:08:38,515 | telegram.ext._application | INFO | start:492 | Application started
2022-06-14 15:08:47,612 | apscheduler.scheduler | INFO | start:171 | Scheduler started
2022-06-14 15:08:47,612 | telegram.ext._application | INFO | start:492 | Application started
2022-06-14 15:09:00,171 | apscheduler.scheduler | INFO | start:171 | Scheduler started
2022-06-14 15:09:00,171 | telegram.ext._application | INFO | start:492 | Application started
2022-06-14 15:09:35,083 | apscheduler.scheduler | INFO | start:171 | Scheduler started
2022-06-14 15:09:35,168 | telegram.ext._application | INFO | start:492 | Application started
2022-06-14 15:10:05,054 | apscheduler.scheduler | INFO | start:171 | Scheduler started
2022-06-14 15:10:05,117 | telegram.ext._application | INFO | start:492 | Application started
2022-06-14 15:10:49,523 | apscheduler.scheduler | INFO | start:171 | Scheduler started
2022-06-14 15:10:49,557 | telegram.ext._application | INFO | start:492 | Application started
2022-06-14 15:12:41,470 | apscheduler.scheduler | INFO | start:171 | Scheduler started
2022-06-14 15:12:41,535 | telegram.ext._application | INFO | start:492 | Application started
2022-06-14 15:12:53,784 | telegram.ext._updater | ERROR | _network_loop_retry:569 | Error while getting Updates: httpx HTTPError: [Errno -2] Name or service not known
2022-06-14 15:12:53,785 | telegram.ext._application | ERROR | process_error:1484 | No error handlers are registered, logging exception.
Traceback (most recent call last):
  File "/home/bori/.local/lib/python3.7/site-packages/httpcore/_exceptions.py", line 8, in map_exceptions
    yield
  File "/home/bori/.local/lib/python3.7/site-packages/httpcore/backends/asyncio.py", line 112, in connect_tcp
    local_host=local_address,
  File "/home/bori/.local/lib/python3.7/site-packages/anyio/_core/_sockets.py", line 190, in connect_tcp
    target_host, remote_port, family=family, type=socket.SOCK_STREAM
  File "/home/bori/.local/lib/python3.7/site-packages/anyio/_core/_sockets.py", line 497, in getaddrinfo
    encoded_host, port, family=family, type=type, proto=proto, flags=flags
  File "/home/bori/.local/lib/python3.7/site-packages/anyio/_backends/_asyncio.py", line 1755, in getaddrinfo
    host, port, family=family, type=type, proto=proto, flags=flags
  File "/usr/lib/python3.7/asyncio/base_events.py", line 792, in getaddrinfo
    None, getaddr_func, host, port, family, type, proto, flags)
  File "/usr/lib/python3.7/concurrent/futures/thread.py", line 57, in run
    result = self.fn(*self.args, **self.kwargs)
  File "/usr/lib/python3.7/socket.py", line 752, in getaddrinfo
    for res in _socket.getaddrinfo(host, port, family, type, proto, flags):
socket.gaierror: [Errno -2] Name or service not known

During handling of the above exception, another exception occurred:

Traceback (most recent call last):
  File "/home/bori/.local/lib/python3.7/site-packages/httpx/_transports/default.py", line 60, in map_httpcore_exceptions
    yield
  File "/home/bori/.local/lib/python3.7/site-packages/httpx/_transports/default.py", line 353, in handle_async_request
    resp = await self._pool.handle_async_request(req)
  File "/home/bori/.local/lib/python3.7/site-packages/httpcore/_async/connection_pool.py", line 253, in handle_async_request
    raise exc
  File "/home/bori/.local/lib/python3.7/site-packages/httpcore/_async/connection_pool.py", line 237, in handle_async_request
    response = await connection.handle_async_request(request)
  File "/home/bori/.local/lib/python3.7/site-packages/httpcore/_async/connection.py", line 86, in handle_async_request
    raise exc
  File "/home/bori/.local/lib/python3.7/site-packages/httpcore/_async/connection.py", line 63, in handle_async_request
    stream = await self._connect(request)
  File "/home/bori/.local/lib/python3.7/site-packages/httpcore/_async/connection.py", line 111, in _connect
    stream = await self._network_backend.connect_tcp(**kwargs)
  File "/home/bori/.local/lib/python3.7/site-packages/httpcore/backends/auto.py", line 30, in connect_tcp
    host, port, timeout=timeout, local_address=local_address
  File "/home/bori/.local/lib/python3.7/site-packages/httpcore/backends/asyncio.py", line 112, in connect_tcp
    local_host=local_address,
  File "/usr/lib/python3.7/contextlib.py", line 130, in __exit__
    self.gen.throw(type, value, traceback)
  File "/home/bori/.local/lib/python3.7/site-packages/httpcore/_exceptions.py", line 12, in map_exceptions
    raise to_exc(exc)
httpcore.ConnectError: [Errno -2] Name or service not known

The above exception was the direct cause of the following exception:

Traceback (most recent call last):
  File "/home/bori/.local/lib/python3.7/site-packages/telegram/request/_httpxrequest.py", line 180, in do_request
    data=data,
  File "/home/bori/.local/lib/python3.7/site-packages/httpx/_client.py", line 1527, in request
    return await self.send(request, auth=auth, follow_redirects=follow_redirects)
  File "/home/bori/.local/lib/python3.7/site-packages/httpx/_client.py", line 1618, in send
    history=[],
  File "/home/bori/.local/lib/python3.7/site-packages/httpx/_client.py", line 1645, in _send_handling_auth
    history=history,
  File "/home/bori/.local/lib/python3.7/site-packages/httpx/_client.py", line 1679, in _send_handling_redirects
    response = await self._send_single_request(request)
  File "/home/bori/.local/lib/python3.7/site-packages/httpx/_client.py", line 1716, in _send_single_request
    response = await transport.handle_async_request(request)
  File "/home/bori/.local/lib/python3.7/site-packages/httpx/_transports/default.py", line 353, in handle_async_request
    resp = await self._pool.handle_async_request(req)
  File "/usr/lib/python3.7/contextlib.py", line 130, in __exit__
    self.gen.throw(type, value, traceback)
  File "/home/bori/.local/lib/python3.7/site-packages/httpx/_transports/default.py", line 77, in map_httpcore_exceptions
    raise mapped_exc(message) from exc
httpx.ConnectError: [Errno -2] Name or service not known

The above exception was the direct cause of the following exception:

Traceback (most recent call last):
  File "/home/bori/.local/lib/python3.7/site-packages/telegram/ext/_updater.py", line 556, in _network_loop_retry
    if not await action_cb():
  File "/home/bori/.local/lib/python3.7/site-packages/telegram/ext/_updater.py", line 318, in polling_action_cb
    raise exc
  File "/home/bori/.local/lib/python3.7/site-packages/telegram/ext/_updater.py", line 310, in polling_action_cb
    allowed_updates=allowed_updates,
  File "/home/bori/.local/lib/python3.7/site-packages/telegram/ext/_extbot.py", line 294, in get_updates
    api_kwargs=api_kwargs,
  File "/home/bori/.local/lib/python3.7/site-packages/telegram/_bot.py", line 236, in decorator
    result = await func(*args, **kwargs)
  File "/home/bori/.local/lib/python3.7/site-packages/telegram/_bot.py", line 3778, in get_updates
    api_kwargs=api_kwargs,
  File "/home/bori/.local/lib/python3.7/site-packages/telegram/_bot.py", line 315, in _post
    pool_timeout=pool_timeout,
  File "/home/bori/.local/lib/python3.7/site-packages/telegram/request/_baserequest.py", line 169, in post
    pool_timeout=pool_timeout,
  File "/home/bori/.local/lib/python3.7/site-packages/telegram/request/_baserequest.py", line 285, in _request_wrapper
    raise exc
  File "/home/bori/.local/lib/python3.7/site-packages/telegram/request/_baserequest.py", line 278, in _request_wrapper
    pool_timeout=pool_timeout,
  File "/home/bori/.local/lib/python3.7/site-packages/telegram/request/_httpxrequest.py", line 195, in do_request
    raise NetworkError(f"httpx HTTPError: {err}") from err
telegram.error.NetworkError: httpx HTTPError: [Errno -2] Name or service not known
2022-06-14 15:12:54,796 | telegram.ext._updater | ERROR | _network_loop_retry:569 | Error while getting Updates: httpx HTTPError: [Errno -2] Name or service not known
2022-06-14 15:12:54,797 | telegram.ext._application | ERROR | process_error:1484 | No error handlers are registered, logging exception.
Traceback (most recent call last):
  File "/home/bori/.local/lib/python3.7/site-packages/httpcore/_exceptions.py", line 8, in map_exceptions
    yield
  File "/home/bori/.local/lib/python3.7/site-packages/httpcore/backends/asyncio.py", line 112, in connect_tcp
    local_host=local_address,
  File "/home/bori/.local/lib/python3.7/site-packages/anyio/_core/_sockets.py", line 190, in connect_tcp
    target_host, remote_port, family=family, type=socket.SOCK_STREAM
  File "/home/bori/.local/lib/python3.7/site-packages/anyio/_core/_sockets.py", line 497, in getaddrinfo
    encoded_host, port, family=family, type=type, proto=proto, flags=flags
  File "/home/bori/.local/lib/python3.7/site-packages/anyio/_backends/_asyncio.py", line 1755, in getaddrinfo
    host, port, family=family, type=type, proto=proto, flags=flags
  File "/usr/lib/python3.7/asyncio/base_events.py", line 792, in getaddrinfo
    None, getaddr_func, host, port, family, type, proto, flags)
  File "/usr/lib/python3.7/concurrent/futures/thread.py", line 57, in run
    result = self.fn(*self.args, **self.kwargs)
  File "/usr/lib/python3.7/socket.py", line 752, in getaddrinfo
    for res in _socket.getaddrinfo(host, port, family, type, proto, flags):
socket.gaierror: [Errno -2] Name or service not known

During handling of the above exception, another exception occurred:

Traceback (most recent call last):
  File "/home/bori/.local/lib/python3.7/site-packages/httpx/_transports/default.py", line 60, in map_httpcore_exceptions
    yield
  File "/home/bori/.local/lib/python3.7/site-packages/httpx/_transports/default.py", line 353, in handle_async_request
    resp = await self._pool.handle_async_request(req)
  File "/home/bori/.local/lib/python3.7/site-packages/httpcore/_async/connection_pool.py", line 253, in handle_async_request
    raise exc
  File "/home/bori/.local/lib/python3.7/site-packages/httpcore/_async/connection_pool.py", line 237, in handle_async_request
    response = await connection.handle_async_request(request)
  File "/home/bori/.local/lib/python3.7/site-packages/httpcore/_async/connection.py", line 86, in handle_async_request
    raise exc
  File "/home/bori/.local/lib/python3.7/site-packages/httpcore/_async/connection.py", line 63, in handle_async_request
    stream = await self._connect(request)
  File "/home/bori/.local/lib/python3.7/site-packages/httpcore/_async/connection.py", line 111, in _connect
    stream = await self._network_backend.connect_tcp(**kwargs)
  File "/home/bori/.local/lib/python3.7/site-packages/httpcore/backends/auto.py", line 30, in connect_tcp
    host, port, timeout=timeout, local_address=local_address
  File "/home/bori/.local/lib/python3.7/site-packages/httpcore/backends/asyncio.py", line 112, in connect_tcp
    local_host=local_address,
  File "/usr/lib/python3.7/contextlib.py", line 130, in __exit__
    self.gen.throw(type, value, traceback)
  File "/home/bori/.local/lib/python3.7/site-packages/httpcore/_exceptions.py", line 12, in map_exceptions
    raise to_exc(exc)
httpcore.ConnectError: [Errno -2] Name or service not known

The above exception was the direct cause of the following exception:

Traceback (most recent call last):
  File "/home/bori/.local/lib/python3.7/site-packages/telegram/request/_httpxrequest.py", line 180, in do_request
    data=data,
  File "/home/bori/.local/lib/python3.7/site-packages/httpx/_client.py", line 1527, in request
    return await self.send(request, auth=auth, follow_redirects=follow_redirects)
  File "/home/bori/.local/lib/python3.7/site-packages/httpx/_client.py", line 1618, in send
    history=[],
  File "/home/bori/.local/lib/python3.7/site-packages/httpx/_client.py", line 1645, in _send_handling_auth
    history=history,
  File "/home/bori/.local/lib/python3.7/site-packages/httpx/_client.py", line 1679, in _send_handling_redirects
    response = await self._send_single_request(request)
  File "/home/bori/.local/lib/python3.7/site-packages/httpx/_client.py", line 1716, in _send_single_request
    response = await transport.handle_async_request(request)
  File "/home/bori/.local/lib/python3.7/site-packages/httpx/_transports/default.py", line 353, in handle_async_request
    resp = await self._pool.handle_async_request(req)
  File "/usr/lib/python3.7/contextlib.py", line 130, in __exit__
    self.gen.throw(type, value, traceback)
  File "/home/bori/.local/lib/python3.7/site-packages/httpx/_transports/default.py", line 77, in map_httpcore_exceptions
    raise mapped_exc(message) from exc
httpx.ConnectError: [Errno -2] Name or service not known

The above exception was the direct cause of the following exception:

Traceback (most recent call last):
  File "/home/bori/.local/lib/python3.7/site-packages/telegram/ext/_updater.py", line 556, in _network_loop_retry
    if not await action_cb():
  File "/home/bori/.local/lib/python3.7/site-packages/telegram/ext/_updater.py", line 318, in polling_action_cb
    raise exc
  File "/home/bori/.local/lib/python3.7/site-packages/telegram/ext/_updater.py", line 310, in polling_action_cb
    allowed_updates=allowed_updates,
  File "/home/bori/.local/lib/python3.7/site-packages/telegram/ext/_extbot.py", line 294, in get_updates
    api_kwargs=api_kwargs,
  File "/home/bori/.local/lib/python3.7/site-packages/telegram/_bot.py", line 236, in decorator
    result = await func(*args, **kwargs)
  File "/home/bori/.local/lib/python3.7/site-packages/telegram/_bot.py", line 3778, in get_updates
    api_kwargs=api_kwargs,
  File "/home/bori/.local/lib/python3.7/site-packages/telegram/_bot.py", line 315, in _post
    pool_timeout=pool_timeout,
  File "/home/bori/.local/lib/python3.7/site-packages/telegram/request/_baserequest.py", line 169, in post
    pool_timeout=pool_timeout,
  File "/home/bori/.local/lib/python3.7/site-packages/telegram/request/_baserequest.py", line 285, in _request_wrapper
    raise exc
  File "/home/bori/.local/lib/python3.7/site-packages/telegram/request/_baserequest.py", line 278, in _request_wrapper
    pool_timeout=pool_timeout,
  File "/home/bori/.local/lib/python3.7/site-packages/telegram/request/_httpxrequest.py", line 195, in do_request
    raise NetworkError(f"httpx HTTPError: {err}") from err
telegram.error.NetworkError: httpx HTTPError: [Errno -2] Name or service not known
2022-06-14 15:12:56,301 | telegram.ext._updater | ERROR | _network_loop_retry:569 | Error while getting Updates: httpx HTTPError: [Errno -2] Name or service not known
2022-06-14 15:12:56,301 | telegram.ext._application | ERROR | process_error:1484 | No error handlers are registered, logging exception.
Traceback (most recent call last):
  File "/home/bori/.local/lib/python3.7/site-packages/httpcore/_exceptions.py", line 8, in map_exceptions
    yield
  File "/home/bori/.local/lib/python3.7/site-packages/httpcore/backends/asyncio.py", line 112, in connect_tcp
    local_host=local_address,
  File "/home/bori/.local/lib/python3.7/site-packages/anyio/_core/_sockets.py", line 190, in connect_tcp
    target_host, remote_port, family=family, type=socket.SOCK_STREAM
  File "/home/bori/.local/lib/python3.7/site-packages/anyio/_core/_sockets.py", line 497, in getaddrinfo
    encoded_host, port, family=family, type=type, proto=proto, flags=flags
  File "/home/bori/.local/lib/python3.7/site-packages/anyio/_backends/_asyncio.py", line 1755, in getaddrinfo
    host, port, family=family, type=type, proto=proto, flags=flags
  File "/usr/lib/python3.7/asyncio/base_events.py", line 792, in getaddrinfo
    None, getaddr_func, host, port, family, type, proto, flags)
  File "/usr/lib/python3.7/concurrent/futures/thread.py", line 57, in run
    result = self.fn(*self.args, **self.kwargs)
  File "/usr/lib/python3.7/socket.py", line 752, in getaddrinfo
    for res in _socket.getaddrinfo(host, port, family, type, proto, flags):
socket.gaierror: [Errno -2] Name or service not known

During handling of the above exception, another exception occurred:

Traceback (most recent call last):
  File "/home/bori/.local/lib/python3.7/site-packages/httpx/_transports/default.py", line 60, in map_httpcore_exceptions
    yield
  File "/home/bori/.local/lib/python3.7/site-packages/httpx/_transports/default.py", line 353, in handle_async_request
    resp = await self._pool.handle_async_request(req)
  File "/home/bori/.local/lib/python3.7/site-packages/httpcore/_async/connection_pool.py", line 253, in handle_async_request
    raise exc
  File "/home/bori/.local/lib/python3.7/site-packages/httpcore/_async/connection_pool.py", line 237, in handle_async_request
    response = await connection.handle_async_request(request)
  File "/home/bori/.local/lib/python3.7/site-packages/httpcore/_async/connection.py", line 86, in handle_async_request
    raise exc
  File "/home/bori/.local/lib/python3.7/site-packages/httpcore/_async/connection.py", line 63, in handle_async_request
    stream = await self._connect(request)
  File "/home/bori/.local/lib/python3.7/site-packages/httpcore/_async/connection.py", line 111, in _connect
    stream = await self._network_backend.connect_tcp(**kwargs)
  File "/home/bori/.local/lib/python3.7/site-packages/httpcore/backends/auto.py", line 30, in connect_tcp
    host, port, timeout=timeout, local_address=local_address
  File "/home/bori/.local/lib/python3.7/site-packages/httpcore/backends/asyncio.py", line 112, in connect_tcp
    local_host=local_address,
  File "/usr/lib/python3.7/contextlib.py", line 130, in __exit__
    self.gen.throw(type, value, traceback)
  File "/home/bori/.local/lib/python3.7/site-packages/httpcore/_exceptions.py", line 12, in map_exceptions
    raise to_exc(exc)
httpcore.ConnectError: [Errno -2] Name or service not known

The above exception was the direct cause of the following exception:

Traceback (most recent call last):
  File "/home/bori/.local/lib/python3.7/site-packages/telegram/request/_httpxrequest.py", line 180, in do_request
    data=data,
  File "/home/bori/.local/lib/python3.7/site-packages/httpx/_client.py", line 1527, in request
    return await self.send(request, auth=auth, follow_redirects=follow_redirects)
  File "/home/bori/.local/lib/python3.7/site-packages/httpx/_client.py", line 1618, in send
    history=[],
  File "/home/bori/.local/lib/python3.7/site-packages/httpx/_client.py", line 1645, in _send_handling_auth
    history=history,
  File "/home/bori/.local/lib/python3.7/site-packages/httpx/_client.py", line 1679, in _send_handling_redirects
    response = await self._send_single_request(request)
  File "/home/bori/.local/lib/python3.7/site-packages/httpx/_client.py", line 1716, in _send_single_request
    response = await transport.handle_async_request(request)
  File "/home/bori/.local/lib/python3.7/site-packages/httpx/_transports/default.py", line 353, in handle_async_request
    resp = await self._pool.handle_async_request(req)
  File "/usr/lib/python3.7/contextlib.py", line 130, in __exit__
    self.gen.throw(type, value, traceback)
  File "/home/bori/.local/lib/python3.7/site-packages/httpx/_transports/default.py", line 77, in map_httpcore_exceptions
    raise mapped_exc(message) from exc
httpx.ConnectError: [Errno -2] Name or service not known

The above exception was the direct cause of the following exception:

Traceback (most recent call last):
  File "/home/bori/.local/lib/python3.7/site-packages/telegram/ext/_updater.py", line 556, in _network_loop_retry
    if not await action_cb():
  File "/home/bori/.local/lib/python3.7/site-packages/telegram/ext/_updater.py", line 318, in polling_action_cb
    raise exc
  File "/home/bori/.local/lib/python3.7/site-packages/telegram/ext/_updater.py", line 310, in polling_action_cb
    allowed_updates=allowed_updates,
  File "/home/bori/.local/lib/python3.7/site-packages/telegram/ext/_extbot.py", line 294, in get_updates
    api_kwargs=api_kwargs,
  File "/home/bori/.local/lib/python3.7/site-packages/telegram/_bot.py", line 236, in decorator
    result = await func(*args, **kwargs)
  File "/home/bori/.local/lib/python3.7/site-packages/telegram/_bot.py", line 3778, in get_updates
    api_kwargs=api_kwargs,
  File "/home/bori/.local/lib/python3.7/site-packages/telegram/_bot.py", line 315, in _post
    pool_timeout=pool_timeout,
  File "/home/bori/.local/lib/python3.7/site-packages/telegram/request/_baserequest.py", line 169, in post
    pool_timeout=pool_timeout,
  File "/home/bori/.local/lib/python3.7/site-packages/telegram/request/_baserequest.py", line 285, in _request_wrapper
    raise exc
  File "/home/bori/.local/lib/python3.7/site-packages/telegram/request/_baserequest.py", line 278, in _request_wrapper
    pool_timeout=pool_timeout,
  File "/home/bori/.local/lib/python3.7/site-packages/telegram/request/_httpxrequest.py", line 195, in do_request
    raise NetworkError(f"httpx HTTPError: {err}") from err
telegram.error.NetworkError: httpx HTTPError: [Errno -2] Name or service not known
2022-06-14 15:12:58,559 | telegram.ext._updater | ERROR | _network_loop_retry:569 | Error while getting Updates: httpx HTTPError: [Errno -2] Name or service not known
2022-06-14 15:12:58,560 | telegram.ext._application | ERROR | process_error:1484 | No error handlers are registered, logging exception.
Traceback (most recent call last):
  File "/home/bori/.local/lib/python3.7/site-packages/httpcore/_exceptions.py", line 8, in map_exceptions
    yield
  File "/home/bori/.local/lib/python3.7/site-packages/httpcore/backends/asyncio.py", line 112, in connect_tcp
    local_host=local_address,
  File "/home/bori/.local/lib/python3.7/site-packages/anyio/_core/_sockets.py", line 190, in connect_tcp
    target_host, remote_port, family=family, type=socket.SOCK_STREAM
  File "/home/bori/.local/lib/python3.7/site-packages/anyio/_core/_sockets.py", line 497, in getaddrinfo
    encoded_host, port, family=family, type=type, proto=proto, flags=flags
  File "/home/bori/.local/lib/python3.7/site-packages/anyio/_backends/_asyncio.py", line 1755, in getaddrinfo
    host, port, family=family, type=type, proto=proto, flags=flags
  File "/usr/lib/python3.7/asyncio/base_events.py", line 792, in getaddrinfo
    None, getaddr_func, host, port, family, type, proto, flags)
  File "/usr/lib/python3.7/concurrent/futures/thread.py", line 57, in run
    result = self.fn(*self.args, **self.kwargs)
  File "/usr/lib/python3.7/socket.py", line 752, in getaddrinfo
    for res in _socket.getaddrinfo(host, port, family, type, proto, flags):
socket.gaierror: [Errno -2] Name or service not known

During handling of the above exception, another exception occurred:

Traceback (most recent call last):
  File "/home/bori/.local/lib/python3.7/site-packages/httpx/_transports/default.py", line 60, in map_httpcore_exceptions
    yield
  File "/home/bori/.local/lib/python3.7/site-packages/httpx/_transports/default.py", line 353, in handle_async_request
    resp = await self._pool.handle_async_request(req)
  File "/home/bori/.local/lib/python3.7/site-packages/httpcore/_async/connection_pool.py", line 253, in handle_async_request
    raise exc
  File "/home/bori/.local/lib/python3.7/site-packages/httpcore/_async/connection_pool.py", line 237, in handle_async_request
    response = await connection.handle_async_request(request)
  File "/home/bori/.local/lib/python3.7/site-packages/httpcore/_async/connection.py", line 86, in handle_async_request
    raise exc
  File "/home/bori/.local/lib/python3.7/site-packages/httpcore/_async/connection.py", line 63, in handle_async_request
    stream = await self._connect(request)
  File "/home/bori/.local/lib/python3.7/site-packages/httpcore/_async/connection.py", line 111, in _connect
    stream = await self._network_backend.connect_tcp(**kwargs)
  File "/home/bori/.local/lib/python3.7/site-packages/httpcore/backends/auto.py", line 30, in connect_tcp
    host, port, timeout=timeout, local_address=local_address
  File "/home/bori/.local/lib/python3.7/site-packages/httpcore/backends/asyncio.py", line 112, in connect_tcp
    local_host=local_address,
  File "/usr/lib/python3.7/contextlib.py", line 130, in __exit__
    self.gen.throw(type, value, traceback)
  File "/home/bori/.local/lib/python3.7/site-packages/httpcore/_exceptions.py", line 12, in map_exceptions
    raise to_exc(exc)
httpcore.ConnectError: [Errno -2] Name or service not known

The above exception was the direct cause of the following exception:

Traceback (most recent call last):
  File "/home/bori/.local/lib/python3.7/site-packages/telegram/request/_httpxrequest.py", line 180, in do_request
    data=data,
  File "/home/bori/.local/lib/python3.7/site-packages/httpx/_client.py", line 1527, in request
    return await self.send(request, auth=auth, follow_redirects=follow_redirects)
  File "/home/bori/.local/lib/python3.7/site-packages/httpx/_client.py", line 1618, in send
    history=[],
  File "/home/bori/.local/lib/python3.7/site-packages/httpx/_client.py", line 1645, in _send_handling_auth
    history=history,
  File "/home/bori/.local/lib/python3.7/site-packages/httpx/_client.py", line 1679, in _send_handling_redirects
    response = await self._send_single_request(request)
  File "/home/bori/.local/lib/python3.7/site-packages/httpx/_client.py", line 1716, in _send_single_request
    response = await transport.handle_async_request(request)
  File "/home/bori/.local/lib/python3.7/site-packages/httpx/_transports/default.py", line 353, in handle_async_request
    resp = await self._pool.handle_async_request(req)
  File "/usr/lib/python3.7/contextlib.py", line 130, in __exit__
    self.gen.throw(type, value, traceback)
  File "/home/bori/.local/lib/python3.7/site-packages/httpx/_transports/default.py", line 77, in map_httpcore_exceptions
    raise mapped_exc(message) from exc
httpx.ConnectError: [Errno -2] Name or service not known

The above exception was the direct cause of the following exception:

Traceback (most recent call last):
  File "/home/bori/.local/lib/python3.7/site-packages/telegram/ext/_updater.py", line 556, in _network_loop_retry
    if not await action_cb():
  File "/home/bori/.local/lib/python3.7/site-packages/telegram/ext/_updater.py", line 318, in polling_action_cb
    raise exc
  File "/home/bori/.local/lib/python3.7/site-packages/telegram/ext/_updater.py", line 310, in polling_action_cb
    allowed_updates=allowed_updates,
  File "/home/bori/.local/lib/python3.7/site-packages/telegram/ext/_extbot.py", line 294, in get_updates
    api_kwargs=api_kwargs,
  File "/home/bori/.local/lib/python3.7/site-packages/telegram/_bot.py", line 236, in decorator
    result = await func(*args, **kwargs)
  File "/home/bori/.local/lib/python3.7/site-packages/telegram/_bot.py", line 3778, in get_updates
    api_kwargs=api_kwargs,
  File "/home/bori/.local/lib/python3.7/site-packages/telegram/_bot.py", line 315, in _post
    pool_timeout=pool_timeout,
  File "/home/bori/.local/lib/python3.7/site-packages/telegram/request/_baserequest.py", line 169, in post
    pool_timeout=pool_timeout,
  File "/home/bori/.local/lib/python3.7/site-packages/telegram/request/_baserequest.py", line 285, in _request_wrapper
    raise exc
  File "/home/bori/.local/lib/python3.7/site-packages/telegram/request/_baserequest.py", line 278, in _request_wrapper
    pool_timeout=pool_timeout,
  File "/home/bori/.local/lib/python3.7/site-packages/telegram/request/_httpxrequest.py", line 195, in do_request
    raise NetworkError(f"httpx HTTPError: {err}") from err
telegram.error.NetworkError: httpx HTTPError: [Errno -2] Name or service not known
2022-06-14 15:13:01,948 | telegram.ext._updater | ERROR | _network_loop_retry:569 | Error while getting Updates: httpx HTTPError: [Errno -2] Name or service not known
2022-06-14 15:13:01,949 | telegram.ext._application | ERROR | process_error:1484 | No error handlers are registered, logging exception.
Traceback (most recent call last):
  File "/home/bori/.local/lib/python3.7/site-packages/httpcore/_exceptions.py", line 8, in map_exceptions
    yield
  File "/home/bori/.local/lib/python3.7/site-packages/httpcore/backends/asyncio.py", line 112, in connect_tcp
    local_host=local_address,
  File "/home/bori/.local/lib/python3.7/site-packages/anyio/_core/_sockets.py", line 190, in connect_tcp
    target_host, remote_port, family=family, type=socket.SOCK_STREAM
  File "/home/bori/.local/lib/python3.7/site-packages/anyio/_core/_sockets.py", line 497, in getaddrinfo
    encoded_host, port, family=family, type=type, proto=proto, flags=flags
  File "/home/bori/.local/lib/python3.7/site-packages/anyio/_backends/_asyncio.py", line 1755, in getaddrinfo
    host, port, family=family, type=type, proto=proto, flags=flags
  File "/usr/lib/python3.7/asyncio/base_events.py", line 792, in getaddrinfo
    None, getaddr_func, host, port, family, type, proto, flags)
  File "/usr/lib/python3.7/concurrent/futures/thread.py", line 57, in run
    result = self.fn(*self.args, **self.kwargs)
  File "/usr/lib/python3.7/socket.py", line 752, in getaddrinfo
    for res in _socket.getaddrinfo(host, port, family, type, proto, flags):
socket.gaierror: [Errno -2] Name or service not known

During handling of the above exception, another exception occurred:

Traceback (most recent call last):
  File "/home/bori/.local/lib/python3.7/site-packages/httpx/_transports/default.py", line 60, in map_httpcore_exceptions
    yield
  File "/home/bori/.local/lib/python3.7/site-packages/httpx/_transports/default.py", line 353, in handle_async_request
    resp = await self._pool.handle_async_request(req)
  File "/home/bori/.local/lib/python3.7/site-packages/httpcore/_async/connection_pool.py", line 253, in handle_async_request
    raise exc
  File "/home/bori/.local/lib/python3.7/site-packages/httpcore/_async/connection_pool.py", line 237, in handle_async_request
    response = await connection.handle_async_request(request)
  File "/home/bori/.local/lib/python3.7/site-packages/httpcore/_async/connection.py", line 86, in handle_async_request
    raise exc
  File "/home/bori/.local/lib/python3.7/site-packages/httpcore/_async/connection.py", line 63, in handle_async_request
    stream = await self._connect(request)
  File "/home/bori/.local/lib/python3.7/site-packages/httpcore/_async/connection.py", line 111, in _connect
    stream = await self._network_backend.connect_tcp(**kwargs)
  File "/home/bori/.local/lib/python3.7/site-packages/httpcore/backends/auto.py", line 30, in connect_tcp
    host, port, timeout=timeout, local_address=local_address
  File "/home/bori/.local/lib/python3.7/site-packages/httpcore/backends/asyncio.py", line 112, in connect_tcp
    local_host=local_address,
  File "/usr/lib/python3.7/contextlib.py", line 130, in __exit__
    self.gen.throw(type, value, traceback)
  File "/home/bori/.local/lib/python3.7/site-packages/httpcore/_exceptions.py", line 12, in map_exceptions
    raise to_exc(exc)
httpcore.ConnectError: [Errno -2] Name or service not known

The above exception was the direct cause of the following exception:

Traceback (most recent call last):
  File "/home/bori/.local/lib/python3.7/site-packages/telegram/request/_httpxrequest.py", line 180, in do_request
    data=data,
  File "/home/bori/.local/lib/python3.7/site-packages/httpx/_client.py", line 1527, in request
    return await self.send(request, auth=auth, follow_redirects=follow_redirects)
  File "/home/bori/.local/lib/python3.7/site-packages/httpx/_client.py", line 1618, in send
    history=[],
  File "/home/bori/.local/lib/python3.7/site-packages/httpx/_client.py", line 1645, in _send_handling_auth
    history=history,
  File "/home/bori/.local/lib/python3.7/site-packages/httpx/_client.py", line 1679, in _send_handling_redirects
    response = await self._send_single_request(request)
  File "/home/bori/.local/lib/python3.7/site-packages/httpx/_client.py", line 1716, in _send_single_request
    response = await transport.handle_async_request(request)
  File "/home/bori/.local/lib/python3.7/site-packages/httpx/_transports/default.py", line 353, in handle_async_request
    resp = await self._pool.handle_async_request(req)
  File "/usr/lib/python3.7/contextlib.py", line 130, in __exit__
    self.gen.throw(type, value, traceback)
  File "/home/bori/.local/lib/python3.7/site-packages/httpx/_transports/default.py", line 77, in map_httpcore_exceptions
    raise mapped_exc(message) from exc
httpx.ConnectError: [Errno -2] Name or service not known

The above exception was the direct cause of the following exception:

Traceback (most recent call last):
  File "/home/bori/.local/lib/python3.7/site-packages/telegram/ext/_updater.py", line 556, in _network_loop_retry
    if not await action_cb():
  File "/home/bori/.local/lib/python3.7/site-packages/telegram/ext/_updater.py", line 318, in polling_action_cb
    raise exc
  File "/home/bori/.local/lib/python3.7/site-packages/telegram/ext/_updater.py", line 310, in polling_action_cb
    allowed_updates=allowed_updates,
  File "/home/bori/.local/lib/python3.7/site-packages/telegram/ext/_extbot.py", line 294, in get_updates
    api_kwargs=api_kwargs,
  File "/home/bori/.local/lib/python3.7/site-packages/telegram/_bot.py", line 236, in decorator
    result = await func(*args, **kwargs)
  File "/home/bori/.local/lib/python3.7/site-packages/telegram/_bot.py", line 3778, in get_updates
    api_kwargs=api_kwargs,
  File "/home/bori/.local/lib/python3.7/site-packages/telegram/_bot.py", line 315, in _post
    pool_timeout=pool_timeout,
  File "/home/bori/.local/lib/python3.7/site-packages/telegram/request/_baserequest.py", line 169, in post
    pool_timeout=pool_timeout,
  File "/home/bori/.local/lib/python3.7/site-packages/telegram/request/_baserequest.py", line 285, in _request_wrapper
    raise exc
  File "/home/bori/.local/lib/python3.7/site-packages/telegram/request/_baserequest.py", line 278, in _request_wrapper
    pool_timeout=pool_timeout,
  File "/home/bori/.local/lib/python3.7/site-packages/telegram/request/_httpxrequest.py", line 195, in do_request
    raise NetworkError(f"httpx HTTPError: {err}") from err
telegram.error.NetworkError: httpx HTTPError: [Errno -2] Name or service not known
2022-06-14 15:13:07,018 | telegram.ext._updater | ERROR | _network_loop_retry:569 | Error while getting Updates: httpx HTTPError: [Errno -2] Name or service not known
2022-06-14 15:13:07,019 | telegram.ext._application | ERROR | process_error:1484 | No error handlers are registered, logging exception.
Traceback (most recent call last):
  File "/home/bori/.local/lib/python3.7/site-packages/httpcore/_exceptions.py", line 8, in map_exceptions
    yield
  File "/home/bori/.local/lib/python3.7/site-packages/httpcore/backends/asyncio.py", line 112, in connect_tcp
    local_host=local_address,
  File "/home/bori/.local/lib/python3.7/site-packages/anyio/_core/_sockets.py", line 190, in connect_tcp
    target_host, remote_port, family=family, type=socket.SOCK_STREAM
  File "/home/bori/.local/lib/python3.7/site-packages/anyio/_core/_sockets.py", line 497, in getaddrinfo
    encoded_host, port, family=family, type=type, proto=proto, flags=flags
  File "/home/bori/.local/lib/python3.7/site-packages/anyio/_backends/_asyncio.py", line 1755, in getaddrinfo
    host, port, family=family, type=type, proto=proto, flags=flags
  File "/usr/lib/python3.7/asyncio/base_events.py", line 792, in getaddrinfo
    None, getaddr_func, host, port, family, type, proto, flags)
  File "/usr/lib/python3.7/concurrent/futures/thread.py", line 57, in run
    result = self.fn(*self.args, **self.kwargs)
  File "/usr/lib/python3.7/socket.py", line 752, in getaddrinfo
    for res in _socket.getaddrinfo(host, port, family, type, proto, flags):
socket.gaierror: [Errno -2] Name or service not known

During handling of the above exception, another exception occurred:

Traceback (most recent call last):
  File "/home/bori/.local/lib/python3.7/site-packages/httpx/_transports/default.py", line 60, in map_httpcore_exceptions
    yield
  File "/home/bori/.local/lib/python3.7/site-packages/httpx/_transports/default.py", line 353, in handle_async_request
    resp = await self._pool.handle_async_request(req)
  File "/home/bori/.local/lib/python3.7/site-packages/httpcore/_async/connection_pool.py", line 253, in handle_async_request
    raise exc
  File "/home/bori/.local/lib/python3.7/site-packages/httpcore/_async/connection_pool.py", line 237, in handle_async_request
    response = await connection.handle_async_request(request)
  File "/home/bori/.local/lib/python3.7/site-packages/httpcore/_async/connection.py", line 86, in handle_async_request
    raise exc
  File "/home/bori/.local/lib/python3.7/site-packages/httpcore/_async/connection.py", line 63, in handle_async_request
    stream = await self._connect(request)
  File "/home/bori/.local/lib/python3.7/site-packages/httpcore/_async/connection.py", line 111, in _connect
    stream = await self._network_backend.connect_tcp(**kwargs)
  File "/home/bori/.local/lib/python3.7/site-packages/httpcore/backends/auto.py", line 30, in connect_tcp
    host, port, timeout=timeout, local_address=local_address
  File "/home/bori/.local/lib/python3.7/site-packages/httpcore/backends/asyncio.py", line 112, in connect_tcp
    local_host=local_address,
  File "/usr/lib/python3.7/contextlib.py", line 130, in __exit__
    self.gen.throw(type, value, traceback)
  File "/home/bori/.local/lib/python3.7/site-packages/httpcore/_exceptions.py", line 12, in map_exceptions
    raise to_exc(exc)
httpcore.ConnectError: [Errno -2] Name or service not known

The above exception was the direct cause of the following exception:

Traceback (most recent call last):
  File "/home/bori/.local/lib/python3.7/site-packages/telegram/request/_httpxrequest.py", line 180, in do_request
    data=data,
  File "/home/bori/.local/lib/python3.7/site-packages/httpx/_client.py", line 1527, in request
    return await self.send(request, auth=auth, follow_redirects=follow_redirects)
  File "/home/bori/.local/lib/python3.7/site-packages/httpx/_client.py", line 1618, in send
    history=[],
  File "/home/bori/.local/lib/python3.7/site-packages/httpx/_client.py", line 1645, in _send_handling_auth
    history=history,
  File "/home/bori/.local/lib/python3.7/site-packages/httpx/_client.py", line 1679, in _send_handling_redirects
    response = await self._send_single_request(request)
  File "/home/bori/.local/lib/python3.7/site-packages/httpx/_client.py", line 1716, in _send_single_request
    response = await transport.handle_async_request(request)
  File "/home/bori/.local/lib/python3.7/site-packages/httpx/_transports/default.py", line 353, in handle_async_request
    resp = await self._pool.handle_async_request(req)
  File "/usr/lib/python3.7/contextlib.py", line 130, in __exit__
    self.gen.throw(type, value, traceback)
  File "/home/bori/.local/lib/python3.7/site-packages/httpx/_transports/default.py", line 77, in map_httpcore_exceptions
    raise mapped_exc(message) from exc
httpx.ConnectError: [Errno -2] Name or service not known

The above exception was the direct cause of the following exception:

Traceback (most recent call last):
  File "/home/bori/.local/lib/python3.7/site-packages/telegram/ext/_updater.py", line 556, in _network_loop_retry
    if not await action_cb():
  File "/home/bori/.local/lib/python3.7/site-packages/telegram/ext/_updater.py", line 318, in polling_action_cb
    raise exc
  File "/home/bori/.local/lib/python3.7/site-packages/telegram/ext/_updater.py", line 310, in polling_action_cb
    allowed_updates=allowed_updates,
  File "/home/bori/.local/lib/python3.7/site-packages/telegram/ext/_extbot.py", line 294, in get_updates
    api_kwargs=api_kwargs,
  File "/home/bori/.local/lib/python3.7/site-packages/telegram/_bot.py", line 236, in decorator
    result = await func(*args, **kwargs)
  File "/home/bori/.local/lib/python3.7/site-packages/telegram/_bot.py", line 3778, in get_updates
    api_kwargs=api_kwargs,
  File "/home/bori/.local/lib/python3.7/site-packages/telegram/_bot.py", line 315, in _post
    pool_timeout=pool_timeout,
  File "/home/bori/.local/lib/python3.7/site-packages/telegram/request/_baserequest.py", line 169, in post
    pool_timeout=pool_timeout,
  File "/home/bori/.local/lib/python3.7/site-packages/telegram/request/_baserequest.py", line 285, in _request_wrapper
    raise exc
  File "/home/bori/.local/lib/python3.7/site-packages/telegram/request/_baserequest.py", line 278, in _request_wrapper
    pool_timeout=pool_timeout,
  File "/home/bori/.local/lib/python3.7/site-packages/telegram/request/_httpxrequest.py", line 195, in do_request
    raise NetworkError(f"httpx HTTPError: {err}") from err
telegram.error.NetworkError: httpx HTTPError: [Errno -2] Name or service not known
2022-06-14 15:27:04,030 | apscheduler.scheduler | INFO | start:171 | Scheduler started
2022-06-14 15:27:04,031 | telegram.ext._application | INFO | start:492 | Application started
2022-06-14 15:30:36,862 | apscheduler.scheduler | INFO | start:171 | Scheduler started
2022-06-14 15:30:36,862 | telegram.ext._application | INFO | start:492 | Application started
2022-06-14 15:32:46,941 | apscheduler.scheduler | INFO | start:171 | Scheduler started
2022-06-14 15:32:46,942 | telegram.ext._application | INFO | start:492 | Application started
2022-06-14 15:36:02,315 | apscheduler.scheduler | INFO | start:171 | Scheduler started
2022-06-14 15:36:02,320 | telegram.ext._application | INFO | start:492 | Application started
2022-06-14 15:48:46,099 | apscheduler.scheduler | INFO | start:171 | Scheduler started
2022-06-14 15:48:46,100 | telegram.ext._application | INFO | start:492 | Application started
2022-06-14 15:49:47,516 | apscheduler.scheduler | INFO | start:171 | Scheduler started
2022-06-14 15:49:47,517 | telegram.ext._application | INFO | start:492 | Application started
2022-06-14 15:49:55,570 | apscheduler.scheduler | INFO | start:171 | Scheduler started
2022-06-14 15:49:55,571 | telegram.ext._application | INFO | start:492 | Application started
2022-06-14 15:51:05,121 | apscheduler.scheduler | INFO | start:171 | Scheduler started
2022-06-14 15:51:05,126 | telegram.ext._application | INFO | start:492 | Application started
2022-06-14 15:51:59,723 | apscheduler.scheduler | INFO | start:171 | Scheduler started
2022-06-14 15:51:59,724 | telegram.ext._application | INFO | start:492 | Application started
2022-06-14 15:52:42,465 | apscheduler.scheduler | INFO | start:171 | Scheduler started
2022-06-14 15:52:42,466 | telegram.ext._application | INFO | start:492 | Application started
2022-06-14 15:54:07,177 | apscheduler.scheduler | INFO | start:171 | Scheduler started
2022-06-14 15:54:07,178 | telegram.ext._application | INFO | start:492 | Application started
2022-06-14 15:54:43,444 | apscheduler.scheduler | INFO | start:171 | Scheduler started
2022-06-14 15:54:43,445 | telegram.ext._application | INFO | start:492 | Application started
2022-06-14 15:55:12,936 | apscheduler.scheduler | INFO | start:171 | Scheduler started
2022-06-14 15:55:12,937 | telegram.ext._application | INFO | start:492 | Application started
2022-06-14 15:55:24,991 | apscheduler.scheduler | INFO | start:171 | Scheduler started
2022-06-14 15:55:24,991 | telegram.ext._application | INFO | start:492 | Application started
2022-06-14 15:56:14,129 | apscheduler.scheduler | INFO | start:171 | Scheduler started
2022-06-14 15:56:14,131 | telegram.ext._application | INFO | start:492 | Application started
2022-06-14 15:56:56,876 | apscheduler.scheduler | INFO | start:171 | Scheduler started
2022-06-14 15:56:56,877 | telegram.ext._application | INFO | start:492 | Application started
2022-06-14 15:57:03,809 | apscheduler.scheduler | INFO | start:171 | Scheduler started
2022-06-14 15:57:03,810 | telegram.ext._application | INFO | start:492 | Application started
2022-06-14 15:58:20,136 | apscheduler.scheduler | INFO | start:171 | Scheduler started
2022-06-14 15:58:20,137 | telegram.ext._application | INFO | start:492 | Application started
2022-06-14 15:58:35,419 | apscheduler.scheduler | INFO | start:171 | Scheduler started
2022-06-14 15:58:35,420 | telegram.ext._application | INFO | start:492 | Application started
2022-06-14 15:59:11,792 | apscheduler.scheduler | INFO | start:171 | Scheduler started
2022-06-14 15:59:11,793 | telegram.ext._application | INFO | start:492 | Application started
2022-06-14 15:59:40,025 | apscheduler.scheduler | INFO | start:171 | Scheduler started
2022-06-14 15:59:40,025 | telegram.ext._application | INFO | start:492 | Application started
2022-06-14 16:00:37,175 | apscheduler.scheduler | INFO | start:171 | Scheduler started
2022-06-14 16:00:37,177 | telegram.ext._application | INFO | start:492 | Application started
2022-06-14 16:01:03,924 | apscheduler.scheduler | INFO | start:171 | Scheduler started
2022-06-14 16:01:03,925 | telegram.ext._application | INFO | start:492 | Application started
2022-06-14 16:02:04,326 | apscheduler.scheduler | INFO | start:171 | Scheduler started
2022-06-14 16:02:04,326 | telegram.ext._application | INFO | start:492 | Application started
2022-06-14 16:02:05,439 | telegram.ext._application | ERROR | process_error:1484 | No error handlers are registered, logging exception.
Traceback (most recent call last):
  File "/home/bori/.local/lib/python3.7/site-packages/telegram/ext/_application.py", line 970, in process_update
    await coroutine
  File "/home/bori/.local/lib/python3.7/site-packages/telegram/ext/_handler.py", line 137, in handle_update
    return await self.callback(update, context)
  File "/home/bori/dev/py/beud/beubot/scopes/general/flows/prompt_handlers/genesis_phlr.py", line 21, in sent_phone_number_hlr
    text=f"📞 Phone Number: {context.user_data['phone_number']}",
  File "/home/bori/.local/lib/python3.7/site-packages/telegram/_bot.py", line 236, in decorator
    result = await func(*args, **kwargs)
TypeError: send_message() missing 1 required positional argument: 'chat_id'
2022-06-14 16:02:19,985 | apscheduler.scheduler | INFO | start:171 | Scheduler started
2022-06-14 16:02:19,986 | telegram.ext._application | INFO | start:492 | Application started
2022-06-14 16:03:38,677 | apscheduler.scheduler | INFO | start:171 | Scheduler started
2022-06-14 16:03:38,678 | telegram.ext._application | INFO | start:492 | Application started
2022-06-14 16:04:06,518 | apscheduler.scheduler | INFO | start:171 | Scheduler started
2022-06-14 16:04:06,521 | telegram.ext._application | INFO | start:492 | Application started
2022-06-14 16:04:39,725 | apscheduler.scheduler | INFO | start:171 | Scheduler started
2022-06-14 16:04:39,726 | telegram.ext._application | INFO | start:492 | Application started
2022-06-14 16:04:50,557 | apscheduler.scheduler | INFO | start:171 | Scheduler started
2022-06-14 16:04:50,558 | telegram.ext._application | INFO | start:492 | Application started
2022-06-14 16:07:48,771 | apscheduler.scheduler | INFO | start:171 | Scheduler started
2022-06-14 16:07:48,771 | telegram.ext._application | INFO | start:492 | Application started
2022-06-14 16:10:08,992 | apscheduler.scheduler | INFO | start:171 | Scheduler started
2022-06-14 16:10:08,994 | telegram.ext._application | INFO | start:492 | Application started
2022-06-14 16:21:01,707 | apscheduler.scheduler | INFO | start:171 | Scheduler started
2022-06-14 16:21:01,707 | telegram.ext._application | INFO | start:492 | Application started
2022-06-14 16:21:35,680 | apscheduler.scheduler | INFO | start:171 | Scheduler started
2022-06-14 16:21:35,682 | telegram.ext._application | INFO | start:492 | Application started
2022-06-14 16:24:10,808 | apscheduler.scheduler | INFO | start:171 | Scheduler started
2022-06-14 16:24:10,812 | telegram.ext._application | INFO | start:492 | Application started
2022-06-14 16:26:26,096 | apscheduler.scheduler | INFO | start:171 | Scheduler started
2022-06-14 16:26:26,097 | telegram.ext._application | INFO | start:492 | Application started
2022-06-14 16:26:59,599 | apscheduler.scheduler | INFO | start:171 | Scheduler started
2022-06-14 16:26:59,600 | telegram.ext._application | INFO | start:492 | Application started
2022-06-14 16:29:07,056 | apscheduler.scheduler | INFO | start:171 | Scheduler started
2022-06-14 16:29:07,056 | telegram.ext._application | INFO | start:492 | Application started
2022-06-14 16:29:33,078 | apscheduler.scheduler | INFO | start:171 | Scheduler started
2022-06-14 16:29:33,082 | telegram.ext._application | INFO | start:492 | Application started
2022-06-14 16:31:02,324 | apscheduler.scheduler | INFO | start:171 | Scheduler started
2022-06-14 16:31:02,325 | telegram.ext._application | INFO | start:492 | Application started
2022-06-14 16:31:50,189 | apscheduler.scheduler | INFO | start:171 | Scheduler started
2022-06-14 16:31:50,190 | telegram.ext._application | INFO | start:492 | Application started
2022-06-14 16:34:25,387 | apscheduler.scheduler | INFO | start:171 | Scheduler started
2022-06-14 16:34:25,387 | telegram.ext._application | INFO | start:492 | Application started
2022-06-14 16:34:40,327 | apscheduler.scheduler | INFO | start:171 | Scheduler started
2022-06-14 16:34:40,328 | telegram.ext._application | INFO | start:492 | Application started
2022-06-14 16:35:53,735 | apscheduler.scheduler | INFO | start:171 | Scheduler started
2022-06-14 16:35:53,736 | telegram.ext._application | INFO | start:492 | Application started
2022-06-14 16:36:48,338 | apscheduler.scheduler | INFO | start:171 | Scheduler started
2022-06-14 16:36:48,339 | telegram.ext._application | INFO | start:492 | Application started
2022-06-14 16:37:07,501 | apscheduler.scheduler | INFO | start:171 | Scheduler started
2022-06-14 16:37:07,502 | telegram.ext._application | INFO | start:492 | Application started
2022-06-14 16:37:43,936 | apscheduler.scheduler | INFO | start:171 | Scheduler started
2022-06-14 16:37:43,937 | telegram.ext._application | INFO | start:492 | Application started
2022-06-14 16:38:17,779 | apscheduler.scheduler | INFO | start:171 | Scheduler started
2022-06-14 16:38:17,780 | telegram.ext._application | INFO | start:492 | Application started
2022-06-14 16:38:38,035 | apscheduler.scheduler | INFO | start:171 | Scheduler started
2022-06-14 16:38:38,036 | telegram.ext._application | INFO | start:492 | Application started
2022-06-14 16:38:52,064 | apscheduler.scheduler | INFO | start:171 | Scheduler started
2022-06-14 16:38:52,064 | telegram.ext._application | INFO | start:492 | Application started
2022-06-14 16:39:24,920 | telegram.ext._application | ERROR | process_error:1484 | No error handlers are registered, logging exception.
Traceback (most recent call last):
  File "/home/bori/.local/lib/python3.7/site-packages/telegram/ext/_application.py", line 970, in process_update
    await coroutine
  File "/home/bori/.local/lib/python3.7/site-packages/telegram/ext/_handler.py", line 137, in handle_update
    return await self.callback(update, context)
  File "/home/bori/dev/py/beud/beubot/scopes/general/start.py", line 22, in start_hlr
    await exec_genesis_new_user_flow(update, context)
  File "/home/bori/dev/py/beud/beubot/scopes/general/flows/genesis_flow.py", line 117, in exec_genesis_new_user_flow
    await genesis_data(update, context)
TypeError: object NoneType can't be used in 'await' expression
2022-06-14 16:39:58,588 | apscheduler.scheduler | INFO | start:171 | Scheduler started
2022-06-14 16:39:58,589 | telegram.ext._application | INFO | start:492 | Application started
2022-06-14 16:40:40,287 | apscheduler.scheduler | INFO | start:171 | Scheduler started
2022-06-14 16:40:40,288 | telegram.ext._application | INFO | start:492 | Application started
2022-06-14 16:41:03,324 | apscheduler.scheduler | INFO | start:171 | Scheduler started
2022-06-14 16:41:03,326 | telegram.ext._application | INFO | start:492 | Application started
2022-06-14 16:43:43,128 | apscheduler.scheduler | INFO | start:171 | Scheduler started
2022-06-14 16:43:43,128 | telegram.ext._application | INFO | start:492 | Application started
2022-06-14 16:45:25,645 | apscheduler.scheduler | INFO | start:171 | Scheduler started
2022-06-14 16:45:25,645 | telegram.ext._application | INFO | start:492 | Application started
2022-06-14 16:45:35,929 | telegram.ext._application | ERROR | process_error:1484 | No error handlers are registered, logging exception.
Traceback (most recent call last):
  File "/home/bori/.local/lib/python3.7/site-packages/telegram/ext/_application.py", line 970, in process_update
    await coroutine
  File "/home/bori/.local/lib/python3.7/site-packages/telegram/ext/_handler.py", line 137, in handle_update
    return await self.callback(update, context)
  File "/home/bori/dev/py/beud/beubot/scopes/general/start.py", line 22, in start_hlr
    await exec_genesis_new_user_flow(update, context)
  File "/home/bori/dev/py/beud/beubot/scopes/general/flows/genesis_flow.py", line 119, in exec_genesis_new_user_flow
    if context.user_data['phone_number'] :
KeyError: 'phone_number'
2022-06-14 16:46:19,816 | apscheduler.scheduler | INFO | start:171 | Scheduler started
2022-06-14 16:46:19,816 | telegram.ext._application | INFO | start:492 | Application started
2022-06-14 18:18:20,303 | apscheduler.scheduler | INFO | start:171 | Scheduler started
2022-06-14 18:18:20,303 | telegram.ext._application | INFO | start:492 | Application started
2022-06-14 18:18:40,011 | apscheduler.scheduler | INFO | start:171 | Scheduler started
2022-06-14 18:18:40,013 | telegram.ext._application | INFO | start:492 | Application started
2022-06-14 18:19:33,509 | apscheduler.scheduler | INFO | start:171 | Scheduler started
2022-06-14 18:19:33,510 | telegram.ext._application | INFO | start:492 | Application started
2022-06-14 18:20:01,082 | apscheduler.scheduler | INFO | start:171 | Scheduler started
2022-06-14 18:20:01,083 | telegram.ext._application | INFO | start:492 | Application started
2022-06-14 18:20:44,131 | apscheduler.scheduler | INFO | start:171 | Scheduler started
2022-06-14 18:20:44,136 | telegram.ext._application | INFO | start:492 | Application started
2022-06-14 18:25:21,653 | apscheduler.scheduler | INFO | start:171 | Scheduler started
2022-06-14 18:25:21,663 | telegram.ext._application | INFO | start:492 | Application started
2022-06-14 18:26:08,043 | apscheduler.scheduler | INFO | start:171 | Scheduler started
2022-06-14 18:26:08,043 | telegram.ext._application | INFO | start:492 | Application started
2022-06-14 18:29:12,707 | apscheduler.scheduler | INFO | start:171 | Scheduler started
2022-06-14 18:29:12,708 | telegram.ext._application | INFO | start:492 | Application started
2022-06-14 18:30:05,739 | apscheduler.scheduler | INFO | start:171 | Scheduler started
2022-06-14 18:30:05,739 | telegram.ext._application | INFO | start:492 | Application started
2022-06-14 18:31:36,010 | apscheduler.scheduler | INFO | start:171 | Scheduler started
2022-06-14 18:31:36,010 | telegram.ext._application | INFO | start:492 | Application started
2022-06-14 18:32:20,681 | apscheduler.scheduler | INFO | start:171 | Scheduler started
2022-06-14 18:32:20,681 | telegram.ext._application | INFO | start:492 | Application started
2022-06-14 18:34:54,672 | apscheduler.scheduler | INFO | start:171 | Scheduler started
2022-06-14 18:34:54,672 | telegram.ext._application | INFO | start:492 | Application started
2022-06-14 18:36:43,733 | apscheduler.scheduler | INFO | start:171 | Scheduler started
2022-06-14 18:36:43,734 | telegram.ext._application | INFO | start:492 | Application started
2022-06-14 18:38:06,710 | apscheduler.scheduler | INFO | start:171 | Scheduler started
2022-06-14 18:38:06,710 | telegram.ext._application | INFO | start:492 | Application started
2022-06-14 18:38:44,685 | apscheduler.scheduler | INFO | start:171 | Scheduler started
2022-06-14 18:38:44,686 | telegram.ext._application | INFO | start:492 | Application started
2022-06-14 18:39:39,514 | apscheduler.scheduler | INFO | start:171 | Scheduler started
2022-06-14 18:39:39,514 | telegram.ext._application | INFO | start:492 | Application started
2022-06-14 18:39:50,180 | telegram.ext._application | ERROR | process_error:1484 | No error handlers are registered, logging exception.
Traceback (most recent call last):
  File "/home/bori/.local/lib/python3.7/site-packages/telegram/ext/_application.py", line 970, in process_update
    await coroutine
  File "/home/bori/.local/lib/python3.7/site-packages/telegram/ext/_handler.py", line 137, in handle_update
    return await self.callback(update, context)
  File "/home/bori/dev/py/beud/beubot/scopes/general/flows/prompt_handlers/genesis_phlr.py", line 42, in skip_role_hlr
    await genesis_persist(update, context)
TypeError: object NoneType can't be used in 'await' expression
2022-06-14 18:40:10,650 | apscheduler.scheduler | INFO | start:171 | Scheduler started
2022-06-14 18:40:10,654 | telegram.ext._application | INFO | start:492 | Application started
2022-06-14 18:42:31,017 | apscheduler.scheduler | INFO | start:171 | Scheduler started
2022-06-14 18:42:31,017 | telegram.ext._application | INFO | start:492 | Application started
2022-06-14 18:43:41,205 | apscheduler.scheduler | INFO | start:171 | Scheduler started
2022-06-14 18:43:41,205 | telegram.ext._application | INFO | start:492 | Application started
2022-06-14 18:43:58,452 | apscheduler.scheduler | INFO | start:171 | Scheduler started
2022-06-14 18:43:58,452 | telegram.ext._application | INFO | start:492 | Application started
2022-06-14 18:44:10,812 | apscheduler.scheduler | INFO | start:171 | Scheduler started
2022-06-14 18:44:10,813 | telegram.ext._application | INFO | start:492 | Application started
